Workbook

Sheet サマリー
A1: アニメーション 呪術廻戦展「懐玉・玉折」「渋谷事変」
A2: LEGS／イベント記念商品 42SKU 全会場 販売分析・札幌予測確定・石川会場以降予測・追加発注判定
A3: 基準日：2026年7月28日 ／ 実績データ：東京(25日)・名古屋(19日)・博多(26日)・大阪(20日)＝全会期、札幌＝7/27(会期6日目)まで ＋ 2026/7/28 SPJ様 欠品報告メール
A5: ■ 結論サマリー
A6: ① 札幌 会期20日予測（確定値） | B6: LEGS42SKU 販売数 8,740個／販売金額 6,680,400円 ※東京を除く名古屋・博多・大阪の実績倍率から算出
A7: 札幌 全物販予測 | B7: 数量 37,254個／金額 36,375,678円 → 東京(初回)対比 10.2% ※コナン実績の北海道13.3%を下回る水準
A8: 札幌 入場者予測 | B8: 7,784人（委員会予測18,000人の43%／LEGS予測14,000人の56%）＝計画を大幅に下回る
A9: ② LEGS物販構成比の推移 | B9: 金額：東京28.5%→名古屋29.9%→博多29.4%→大阪21.1%→札幌18.4%(予測) 数量：38.7%→34.5%→40.0%→26.7%→札幌23.5%(予測)
A10: 構成比低下の主因 | B10: 大阪会場からの新商品106SKU投入（大阪の会期20日 金額シェア19.8%）。札幌は新規SKU 0で品揃えは大阪と同一
A11: ③ 石川以降5会場 LEGS必要数 | B11: 81,760個（シナリオ①ユーザー指定：石川11%・仙台13%・神戸12%(仮)・鳥取9%・東京凱旋50%）
A12: シナリオ②企画概要書ベース | B12: 石川12.48%・仙台15.60%（企画概要書グッズ売上÷東京）→ 必要数 85,272個
A13: シナリオ③札幌実績連動(保守) | B13: ②に札幌の計画比達成率46.5%を乗算 → 石川5.83%・仙台7.29%・神戸5.61%・鳥取4.21%（凱旋50%据置）→ 必要数 62,673個
A14: ★残在庫想定の反映 | B14: 在庫フロー台帳の「梅田まで(SET)」列 274,688個を採用（梅田会場後の検品結果まで反映済み）。
A15: ★札幌への追納（実施済） | B15: 2026/7/31・8/1 札幌会場追納リスト（レッグス商品分のみ抜粋）：呪術廻戦 渋谷事変 クリアファイル（脹相） 50個／前髪ヘアバンド 100個／脱兎！ポーチ入りクリップセット 60個／宿儺の指風お菓子 100個 計310個。倉庫在庫からの出荷なので全社在庫は不変
A16: 追納後になお必要な追納 | B16: 2個（会期20日予測が販売可能数を上回る残差）
A17: 石川以降 供給可能在庫 | B17: 265,948個 ＝ 残在庫274,688個 − 札幌 会期20日予測販売8,740個（札幌への追納と会期末返送を相殺した正味）
... A29: 札幌 会期中の追加発注 | B29: 1品目が会期内に在庫切れ見込：呪術廻戦 渋谷事変 クリアファイル（宿儺）(不足2)
A31: ■ 運営（SPJ様）欠品報告との突合 ※2026/7/28受領メール
A32: 報告された欠品／近々欠品 | B32: 8品目：呪術廻戦 渋谷事変 クリアファイル（虎杖 悠仁） 呪術廻戦 渋谷事変 クリアファイル（七海 建人） 呪術廻戦 渋谷事変 クリアファイル（脹相） 呪術廻戦 渋谷事変 クリアファイル（宿儺） 前髪ヘアバンド 宿儺の指風お菓子 脱兎！ポーチ入りクリップセット 気分リフレッシュオルゴール
A33: ◎ モデルも会期中欠品を検知 | B33: 1品目：呪術廻戦 渋谷事変 クリアファイル（宿儺）
A34: ○ モデルは高消化率で整合 | B34: 6品目：呪術廻戦 渋谷事変 クリアファイル（虎杖 悠仁） 呪術廻戦 渋谷事変 クリアファイル（七海 建人） 呪術廻戦 渋谷事変 クリアファイル（脹相） 前髪ヘアバンド 宿儺の指風お菓子 気分リフレッシュオルゴール（予測消化率70%超。会期末までに枯渇する水準）
A35: △ モデル未検知（現場優先） | B35: 1品目：脱兎！ポーチ入りクリップセット(予測消化率67%)
A36: ▲ モデルのみ検知（現場未報告） | B36: 0品目：なし → 現場に実在庫の確認を推奨
A37: ★追納不可と回答された品目 | B37: 気分リフレッシュオルゴール ＝ 前会場時点で「追納困難」と回答済。ただし7/8実在庫では倉庫残23個が確認できるため、下記の要確認事項を参照
A38: 突合の結論 | B38: 現場報告8品目のうち7品目がモデル側でも欠品または高消化率として検知されており、見落とし0・空振り0で完全に整合。
B39: 7/27（6日目）実績を織り込んだことで検知精度が上がり、予測モデルは現場実感と一致する水準にある。
B40: ④シートのU列（運営 欠品報告）・V列（モデル×現場 突合）で商品別に明示している。
A41: ★倉庫在庫による解決可否 | B41: 報告8品目すべて2026/7/8時点で倉庫に在庫が残っており、追加生産ではなく倉庫からの追加納品で対応可能。
A42: 倉庫残（札幌納品を除く） | B42: 呪術廻戦 渋谷事変 クリアファイル（虎杖 悠仁）:1,740個 呪術廻戦 渋谷事変 クリアファイル（七海 建人）:2,423個 呪術廻戦 渋谷事変 クリアファイル（脹相）:208個 呪術廻戦 渋谷事変 クリアファイル（宿儺）:1,281個 前髪ヘアバンド:297個 宿儺の指風お菓子:160個 脱兎！ポーチ入りクリップセット:260個 気分リフレッシュオルゴール:23個
A43: ※要確認 | B43: 「気分リフレッシュオルゴール」は倉庫残28個が存在する。前会場時の「追納困難」回答と実在庫が食い違うため、
B44: 28個が出荷可能かSPJ様・倉庫に再確認のうえ、可能なら札幌へ充当することを推奨。
A46: ■ 最重要リスクと打ち手
A47: 札幌の動員が計画比43% | B47: 初6日入場者3,880人（大阪同期間14,703人の26.4%）。物販売上も東京対比10.2%と、
B48: 石川11%・鳥取9%として設定された「格下」会場と同水準。石川以降の会場比率も下方修正を検討すべき。
A49: 東京凱旋が必要数の53% | B49: 石川以降必要数81,760個のうち43,032個(53%)が東京凱旋。凱旋の50%前提が外れると発注量が大きくブレる。
B50: 発注は「石川〜鳥取(4会場・38,729個)」を先行確定し、凱旋分は会期確定後に第2弾発注とするのが安全。
A51: ★過剰在庫のほうが深刻 | B51: 残在庫274,688個に対し石川以降の必要数は81,760個。差引184,188個（残在庫の67%）が余剰となる見込み。
B52: 特に渋谷事変ポストカードセット(供給可能27,282個 vs 必要1,911個)、懐玉・玉折ポストカードセット(5,977 vs 1,488)は
B53: 20倍超の在庫を抱えている。追加発注よりも、余剰在庫の消化策（セット販売・ノベルティ転用等）の検討が急務。
A54: 不足はごく一部 | B54: 追加生産が必要なのは8品目・2,552個のみ。うち展示会キービジュアル クリアファイルが928個で全体の36%を占める。
...

Sheet 前提・入力
A1: 前提・入力パラメータ
A2: 青字・黄色セルが入力値です。変更すると①③④⑤シートの予測が自動再計算されます。
A4: ■ ①札幌予測 モデルパラメータ
A5: 会期倍率g 加重：大阪 | B5: 2 | C5: 20日会期・水曜開始・新商品投入後で札幌と同条件のため2倍加重
A6: 会期倍率g 加重：博多 | B6: 1 | C6: 26日会期のうち初20日で算出
A7: 会期倍率g 加重：名古屋 | B7: 1 | C7: 19日会期・全日実績あり。20日目分のみ補完して札幌20日と揃える
A8: 会期倍率g 加重：東京 | B8: 0 | C8: ユーザー指示により東京は算出根拠から除外（0固定）
A9: 名古屋 20日目 補完率 | B9: 0.048292031 | C9: 大阪・博多の「20日目÷1-19日累計」平均。名古屋19日会期を20日相当に換算
A10: 全体倍率g（実績ゼロ品のフォールバック） | B10: 1.7519247 | C10: 42品計の加重平均倍率
A11: ■ ②③会場比率 前提
A12: 東京(初回) 全物販売上（税込） | B12: 358193925 | C12: 池袋サンシャイン25日間・レジ袋/音声ガイド/当日券を除く
A13: 東京(初回) 全物販 販売数量 | B13: 383342 | C13: 同上
A14: ★シナリオ選択（1〜4） | B14: 1 | C14: 1=ユーザー指定／2=企画概要書ベース／3=札幌実績連動(保守)／4=手動入力（下の手動値を使用）
A15: シナリオ別 東京対比比率 | C15: ①ユーザー指定 | D15: ②企画概要書ベース | E15: ③札幌実績連動(保守) | F15: ④手動入力
A16: 石川 香林坊大和 | B16: 26/8/14(金)-8/31(月)（18日間） | C16: 0.11 | D16: 0.1248 | E16: 0.058030303 | F16: 0.11
A17: 仙台 Ebeans | B17: 26/9/5(土)-10/4(日)（30日間） | C17: 0.13 | D17: 0.156 | E17: 0.072537878 | F17: 0.13
A18: 神戸阪急 | B18: 26/12/16(水)-27/1/7(木)（21日間） | C18: 0.12 | D18: 0.12 | E18: 0.055798368 | F18: 0.12
A19: 鳥取島根 夢みなとタワー | B19: 27/3/15-4/4（21日間） | C19: 0.09 | D19: 0.09 | E19: 0.041848776 | F19: 0.09
A20: 東京凱旋 東京建物ぴあホール | B20: 27年4-5月（25日間） | C20: 0.5 | D20: 0.5 | E20: 0.5 | F20: 0.5
A21: ※③は企画概要書の計画値に札幌の計画比達成率 46.5% を乗じたもの（凱旋は据置）
A23: 東京対比：石川 香林坊大和 | B23: =INDEX(C16:F16,前提・入力!$B$14) -> 0.11 | C23: 緑字＝シナリオ選択で自動決定 ／ ユーザー指定
A24: 東京対比：仙台 Ebeans | B24: =INDEX(C17:F17,前提・入力!$B$14) -> 0.13 | C24: 緑字＝シナリオ選択で自動決定 ／ ユーザー指定（コナン実績は10.5%）
A25: 東京対比：神戸阪急 | B25: =INDEX(C18:F18,前提・入力!$B$14) -> 0.12 | C25: 緑字＝シナリオ選択で自動決定 ／ ★要確認：指定なきため仮置き
A26: 東京対比：鳥取島根 夢みなとタワー | B26: =INDEX(C19:F19,前提・入力!$B$14) -> 0.09 | C26: 緑字＝シナリオ選択で自動決定 ／ ユーザー指定
A27: 東京対比：東京凱旋 東京建物ぴあホール | B27: =INDEX(C20:F20,前提・入力!$B$14) -> 0.5 | C27: 緑字＝シナリオ選択で自動決定 ／ ユーザー指定（初回東京の50%）
A28: ［参考］コナンカフェ2026 東京対比 | C28: 大阪53.6% 名古屋26.8% 神奈川19.1% 北海道13.3% 仙台10.5%
A29: ■ ③石川以降 LEGS構成比 前提
A30: LEGS 金額構成比（石川以降） | B30: 0.18365018 | C30: 札幌の会期20日予測値。大阪21.1%→札幌19.6%の到達点を採用
A31: LEGS 平均単価（税込） | B31: 764 | C31: 札幌20日予測ミックスの加重平均単価
A32: 商品別按分：大阪20日実績の構成比ウェイト | B32: 0.5
A33: 商品別按分：札幌20日予測の構成比ウェイト | B33: 0.5 | C33: 大阪ウェイトとの合計が100%になるよう設定
A34: ■ ④追加発注 前提
A35: 安全率（不足数に対する上乗せ） | B35: 0.1 | C35: 推奨発注数＝不足数×(1+安全率)を切り上げ
A36: ［参考］残在庫想定 全品計（梅田まで(SET)） | B36: 274688 | C36: 在庫フロー台帳の最終実在庫列。商品別の実数を③⑧⑩⑪シートで直接使用
A37: 札幌 会期末残在庫のスライド率 | B37: 1 | C37: 札幌終了在庫を石川以降へ回せる割合
A38: 発注〜納品バッファ日数（輸送・検品） | B38: 14 | C38: 発注期限＝会場初日 − 生産日数 − 本バッファ。⑪シートで使用
A39: 基準日 | B39: 46233 | C39: 生産日数の提示日＝2026/7/28。残日数の起点

Sheet ①札幌予測確定
A1: ① 札幌会場 会期20日間（7/22-8/10）商品別 販売予測【確定値】
A2: 算出根拠：東京を除く名古屋①・博多②・大阪④の「20日累計 ÷ 初6日」倍率を商品別に加重平均し、札幌の初6日(7/22-7/27)実績に乗算
A3: 加重：大阪2・博多1・名古屋1（「前提・入力」シートで変更可）／名古屋は19日全会期実績を20日相当に換算（+4.83%）
A6: No. | B6: JAN | C6: 商品名 | D6: 税込 単価 | E6: 札幌 初6日 7/22-27 | F6: 名古屋① 初6日 | G6: 名古屋① 19日累計 (全会期) | H6: 名古屋 倍率g | I6: 博多② 初6日 | J6: 博多② 20日累計 | K6: 博多 倍率g | L6: 大阪④ 初6日 | M6: 大阪④ 20日累計 | N6: 大阪 倍率g | O6: 採用 倍率g | P6: 札幌 会期20日 予測販売数 | Q6: 札幌 予測販売金額 | R6: 札幌 数量構成比 | S6: 札幌 販売可能数 (追納込) | T6: 予測 消化率 | U6: 会期末 残在庫 | V6: 会期中 過不足 | W6: 会期中 在庫判定
A7: 1 | B7: 4515142545082 | C7: 呪術廻戦 メタリックポストカード 展示会キービジュアル | D7: 500 | E7: 261 | F7: 790 | G7: 1316 | H7: =IF(F7=0,"",G7*(1+前提・入力!$B$9)/F7) -> 1.7462688 | I7: 559 | J7: 987 | K7: =IF(I7=0,"",J7/I7) -> 1.765653 | L7: 1277 | M7: 2325 | N7: =IF(L7=0,"",M7/L7) -> 1.8206735 | O7: =IFERROR((IF(N7="",0,N7*前提・入力!$B$5)+IF(K7="",0,K7*前提・入力!$B$6)+IF(H7="",0,H7*前提・入力!$B$7))/(IF(N7="",0,前提・入力!$B$5)+IF(K7="",0,前提・入力!$B$6)+IF(H7="",0,前提・入力!$B$7)),前提・入力!$B$10) -> 1.7883172 | P7: =ROUND(E7*O7,0) -> 467 | Q7: =P7*D7 -> 233500 | R7: =IFERROR(P7/P$49,0) -> 0.053432494 | S7: 1000 | T7: =IFERROR(P7/S7,0) -> 0.467 | U7: =MAX(0,S7-P7) -> 533 | V7: =P7-S7 -> -533 | W7: =IF(V7>0,"会期中に在庫切れ",IF(T7>=0.9,"要注意(90%超)",IF(T7>=0.5,"適正","在庫余剰"))) -> 在庫余剰
A8: 2 | B8: 4515142545099 | C8: 呪術廻戦 クリアファイル 展示会キービジュアル | D8: 600 | E8: 283 | F8: 812 | G8: 1466 | H8: =IF(F8=0,"",G8*(1+前提・入力!$B$9)/F8) -> 1.8926061 | I8: 486 | J8: 898 | K8: =IF(I8=0,"",J8/I8) -> 1.8477366 | L8: 1137 | M8: 1965 | N8: =IF(L8=0,"",M8/L8) -> 1.7282322 | O8: =IFERROR((IF(N8="",0,N8*前提・入力!$B$5)+IF(K8="",0,K8*前提・入力!$B$6)+IF(H8="",0,H8*前提・入力!$B$7))/(IF(N8="",0,前提・入力!$B$5)+IF(K8="",0,前提・入力!$B$6)+IF(H8="",0,前提・入力!$B$7)),前提・入力!$B$10) -> 1.7992018 | P8: =ROUND(E8*O8,0) -> 509 | Q8: =P8*D8 -> 305400 | R8: =IFERROR(P8/P$49,0) -> 0.058237986 | S8: 1000 | T8: =IFERROR(P8/S8,0) -> 0.509 | U8: =MAX(0,S8-P8) -> 491 | V8: =P8-S8 -> -491 | W8: =IF(V8>0,"会期中に在庫切れ",IF(T8>=0.9,"要注意(90%超)",IF(T8>=0.5,"適正","在庫余剰"))) -> 適正
A9: 3 | B9: 4515142545105 | C9: 呪術廻戦 懐玉・玉折 ポストカードセット（5枚入） | D9: 1000 | E9: 102 | F9: 430 | G9: 601 | H9: =IF(F9=0,"",G9*(1+前提・入力!$B$9)/F9) -> 1.465171 | I9: 217 | J9: 384 | K9: =IF(I9=0,"",J9/I9) -> 1.7695853 | L9: 715 | M9: 1132 | N9: =IF(L9=0,"",M9/L9) -> 1.5832168 | O9: =IFERROR((IF(N9="",0,N9*前提・入力!$B$5)+IF(K9="",0,K9*前提・入力!$B$6)+IF(H9="",0,H9*前提・入力!$B$7))/(IF(N9="",0,前提・入力!$B$5)+IF(K9="",0,前提・入力!$B$6)+IF(H9="",0,前提・入力!$B$7)),前提・入力!$B$10) -> 1.6002974 | P9: =ROUND(E9*O9,0) -> 163 | Q9: =P9*D9 -> 163000 | R9: =IFERROR(P9/P$49,0) -> 0.018649886 | S9: 450 | T9: =IFERROR(P9/S9,0) -> 0.36222222 | U9: =MAX(0,S9-P9) -> 287 | V9: =P9-S9 -> -287 | W9: =IF(V9>0,"会期中に在庫切れ",IF(T9>=0.9,"要注意(90%超)",IF(T9>=0.5,"適正","在庫余剰"))) -> 在庫余剰
A10: 4 | B10: 4515142545112 | C10: 呪術廻戦 渋谷事変 ポストカードセット（9枚入） | D10: 1800 | E10: 144 | F10: 666 | G10: 922 | H10: =IF(F10=0,"",G10*(1+前提・入力!$B$9)/F10) -> 1.4512391 | I10: 280 | J10: 442 | K10: =IF(I10=0,"",J10/I10) -> 1.5785714 | L10: 784 | M10: 1310 | N10: =IF(L10=0,"",M10/L10) -> 1.6709184 | O10: =IFERROR((IF(N10="",0,N10*前提・入力!$B$5)+IF(K10="",0,K10*前提・入力!$B$6)+IF(H10="",0,H10*前提・入力!$B$7))/(IF(N10="",0,前提・入力!$B$5)+IF(K10="",0,前提・入力!$B$6)+IF(H10="",0,前提・入力!$B$7)),前提・入力!$B$10) -> 1.5929118 | P10: =ROUND(E10*O10,0) -> 229 | Q10: =P10*D10 -> 412200 | R10: =IFERROR(P10/P$49,0) -> 0.026201373 | S10: 800 | T10: =IFERROR(P10/S10,0) -> 0.28625 | U10: =MAX(0,S10-P10) -> 571 | V10: =P10-S10 -> -571 | W10: =IF(V10>0,"会期中に在庫切れ",IF(T10>=0.9,"要注意(90%超)",IF(T10>=0.5,"適正","在庫余剰"))) -> 在庫余剰
A11: 5 | B11: 4515142545129 | C11: 呪術廻戦 懐玉・玉折 ブラインド缶バッジ（全5種） | D11: 600 | E11: 268 | F11: 7505 | G11: 10777 | H11: =IF(F11=0,"",G11*(1+前提・入力!$B$9)/F11) -> 1.5053222 | I11: 2716 | J11: 6948 | K11: =IF(I11=0,"",J11/I11) -> 2.5581738 | L11: 6209 | M11: 8936 | N11: =IF(L11=0,"",M11/L11) -> 1.4392012 | O11: =IFERROR((IF(N11="",0,N11*前提・入力!$B$5)+IF(K11="",0,K11*前提・入力!$B$6)+IF(H11="",0,H11*前提・入力!$B$7))/(IF(N11="",0,前提・入力!$B$5)+IF(K11="",0,前提・入力!$B$6)+IF(H11="",0,前提・入力!$B$7)),前提・入力!$B$10) -> 1.7354746 | P11: =ROUND(E11*O11,0) -> 465 | Q11: =P11*D11 -> 279000 | R11: =IFERROR(P11/P$49,0) -> 0.053203661 | S11: 9000 | T11: =IFERROR(P11/S11,0) -> 0.051666667 | U11: =MAX(0,S11-P11) -> 8535 | V11: =P11-S11 -> -8535 | W11: =IF(V11>0,"会期中に在庫切れ",IF(T11>=0.9,"要注意(90%超)",IF(T11>=0.5,"適正","在庫余剰"))) -> 在庫余剰
A12: 6 | B12: 4515142545136 | C12: 呪術廻戦 渋谷事変 ブラインド缶バッジ（全9種） | D12: 600 | E12: 704 | F12: 10406 | G12: 15602 | H12: =IF(F12=0,"",G12*(1+前提・入力!$B$9)/F12) -> 1.5717329 | I12: 3521 | J12: 8314 | K12: =IF(I12=0,"",J12/I12) -> 2.361261 | L12: 10485 | M12: 18611 | N12: =IF(L12=0,"",M12/L12) -> 1.7750119 | O12: =IFERROR((IF(N12="",0,N12*前提・入力!$B$5)+IF(K12="",0,K12*前提・入力!$B$6)+IF(H12="",0,H12*前提・入力!$B$7))/(IF(N12="",0,前提・入力!$B$5)+IF(K12="",0,前提・入力!$B$6)+IF(H12="",0,前提・入力!$B$7)),前提・入力!$B$10) -> 1.8707544 | P12: =ROUND(E12*O12,0) -> 1317 | Q12: =P12*D12 -> 790200 | R12: =IFERROR(P12/P$49,0) -> 0.1506865 | S12: 13991 | T12: =IFERROR(P12/S12,0) -> 0.094131942 | U12: =MAX(0,S12-P12) -> 12674 | V12: =P12-S12 -> -12674 | W12: =IF(V12>0,"会期中に在庫切れ",IF(T12>=0.9,"要注意(90%超)",IF(T12>=0.5,"適正","在庫余剰"))) -> 在庫余剰
A13: 7 | B13: 4515142545143 | C13: 呪術廻戦 懐玉・玉折 ブラインドダイカットステッカー（全5種） | D13: 600 | E13: 108 | F13: 282 | G13: 520 | H13: =IF(F13=0,"",G13*(1+前提・入力!$B$9)/F13) -> 1.9330208 | I13: 190 | J13: 349 | K13: =IF(I13=0,"",J13/I13) -> 1.8368421 | L13: 551 | M13: 940 | N13: =IF(L13=0,"",M13/L13) -> 1.7059891 | O13: =IFERROR((IF(N13="",0,N13*前提・入力!$B$5)+IF(K13="",0,K13*前提・入力!$B$6)+IF(H13="",0,H13*前提・入力!$B$7))/(IF(N13="",0,前提・入力!$B$5)+IF(K13="",0,前提・入力!$B$6)+IF(H13="",0,前提・入力!$B$7)),前提・入力!$B$10) -> 1.7954603 | P13: =ROUND(E13*O13,0) -> 194 | Q13: =P13*D13 -> 116400 | R13: =IFERROR(P13/P$49,0) -> 0.022196796 | S13: 350 | T13: =IFERROR(P13/S13,0) -> 0.55428571 | U13: =MAX(0,S13-P13) -> 156 | V13: =P13-S13 -> -156 | W13: =IF(V13>0,"会期中に在庫切れ",IF(T13>=0.9,"要注意(90%超)",IF(T13>=0.5,"適正","在庫余剰"))) -> 適正
A14: 8 | B14: 4515142545150 | C14: 呪術廻戦 渋谷事変 ブラインドダイカットステッカー（全9種） | D14: 600 | E14: 173 | F14: 588 | G14: 1107 | H14: =IF(F14=0,"",G14*(1+前提・入力!$B$9)/F14) -> 1.9735702 | I14: 330 | J14: 608 | K14: =IF(I14=0,"",J14/I14) -> 1.8424242 | L14: 972 | M14: 1758 | N14: =IF(L14=0,"",M14/L14) -> 1.808642 | O14: =IFERROR((IF(N14="",0,N14*前提・入力!$B$5)+IF(K14="",0,K14*前提・入力!$B$6)+IF(H14="",0,H14*前提・入力!$B$7))/(IF(N14="",0,前提・入力!$B$5)+IF(K14="",0,前提・入力!$B$6)+IF(H14="",0,前提・入力!$B$7)),前提・入力!$B$10) -> 1.8583196 | P14: =ROUND(E14*O14,0) -> 321 | Q14: =P14*D14 -> 192600 | R14: =IFERROR(P14/P$49,0) -> 0.036727689 | S14: 900 | T14: =IFERROR(P14/S14,0) -> 0.35666667 | U14: =MAX(0,S14-P14) -> 579 | V14: =P14-S14 -> -579 | W14: =IF(V14>0,"会期中に在庫切れ",IF(T14>=0.9,"要注意(90%超)",IF(T14>=0.5,"適正","在庫余剰"))) -> 在庫余剰
A15: 9 | B15: 4515142545372 | C15: 呪術廻戦 懐玉・玉折 クリアファイル（五条 悟） | D15: 600 | E15: 87 | F15: 225 | G15: 313 | H15: =IF(F15=0,"",G15*(1+前提・入力!$B$9)/F15) -> 1.4582907 | I15: 185 | J15: 265 | K15: =IF(I15=0,"",J15/I15) -> 1.4324324 | L15: 494 | M15: 743 | N15: =IF(L15=0,"",M15/L15) -> 1.5040486 | O15: =IFERROR((IF(N15="",0,N15*前提・入力!$B$5)+IF(K15="",0,K15*前提・入力!$B$6)+IF(H15="",0,H15*前提・入力!$B$7))/(IF(N15="",0,前提・入力!$B$5)+IF(K15="",0,前提・入力!$B$6)+IF(H15="",0,前提・入力!$B$7)),前提・入力!$B$10) -> 1.4747051 | P15: =ROUND(E15*O15,0) -> 128 | Q15: =P15*D15 -> 76800 | R15: =IFERROR(P15/P$49,0) -> 0.014645309 | S15: 300 | T15: =IFERROR(P15/S15,0) -> 0.42666667 | U15: =MAX(0,S15-P15) -> 172 | V15: =P15-S15 -> -172 | W15: =IF(V15>0,"会期中に在庫切れ",IF(T15>=0.9,"要注意(90%超)",IF(T15>=0.5,"適正","在庫余剰"))) -> 在庫余剰
A16: 10 | B16: 4515142545389 | C16: 呪術廻戦 懐玉・玉折 クリアファイル（夏油 傑） | D16: 600 | E16: 33 | F16: 96 | G16: 141 | H16: =IF(F16=0,"",G16*(1+前提・入力!$B$9)/F16) -> 1.5396789 | I16: 80 | J16: 108 | K16: =IF(I16=0,"",J16/I16) -> 1.35 | L16: 187 | M16: 277 | N16: =IF(L16=0,"",M16/L16) -> 1.4812834 | O16: =IFERROR((IF(N16="",0,N16*前提・入力!$B$5)+IF(K16="",0,K16*前提・入力!$B$6)+IF(H16="",0,H16*前提・入力!$B$7))/(IF(N16="",0,前提・入力!$B$5)+IF(K16="",0,前提・入力!$B$6)+IF(H16="",0,前提・入力!$B$7)),前提・入力!$B$10) -> 1.4630614 | P16: =ROUND(E16*O16,0) -> 48 | Q16: =P16*D16 -> 28800 | R16: =IFERROR(P16/P$49,0) -> 0.0054919908 | S16: 100 | T16: =IFERROR(P16/S16,0) -> 0.48 | U16: =MAX(0,S16-P16) -> 52 | V16: =P16-S16 -> -52 | W16: =IF(V16>0,"会期中に在庫切れ",IF(T16>=0.9,"要注意(90%超)",IF(T16>=0.5,"適正","在庫余剰"))) -> 在庫余剰
A17: 11 | B17: 4515142545396 | C17: 呪術廻戦 懐玉・玉折 クリアファイル（家入 硝子） | D17: 600 | E17: 10 | F17: 11 | G17: 37 | H17: =IF(F17=0,"",G17*(1+前提・入力!$B$9)/F17) -> 3.5260732 | I17: 17 | J17: 30 | K17: =IF(I17=0,"",J17/I17) -> 1.7647059 | L17: 36 | M17: 78 | N17: =IF(L17=0,"",M17/L17) -> 2.1666667 | O17: =IFERROR((IF(N17="",0,N17*前提・入力!$B$5)+IF(K17="",0,K17*前提・入力!$B$6)+IF(H17="",0,H17*前提・入力!$B$7))/(IF(N17="",0,前提・入力!$B$5)+IF(K17="",0,前提・入力!$B$6)+IF(H17="",0,前提・入力!$B$7)),前提・入力!$B$10) -> 2.4060281 | P17: =ROUND(E17*O17,0) -> 24 | Q17: =P17*D17 -> 14400 | R17: =IFERROR(P17/P$49,0) -> 0.0027459954 | S17: 50 | T17: =IFERROR(P17/S17,0) -> 0.48 | U17: =MAX(0,S17-P17) -> 26 | V17: =P17-S17 -> -26 | W17: =IF(V17>0,"会期中に在庫切れ",IF(T17>=0.9,"要注意(90%超)",IF(T17>=0.5,"適正","在庫余剰"))) -> 在庫余剰
A18: 12 | B18: 4515142545402 | C18: 呪術廻戦 懐玉・玉折 クリアファイル（七海 建人） | D18: 600 | E18: 19 | F18: 41 | G18: 58 | H18: =IF(F18=0,"",G18*(1+前提・入力!$B$9)/F18) -> 1.4829497 | I18: 20 | J18: 43 | K18: =IF(I18=0,"",J18/I18) -> 2.15 | L18: 83 | M18: 142 | N18: =IF(L18=0,"",M18/L18) -> 1.7108434 | O18: =IFERROR((IF(N18="",0,N18*前提・入力!$B$5)+IF(K18="",0,K18*前提・入力!$B$6)+IF(H18="",0,H18*前提・入力!$B$7))/(IF(N18="",0,前提・入力!$B$5)+IF(K18="",0,前提・入力!$B$6)+IF(H18="",0,前提・入力!$B$7)),前提・入力!$B$10) -> 1.7636591 | P18: =ROUND(E18*O18,0) -> 34 | Q18: =P18*D18 -> 20400 | R18: =IFERROR(P18/P$49,0) -> 0.0038901602 | S18: 50 | T18: =IFERROR(P18/S18,0) -> 0.68 | U18: =MAX(0,S18-P18) -> 16 | V18: =P18-S18 -> -16 | W18: =IF(V18>0,"会期中に在庫切れ",IF(T18>=0.9,"要注意(90%超)",IF(T18>=0.5,"適正","在庫余剰"))) -> 適正
... A48: 42 | B48: 4515142545365 | C48: 伏黒 恵 イメージフラグメントケース | D48: 25000 | E48: 1 | F48: 4 | G48: 8 | H48: =IF(F48=0,"",G48*(1+前提・入力!$B$9)/F48) -> 2.0965841 | I48: 1 | J48: 2 | K48: =IF(I48=0,"",J48/I48) -> 2 | L48: 4 | M48: 8 | N48: =IF(L48=0,"",M48/L48) -> 2 | O48: =IFERROR((IF(N48="",0,N48*前提・入力!$B$5)+IF(K48="",0,K48*前提・入力!$B$6)+IF(H48="",0,H48*前提・入力!$B$7))/(IF(N48="",0,前提・入力!$B$5)+IF(K48="",0,前提・入力!$B$6)+IF(H48="",0,前提・入力!$B$7)),前提・入力!$B$10) -> 2.024146 | P48: =ROUND(E48*O48,0) -> 2 | Q48: =P48*D48 -> 50000 | R48: =IFERROR(P48/P$49,0) -> 0.00022883295 | S48: 6 | T48: =IFERROR(P48/S48,0) -> 0.33333333 | U48: =MAX(0,S48-P48) -> 4 | V48: =P48-S48 -> -4 | W48: =IF(V48>0,"会期中に在庫切れ",IF(T48>=0.9,"要注意(90%超)",IF(T48>=0.5,"適正","在庫余剰"))) -> 在庫余剰
C49: 合計（LEGS 42SKU） | E49: =SUM(E7:E48) -> 5077 | F49: =SUM(F7:F48) -> 38843 | G49: =SUM(G7:G48) -> 58600 | I49: =SUM(I7:I48) -> 15767 | J49: =SUM(J7:J48) -> 33235 | L49: =SUM(L7:L48) -> 38417 | M49: =SUM(M7:M48) -> 63740 | O49: =IFERROR(P49/E49,0) -> 1.7214891 | P49: =SUM(P7:P48) -> 8740 | Q49: =SUM(Q7:Q48) -> 6680400 | R49: 1 | S49: =SUM(S7:S48) -> 50506 | T49: =IFERROR(P49/S49,0) -> 0.17304875 | U49: =SUM(U7:U48) -> 41768 | V49: =SUM(V7:V48) -> -41766 | W49: =COUNTIF(W7:W48,"会期中に在庫切れ")&"品目" -> 1品目

Sheet ②会場別構成比
A1: ② 会場別 物販実績とLEGS構成比／東京対比 会場比率
A2: 物販売上＝レジ袋代・音声ガイド・当日券を除く商品売上（税込）。LEGS＝本42SKU（各会場の商品分類「レッグス」と完全一致）
A4: ■ 会場別 実績・予測サマリー
A5: 項目 | B5: 東京対比 算出根拠 | C5: 東京 | D5: 名古屋 | E5: 博多 | F5: 大阪 | G5: 札幌 | H5: 札幌(予測) | I5: 石川 香林坊大和 | J5: 仙台 Ebeans | K5: 神戸阪急 | L5: 鳥取島根 夢みなとタワー | M5: 東京凱旋 東京建物ぴあホール
A6: 会期 | C6: 25/12/5(金)-12/29(月) 池袋サンシャインシティ | D6: 26/3/18(水)-4/5(日) 松坂屋 | E6: 26/4/23(木)-5/18(月) 博多阪急 | F6: 26/6/10(水)-6/29(月) 阪急梅田 | G6: 26/7/22(水)-8/10(月) 札幌大丸 | H6: 26/7/22(水)-8/10(月) 会期20日 予測 | I6: 26/8/14(金)-8/31(月) 石川 香林坊大和 | J6: 26/9/5(土)-10/4(日) 仙台 Ebeans | K6: 26/12/16(水)-27/1/7(木) 神戸阪急 | L6: 27/3/15-4/4 鳥取島根 夢みなとタワー | M6: 27年4-5月 東京凱旋 東京建物ぴあホール
A7: 会期日数 | C7: 25 | D7: 19 | E7: 26 | F7: 20 | G7: 20 | H7: 20 | I7: 18 | J7: 30 | K7: 21 | L7: 21 | M7: 25
A8: データ実績日数 | C8: 25 | D8: 19 | E8: 26 | F8: 20 | G8: 8 | H8: 予測 | I8: 予測 | J8: 予測 | K8: 予測 | L8: 予測 | M8: 予測
A9: 入場者数 | C9: 47339 | D9: 19764 | E9: 18993 | F9: 31267 | G9: 3880 | H9: 7784
A10: 全物販 販売数量 | C10: 383342 | D10: 169802 | E10: 112198 | F10: 238658 | G10: 22685 | H10: =G10*1.642236 -> 37254.124 | I10: =前提・入力!$B$13*前提・入力!$B$23 -> 42167.62 | J10: =前提・入力!$B$13*前提・入力!$B$24 -> 49834.46 | K10: =前提・入力!$B$13*前提・入力!$B$25 -> 46001.04 | L10: =前提・入力!$B$13*前提・入力!$B$26 -> 34500.78 | M10: =前提・入力!$B$13*前提・入力!$B$27 -> 191671
A11: 全物販 販売金額(税込) | C11: 358193925 | D11: 138575410 | E11: 105540655 | F11: 215184570 | G11: 22859680 | H11: =G11*1.591259 -> 36375672 | I11: =前提・入力!$B$12*前提・入力!$B$23 -> 39401332 | J11: =前提・入力!$B$12*前提・入力!$B$24 -> 46565210 | K11: =前提・入力!$B$12*前提・入力!$B$25 -> 42983271 | L11: =前提・入力!$B$12*前提・入力!$B$26 -> 32237453 | M11: =前提・入力!$B$12*前提・入力!$B$27 -> 1.7909696e+08
A12: LEGS 販売数量 | C12: 148185 | D12: 58600 | E12: 44871 | F12: 63740 | G12: 5077 | H12: =①札幌予測確定!P49 -> 8740 | I12: =ROUND(I13/前提・入力!$B$31,0) -> 9471 | J12: =ROUND(J13/前提・入力!$B$31,0) -> 11193 | K12: =ROUND(K13/前提・入力!$B$31,0) -> 10332 | L12: =ROUND(L13/前提・入力!$B$31,0) -> 7749 | M12: =ROUND(M13/前提・入力!$B$31,0) -> 43051
A13: LEGS 販売金額(税込) | C13: 102186200 | D13: 41479600 | E13: 31026800 | F13: 45507600 | G13: 4058700 | H13: =①札幌予測確定!Q49 -> 6680400 | I13: =I11*前提・入力!$B$30 -> 7236061.8 | J13: =J11*前提・入力!$B$30 -> 8551709.4 | K13: =K11*前提・入力!$B$30 -> 7893885.6 | L13: =L11*前提・入力!$B$30 -> 5920414.2 | M13: =M11*前提・入力!$B$30 -> 32891190
A14: LEGS 数量構成比 | C14: =C12/C10 -> 0.38656083 | D14: =D12/D10 -> 0.34510783 | E14: =E12/E10 -> 0.39992691 | F14: =F12/F10 -> 0.26707674 | G14: =G12/G10 -> 0.22380428 | H14: =H12/H10 -> 0.2346049 | I14: =I12/I10 -> 0.22460362 | J14: =J12/J10 -> 0.22460362 | ... M14: =M12/M10 -> 0.22460883
A15: LEGS 金額構成比 | C15: =C13/C11 -> 0.28528178 | D15: =D13/D11 -> 0.29932872 | E15: =E13/E11 -> 0.2939796 | F15: =F13/F11 -> 0.21148171 | G15: =G13/G11 -> 0.17754842 | H15: =H13/H11 -> 0.18365022 | I15: =I13/I11 -> 0.18365018 | J15: =J13/J11 -> 0.18365018 | ... M15: =M13/M11 -> 0.18365018
A16: 東京対比（数量） | C16: =C10/$C$10 -> 1 | D16: =D10/$C$10 -> 0.44295172 | E16: =E10/$C$10 -> 0.29268382 | F16: =F10/$C$10 -> 0.62257201 | G16: =G10/$C$10 -> 0.059176923 | H16: =H10/$C$10 -> 0.097182473 | I16: =I10/$C$10 -> 0.11 | J16: =J10/$C$10 -> 0.13 | ... M16: =M10/$C$10 -> 0.5
A17: 東京対比（金額） | B17: ユーザー指定／入力値 | C17: =C11/$C$11 -> 1 | D17: =D11/$C$11 -> 0.38687259 | E17: =E11/$C$11 -> 0.29464669 | F17: =F11/$C$11 -> 0.6007488 | G17: =G11/$C$11 -> 0.063819284 | H17: =H11/$C$11 -> 0.10155301 | I17: =前提・入力!$B$23 -> 0.11 | J17: =前提・入力!$B$24 -> 0.13 | K17: =前提・入力!$B$25 -> 0.12 | L17: =前提・入力!$B$26 -> 0.09 | M17: =前提・入力!$B$27 -> 0.5
A18: LEGS平均単価 | C18: =IFERROR(C13/C12,0) -> 689.58532 | D18: =IFERROR(D13/D12,0) -> 707.843 | E18: =IFERROR(E13/E12,0) -> 691.46665 | F18: =IFERROR(F13/F12,0) -> 713.9567 | G18: =IFERROR(G13/G12,0) -> 799.4288 | H18: =H13/H12 -> 764.34783 | I18: =I13/I12 -> 764.023 | J18: =J13/J12 -> 764.023 | K18: =K13/K12 -> 764.023 | L18: =L13/L12 -> 764.023 | M18: =M13/M12 -> 764.00525
A21: ■ 供給元別 金額構成比（各会場 会期全体。札幌は初6日実績）
A22: 供給元 | C22: 東京 | D22: 名古屋 | E22: 博多 | F22: 大阪 | G22: 札幌
A23: LEGS(42SKU) | C23: 0.28528178 | D23: 0.29932872 | E23: 0.2939796 | F23: 0.21148171 | G23: 0.17754842
A24: ムービック | C24: 0.53383923 | D24: 0.35138442 | E24: 0.32105543 | F24: 0.41894519 | G24: 0.41005955
A25: 東宝 | C25: 0.092163721 | D25: 0.078365491 | E25: 0.078289309 | F25: 0.15216207 | G25: 0.16130191
A26: MAPPA | C26: 0 | D26: 0.23618072 | E26: 0.23252348 | F26: 0.14301109 | G26: 0.18314255
A27: MBS | C27: 0.033272116 | D27: 0.034740651 | E27: 0.074152183 | F27: 0.074399944 | G27: 0.067947583
A28: 書籍 | C28: 0.055443151 | D28: 0 | E28: 0 | F28: 0 | G28: 0
A29: その他 | C29: 0 | D29: 0 | E29: 0 | F29: 0 | G29: 0
A30: 合計 | C30: =SUM(C23:C29) -> 1 | D30: =SUM(D23:D29) -> 1 | E30: =SUM(E23:E29) -> 1 | F30: =SUM(F23:F29) -> 1 | G30: =SUM(G23:G29) -> 1
A32: ■ 新規SKU投入状況（前会場までに存在しなかったJAN）
A33: 会場 | C33: 総SKU数 | D33: 新規SKU数 | E33: 新規の金額シェア(初6日) | F33: LEGS金額構成比(初6日) | G33: 備考
A34: 東京 | C34: 332 | D34: 332 | E34: 1 | F34: 0.29443142 | G34: 初回会場
A35: 名古屋 | C35: 416 | D35: 85 | E35: 0.21558758 | F35: 0.31478048 | G35: MAPPA記念商品26SKU等を追加投入
A36: 博多 | C36: 435 | D36: 19 | E36: 0.15170241 | F36: 0.2439191 | G36: 小幅追加
A37: 大阪 | C37: 515 | D37: 106 | E37: 0.19121268 | F37: 0.206477 | G37: ★新商品106SKU投入（東宝一般66・ムービック23・MAPPA16）
A38: 札幌 | C38: 382 | D38: 0 | E38: 0 | F38: 0.17754842 | G38: 新規なし。品揃えは大阪と同一

Sheet ③石川以降予測
A1: ③ 石川会場以降 5会場 LEGS商品 需要予測
A2: 会場物販売上＝東京(初回)実績 × 東京対比比率 ／ LEGS売上＝会場物販売上 × LEGS金額構成比 ／ LEGS数量＝LEGS売上 ÷ LEGS平均単価
A3: 商品別按分＝大阪20日実績の数量構成比 × ウェイト ＋ 札幌20日予測の数量構成比 × ウェイト（「前提・入力」で調整可）
A4: ※商品別表の必要数合計は、会場×商品ごとに整数丸めを行うため会場別表の合計と数個の差が生じる（発注判断に影響しない範囲）
A5: ■ 会場別 需要予測
A6: 会場 | B6: 会期 | C6: 日数 | D6: 東京対比 | E6: 会場 全物販売上 | F6: LEGS 売上 | G6: LEGS 数量 | H6: 構成比根拠
A7: 石川 香林坊大和 | B7: 26/8/14(金)-8/31(月) | C7: 18 | D7: =前提・入力!$B$23 -> 0.11 | E7: =前提・入力!$B$12*D7 -> 39401332 | F7: =E7*前提・入力!$B$30 -> 7236061.8 | G7: =ROUND(F7/前提・入力!$B$31,0) -> 9471 | H7: ユーザー指定
A8: 仙台 Ebeans | B8: 26/9/5(土)-10/4(日) | C8: 30 | D8: =前提・入力!$B$24 -> 0.13 | E8: =前提・入力!$B$12*D8 -> 46565210 | F8: =E8*前提・入力!$B$30 -> 8551709.4 | G8: =ROUND(F8/前提・入力!$B$31,0) -> 11193 | H8: ユーザー指定（コナン実績は10.5%）
A9: 神戸阪急 | B9: 26/12/16(水)-27/1/7(木) | C9: 21 | D9: =前提・入力!$B$25 -> 0.12 | E9: =前提・入力!$B$12*D9 -> 42983271 | F9: =E9*前提・入力!$B$30 -> 7893885.6 | G9: =ROUND(F9/前提・入力!$B$31,0) -> 10332 | H9: ★要確認：指定なきため仮置き
A10: 鳥取島根 夢みなとタワー | B10: 27/3/15-4/4 | C10: 21 | D10: =前提・入力!$B$26 -> 0.09 | E10: =前提・入力!$B$12*D10 -> 32237453 | F10: =E10*前提・入力!$B$30 -> 5920414.2 | G10: =ROUND(F10/前提・入力!$B$31,0) -> 7749 | H10: ユーザー指定
A11: 東京凱旋 東京建物ぴあホール | B11: 27年4-5月 | C11: 25 | D11: =前提・入力!$B$27 -> 0.5 | E11: =前提・入力!$B$12*D11 -> 1.7909696e+08 | F11: =E11*前提・入力!$B$30 -> 32891190 | G11: =ROUND(F11/前提・入力!$B$31,0) -> 43051 | H11: ユーザー指定（初回東京の50%）
A12: 石川以降 5会場 合計 | D12: =SUM(D7:D11) -> 0.95 | E12: =SUM(E7:E11) -> 3.4028423e+08 | F12: =SUM(F7:F11) -> 62493261 | G12: =SUM(G7:G11) -> 81796
A14: ■ 在庫収支（LEGS 42SKU 合計）
A15: 残在庫想定（梅田まで(SET)／総計） | B15: 274688 | C15: 在庫フロー台帳の最終「実在庫」列。会場ごとの追加発注→販売→検品を積み上げた値
A16: うち札幌会場へ納品（初回＋追納） | B16: =①札幌予測確定!S49 -> 50506 | C16: 札幌の販売可能数。2026/7/31・8/1 札幌会場追納リスト（レッグス商品分のみ抜粋）（LEGS計310個）を含む
A17: 差引 倉庫残（石川以降へ即出荷可） | B17: =B15-B16 -> 224182 | C17: 札幌へ引き当てた分を除いた手元在庫
A18: 札幌 会期20日 予測販売数 | B18: =①札幌予測確定!P49 -> 8740
A19: うち札幌へ追納が必要 | B19: =R72 -> 2 | C19: 札幌の会期20日予測が納品済数を上回る分。倉庫残から充当する（運営欠品報告への対応分）
A20: 札幌 会期末 残在庫（返送見込） | B20: =①札幌予測確定!U49 -> 41768 | C20: 品目別に下限0で集計（在庫切れ品はマイナスにしない）
A21: うち石川以降へスライド可能 | B21: =B20*前提・入力!$B$37 -> 41768 | C21: スライド率は「前提・入力」で調整
A22: 石川以降 供給可能在庫 合計 | B22: =B17-B19+B21 -> 265948 | C22: ＝倉庫残 − 札幌への追納 ＋ 札幌からの返送スライド
A23: 確定済み追加発注（入荷予定） | B23: 1200 | C23: 発注判断済みの分。宿儺の指風お菓子 1,200SET（仙台 Ebeans入荷）
A24: 石川以降 5会場 必要数 | B24: =G12 -> 81796
A25: 全体過不足（供給可能＋確定発注−必要） | B25: =B22+B23-B24 -> 185352 | C25: プラス＝全体では在庫充足。ただし商品別には過不足が生じる
A26: 追加生産 必要数（商品別不足の合計） | B26: =W72 -> 2554 | C26: 下表の商品別「追加生産必要数」の合計。全体余剰でも品目別には不足が出る
A28: ■ 商品別 石川以降 必要数と在庫過不足
A29: No. | B29: JAN | C29: 商品名 | D29: 大阪④ 20日実績 | E29: 大阪 構成比 | F29: 札幌⑤ 20日予測 | G29: 札幌 構成比 | H29: 採用 按分構成比 | I29: 石川 必要数 | J29: 仙台 必要数 | K29: 神戸阪急 必要数 | L29: 鳥取島根 必要数 | M29: 東京凱旋 必要数 | N29: 石川以降 必要数 計 | O29: ★残在庫想定 (梅田会場後) | P29: うち札幌 納品済 | Q29: 差引 倉庫残 | R29: 札幌へ 追納必要数 | S29: 札幌会期末 返送(スライド) | T29: 石川以降 供給可能計 | U29: 確定発注 (入荷予定) | V29: 過不足 (必要−供給可能−確定) | W29: 追加生産 必要数 | X29: 推奨発注数 (安全率込)
A30: 1 | B30: 4515142545082 | C30: 呪術廻戦 メタリックポストカード 展示会キービジュアル | D30: 2325 | E30: =IFERROR(D30/D$72,0) -> 0.03647631 | F30: =①札幌予測確定!P7 -> 467 | G30: =IFERROR(F30/F$72,0) -> 0.053432494 | H30: =E30*前提・入力!$B$32+G30*前提・入力!$B$33 -> 0.044954402 | I30: =ROUND($H30*③石川以降予測!$G$7,0) -> 426 | J30: =ROUND($H30*③石川以降予測!$G$8,0) -> 503 | K30: =ROUND($H30*③石川以降予測!$G$9,0) -> 464 | L30: =ROUND($H30*③石川以降予測!$G$10,0) -> 348 | M30: =ROUND($H30*③石川以降予測!$G$11,0) -> 1935 | N30: =SUM(I30:M30) -> 3676 | O30: 3264 | P30: =①札幌予測確定!S7 -> 1000 | Q30: =O30-P30 -> 2264 | R30: =MAX(0,①札幌予測確定!P7-①札幌予測確定!S7) -> 0 | S30: =ROUND(①札幌予測確定!U7*前提・入力!$B$37,0) -> 533 | T30: =Q30-R30+S30 -> 2797 | U30: 0 | V30: =N30-T30-U30 -> 879 | W30: =MAX(0,V30) -> 879 | X30: =IF(W30>0,ROUNDUP(W30*(1+前提・入力!$B$35),0),0) -> 967
A31: 2 | B31: 4515142545099 | C31: 呪術廻戦 クリアファイル 展示会キービジュアル | D31: 1965 | E31: =IFERROR(D31/D$72,0) -> 0.030828365 | F31: =①札幌予測確定!P8 -> 509 | G31: =IFERROR(F31/F$72,0) -> 0.058237986 | H31: =E31*前提・入力!$B$32+G31*前提・入力!$B$33 -> 0.044533176 | I31: =ROUND($H31*③石川以降予測!$G$7,0) -> 422 | J31: =ROUND($H31*③石川以降予測!$G$8,0) -> 498 | K31: =ROUND($H31*③石川以降予測!$G$9,0) -> 460 | L31: =ROUND($H31*③石川以降予測!$G$10,0) -> 345 | M31: =ROUND($H31*③石川以降予測!$G$11,0) -> 1917 | N31: =SUM(I31:M31) -> 3642 | O31: 5037 | P31: =①札幌予測確定!S8 -> 1000 | Q31: =O31-P31 -> 4037 | R31: =MAX(0,①札幌予測確定!P8-①札幌予測確定!S8) -> 0 | S31: =ROUND(①札幌予測確定!U8*前提・入力!$B$37,0) -> 491 | T31: =Q31-R31+S31 -> 4528 | U31: 0 | V31: =N31-T31-U31 -> -886 | W31: =MAX(0,V31) -> 0 | X31: =IF(W31>0,ROUNDUP(W31*(1+前提・入力!$B$35),0),0) -> 0
A32: 3 | B32: 4515142545105 | C32: 呪術廻戦 懐玉・玉折 ポストカードセット（5枚入） | D32: 1132 | E32: =IFERROR(D32/D$72,0) -> 0.017759649 | F32: =①札幌予測確定!P9 -> 163 | G32: =IFERROR(F32/F$72,0) -> 0.018649886 | H32: =E32*前提・入力!$B$32+G32*前提・入力!$B$33 -> 0.018204767 | I32: =ROUND($H32*③石川以降予測!$G$7,0) -> 172 | J32: =ROUND($H32*③石川以降予測!$G$8,0) -> 204 | K32: =ROUND($H32*③石川以降予測!$G$9,0) -> 188 | L32: =ROUND($H32*③石川以降予測!$G$10,0) -> 141 | M32: =ROUND($H32*③石川以降予測!$G$11,0) -> 784 | N32: =SUM(I32:M32) -> 1489 | O32: 6140 | P32: =①札幌予測確定!S9 -> 450 | Q32: =O32-P32 -> 5690 | R32: =MAX(0,①札幌予測確定!P9-①札幌予測確定!S9) -> 0 | S32: =ROUND(①札幌予測確定!U9*前提・入力!$B$37,0) -> 287 | T32: =Q32-R32+S32 -> 5977 | U32: 0 | V32: =N32-T32-U32 -> -4488 | W32: =MAX(0,V32) -> 0 | X32: =IF(W32>0,ROUNDUP(W32*(1+前提・入力!$B$35),0),0) -> 0
A33: 4 | B33: 4515142545112 | C33: 呪術廻戦 渋谷事変 ポストカードセット（9枚入） | D33: 1310 | E33: =IFERROR(D33/D$72,0) -> 0.020552243 | F33: =①札幌予測確定!P10 -> 229 | G33: =IFERROR(F33/F$72,0) -> 0.026201373 | H33: =E33*前提・入力!$B$32+G33*前提・入力!$B$33 -> 0.023376808 | I33: =ROUND($H33*③石川以降予測!$G$7,0) -> 221 | J33: =ROUND($H33*③石川以降予測!$G$8,0) -> 262 | K33: =ROUND($H33*③石川以降予測!$G$9,0) -> 242 | L33: =ROUND($H33*③石川以降予測!$G$10,0) -> 181 | M33: =ROUND($H33*③石川以降予測!$G$11,0) -> 1006 | N33: =SUM(I33:M33) -> 1912 | O33: 27511 | P33: =①札幌予測確定!S10 -> 800 | Q33: =O33-P33 -> 26711 | R33: =MAX(0,①札幌予測確定!P10-①札幌予測確定!S10) -> 0 | S33: =ROUND(①札幌予測確定!U10*前提・入力!$B$37,0) -> 571 | T33: =Q33-R33+S33 -> 27282 | U33: 0 | V33: =N33-T33-U33 -> -25370 | W33: =MAX(0,V33) -> 0 | X33: =IF(W33>0,ROUNDUP(W33*(1+前提・入力!$B$35),0),0) -> 0
A34: 5 | B34: 4515142545129 | C34: 呪術廻戦 懐玉・玉折 ブラインド缶バッジ（全5種） | D34: 8936 | E34: =IFERROR(D34/D$72,0) -> 0.14019454 | F34: =①札幌予測確定!P11 -> 465 | G34: =IFERROR(F34/F$72,0) -> 0.053203661 | H34: =E34*前提・入力!$B$32+G34*前提・入力!$B$33 -> 0.096699101 | I34: =ROUND($H34*③石川以降予測!$G$7,0) -> 916 | J34: =ROUND($H34*③石川以降予測!$G$8,0) -> 1082 | K34: =ROUND($H34*③石川以降予測!$G$9,0) -> 999 | L34: =ROUND($H34*③石川以降予測!$G$10,0) -> 749 | M34: =ROUND($H34*③石川以降予測!$G$11,0) -> 4163 | N34: =SUM(I34:M34) -> 7909 | O34: 39825 | P34: =①札幌予測確定!S11 -> 9000 | Q34: =O34-P34 -> 30825 | R34: =MAX(0,①札幌予測確定!P11-①札幌予測確定!S11) -> 0 | S34: =ROUND(①札幌予測確定!U11*前提・入力!$B$37,0) -> 8535 | T34: =Q34-R34+S34 -> 39360 | U34: 0 | V34: =N34-T34-U34 -> -31451 | W34: =MAX(0,V34) -> 0 | X34: =IF(W34>0,ROUNDUP(W34*(1+前提・入力!$B$35),0),0) -> 0
A35: 6 | B35: 4515142545136 | C35: 呪術廻戦 渋谷事変 ブラインド缶バッジ（全9種） | D35: 18611 | E35: =IFERROR(D35/D$72,0) -> 0.29198306 | F35: =①札幌予測確定!P12 -> 1317 | G35: =IFERROR(F35/F$72,0) -> 0.1506865 | H35: =E35*前提・入力!$B$32+G35*前提・入力!$B$33 -> 0.22133478 | I35: =ROUND($H35*③石川以降予測!$G$7,0) -> 2096 | J35: =ROUND($H35*③石川以降予測!$G$8,0) -> 2477 | K35: =ROUND($H35*③石川以降予測!$G$9,0) -> 2287 | L35: =ROUND($H35*③石川以降予測!$G$10,0) -> 1715 | M35: =ROUND($H35*③石川以降予測!$G$11,0) -> 9529 | N35: =SUM(I35:M35) -> 18104 | O35: 50834 | P35: =①札幌予測確定!S12 -> 13991 | Q35: =O35-P35 -> 36843 | R35: =MAX(0,①札幌予測確定!P12-①札幌予測確定!S12) -> 0 | S35: =ROUND(①札幌予測確定!U12*前提・入力!$B$37,0) -> 12674 | T35: =Q35-R35+S35 -> 49517 | U35: 0 | V35: =N35-T35-U35 -> -31413 | W35: =MAX(0,V35) -> 0 | X35: =IF(W35>0,ROUNDUP(W35*(1+前提・入力!$B$35),0),0) -> 0
A36: 7 | B36: 4515142545143 | C36: 呪術廻戦 懐玉・玉折 ブラインドダイカットステッカー（全5種） | D36: 940 | E36: =IFERROR(D36/D$72,0) -> 0.014747411 | F36: =①札幌予測確定!P13 -> 194 | G36: =IFERROR(F36/F$72,0) -> 0.022196796 | H36: =E36*前提・入力!$B$32+G36*前提・入力!$B$33 -> 0.018472104 | I36: =ROUND($H36*③石川以降予測!$G$7,0) -> 175 | J36: =ROUND($H36*③石川以降予測!$G$8,0) -> 207 | K36: =ROUND($H36*③石川以降予測!$G$9,0) -> 191 | L36: =ROUND($H36*③石川以降予測!$G$10,0) -> 143 | M36: =ROUND($H36*③石川以降予測!$G$11,0) -> 795 | N36: =SUM(I36:M36) -> 1511 | O36: 4542 | P36: =①札幌予測確定!S13 -> 350 | Q36: =O36-P36 -> 4192 | R36: =MAX(0,①札幌予測確定!P13-①札幌予測確定!S13) -> 0 | S36: =ROUND(①札幌予測確定!U13*前提・入力!$B$37,0) -> 156 | T36: =Q36-R36+S36 -> 4348 | U36: 0 | V36: =N36-T36-U36 -> -2837 | W36: =MAX(0,V36) -> 0 | X36: =IF(W36>0,ROUNDUP(W36*(1+前提・入力!$B$35),0),0) -> 0
A37: 8 | B37: 4515142545150 | C37: 呪術廻戦 渋谷事変 ブラインドダイカットステッカー（全9種） | D37: 1758 | E37: =IFERROR(D37/D$72,0) -> 0.027580797 | F37: =①札幌予測確定!P14 -> 321 | G37: =IFERROR(F37/F$72,0) -> 0.036727689 | H37: =E37*前提・入力!$B$32+G37*前提・入力!$B$33 -> 0.032154243 | I37: =ROUND($H37*③石川以降予測!$G$7,0) -> 305 | J37: =ROUND($H37*③石川以降予測!$G$8,0) -> 360 | K37: =ROUND($H37*③石川以降予測!$G$9,0) -> 332 | L37: =ROUND($H37*③石川以降予測!$G$10,0) -> 249 | M37: =ROUND($H37*③石川以降予測!$G$11,0) -> 1384 | N37: =SUM(I37:M37) -> 2630 | O37: 8551 | P37: =①札幌予測確定!S14 -> 900 | Q37: =O37-P37 -> 7651 | R37: =MAX(0,①札幌予測確定!P14-①札幌予測確定!S14) -> 0 | S37: =ROUND(①札幌予測確定!U14*前提・入力!$B$37,0) -> 579 | T37: =Q37-R37+S37 -> 8230 | U37: 0 | V37: =N37-T37-U37 -> -5600 | W37: =MAX(0,V37) -> 0 | X37: =IF(W37>0,ROUNDUP(W37*(1+前提・入力!$B$35),0),0) -> 0
A38: 9 | B38: 4515142545372 | C38: 呪術廻戦 懐玉・玉折 クリアファイル（五条 悟） | D38: 743 | E38: =IFERROR(D38/D$72,0) -> 0.01165673 | F38: =①札幌予測確定!P15 -> 128 | G38: =IFERROR(F38/F$72,0) -> 0.014645309 | H38: =E38*前提・入力!$B$32+G38*前提・入力!$B$33 -> 0.01315102 | I38: =ROUND($H38*③石川以降予測!$G$7,0) -> 125 | J38: =ROUND($H38*③石川以降予測!$G$8,0) -> 147 | K38: =ROUND($H38*③石川以降予測!$G$9,0) -> 136 | L38: =ROUND($H38*③石川以降予測!$G$10,0) -> 102 | M38: =ROUND($H38*③石川以降予測!$G$11,0) -> 566 | N38: =SUM(I38:M38) -> 1076 | O38: 8759 | P38: =①札幌予測確定!S15 -> 300 | Q38: =O38-P38 -> 8459 | R38: =MAX(0,①札幌予測確定!P15-①札幌予測確定!S15) -> 0 | S38: =ROUND(①札幌予測確定!U15*前提・入力!$B$37,0) -> 172 | T38: =Q38-R38+S38 -> 8631 | U38: 0 | V38: =N38-T38-U38 -> -7555 | W38: =MAX(0,V38) -> 0 | X38: =IF(W38>0,ROUNDUP(W38*(1+前提・入力!$B$35),0),0) -> 0
A39: 10 | B39: 4515142545389 | C39: 呪術廻戦 懐玉・玉折 クリアファイル（夏油 傑） | D39: 277 | E39: =IFERROR(D39/D$72,0) -> 0.0043457797 | F39: =①札幌予測確定!P16 -> 48 | G39: =IFERROR(F39/F$72,0) -> 0.0054919908 | H39: =E39*前提・入力!$B$32+G39*前提・入力!$B$33 -> 0.0049188853 | I39: =ROUND($H39*③石川以降予測!$G$7,0) -> 47 | J39: =ROUND($H39*③石川以降予測!$G$8,0) -> 55 | K39: =ROUND($H39*③石川以降予測!$G$9,0) -> 51 | L39: =ROUND($H39*③石川以降予測!$G$10,0) -> 38 | M39: =ROUND($H39*③石川以降予測!$G$11,0) -> 212 | N39: =SUM(I39:M39) -> 403 | O39: 4935 | P39: =①札幌予測確定!S16 -> 100 | Q39: =O39-P39 -> 4835 | R39: =MAX(0,①札幌予測確定!P16-①札幌予測確定!S16) -> 0 | S39: =ROUND(①札幌予測確定!U16*前提・入力!$B$37,0) -> 52 | T39: =Q39-R39+S39 -> 4887 | U39: 0 | V39: =N39-T39-U39 -> -4484 | W39: =MAX(0,V39) -> 0 | X39: =IF(W39>0,ROUNDUP(W39*(1+前提・入力!$B$35),0),0) -> 0
A40: 11 | B40: 4515142545396 | C40: 呪術廻戦 懐玉・玉折 クリアファイル（家入 硝子） | D40: 78 | E40: =IFERROR(D40/D$72,0) -> 0.0012237214 | F40: =①札幌予測確定!P17 -> 24 | G40: =IFERROR(F40/F$72,0) -> 0.0027459954 | H40: =E40*前提・入力!$B$32+G40*前提・入力!$B$33 -> 0.0019848584 | I40: =ROUND($H40*③石川以降予測!$G$7,0) -> 19 | J40: =ROUND($H40*③石川以降予測!$G$8,0) -> 22 | K40: =ROUND($H40*③石川以降予測!$G$9,0) -> 21 | L40: =ROUND($H40*③石川以降予測!$G$10,0) -> 15 | M40: =ROUND($H40*③石川以降予測!$G$11,0) -> 85 | N40: =SUM(I40:M40) -> 162 | O40: 640 | P40: =①札幌予測確定!S17 -> 50 | Q40: =O40-P40 -> 590 | R40: =MAX(0,①札幌予測確定!P17-①札幌予測確定!S17) -> 0 | S40: =ROUND(①札幌予測確定!U17*前提・入力!$B$37,0) -> 26 | T40: =Q40-R40+S40 -> 616 | U40: 0 | V40: =N40-T40-U40 -> -454 | W40: =MAX(0,V40) -> 0 | X40: =IF(W40>0,ROUNDUP(W40*(1+前提・入力!$B$35),0),0) -> 0
A41: 12 | B41: 4515142545402 | C41: 呪術廻戦 懐玉・玉折 クリアファイル（七海 建人） | D41: 142 | E41: =IFERROR(D41/D$72,0) -> 0.0022278004 | F41: =①札幌予測確定!P18 -> 34 | G41: =IFERROR(F41/F$72,0) -> 0.0038901602 | H41: =E41*前提・入力!$B$32+G41*前提・入力!$B$33 -> 0.0030589803 | I41: =ROUND($H41*③石川以降予測!$G$7,0) -> 29 | J41: =ROUND($H41*③石川以降予測!$G$8,0) -> 34 | K41: =ROUND($H41*③石川以降予測!$G$9,0) -> 32 | L41: =ROUND($H41*③石川以降予測!$G$10,0) -> 24 | M41: =ROUND($H41*③石川以降予測!$G$11,0) -> 132 | N41: =SUM(I41:M41) -> 251 | O41: 953 | P41: =①札幌予測確定!S18 -> 50 | Q41: =O41-P41 -> 903 | R41: =MAX(0,①札幌予測確定!P18-①札幌予測確定!S18) -> 0 | S41: =ROUND(①札幌予測確定!U18*前提・入力!$B$37,0) -> 16 | T41: =Q41-R41+S41 -> 919 | U41: 0 | V41: =N41-T41-U41 -> -668 | W41: =MAX(0,V41) -> 0 | X41: =IF(W41>0,ROUNDUP(W41*(1+前提・入力!$B$35),0),0) -> 0
... A71: 42 | B71: 4515142545365 | C71: 伏黒 恵 イメージフラグメントケース | D71: 8 | E71: =IFERROR(D71/D$72,0) -> 0.00012550988 | F71: =①札幌予測確定!P48 -> 2 | G71: =IFERROR(F71/F$72,0) -> 0.00022883295 | H71: =E71*前提・入力!$B$32+G71*前提・入力!$B$33 -> 0.00017717142 | I71: =ROUND($H71*③石川以降予測!$G$7,0) -> 2 | J71: =ROUND($H71*③石川以降予測!$G$8,0) -> 2 | K71: =ROUND($H71*③石川以降予測!$G$9,0) -> 2 | L71: =ROUND($H71*③石川以降予測!$G$10,0) -> 1 | M71: =ROUND($H71*③石川以降予測!$G$11,0) -> 8 | N71: =SUM(I71:M71) -> 15 | O71: 49 | P71: =①札幌予測確定!S48 -> 6 | Q71: =O71-P71 -> 43 | R71: =MAX(0,①札幌予測確定!P48-①札幌予測確定!S48) -> 0 | S71: =ROUND(①札幌予測確定!U48*前提・入力!$B$37,0) -> 4 | T71: =Q71-R71+S71 -> 47 | U71: 0 | V71: =N71-T71-U71 -> -32 | W71: =MAX(0,V71) -> 0 | X71: =IF(W71>0,ROUNDUP(W71*(1+前提・入力!$B$35),0),0) -> 0
...

Sheet ④追加発注判定
A1: ④ 追加発注 必要有無の判定（札幌会期中 ＋ 石川以降5会場）
A2: 【札幌会期中】会期20日予測 vs 札幌への納品済 販売可能数 ／ 【石川以降】5会場必要数 vs 札幌会期末残在庫＋倉庫在庫 ※2026/7/28 SPJ様欠品報告を突合
A3: 推奨発注数＝不足数×(1+安全率10%)を切り上げ。T〜W列に欠品発生会場・最終発注期限（会期初日−生産日数−バッファ）・残日数・緊急度を記載
A6: No. | B6: JAN | C6: 商品名 | D6: 税込単価 | E6: 札幌 初6日実績 | F6: 札幌 会期20日予測 | G6: 札幌 販売可能数 (追納込) | H6: 札幌 予測消化率 | I6: 札幌会期中 過不足 | J6: 札幌会期中 判定 | K6: 札幌会期中 推奨発注数 | L6: 石川以降 必要数 | M6: 札幌からの スライド | N6: 7/8実在庫の 倉庫残 | O6: 石川以降 過不足 | P6: 石川以降 判定 | Q6: 石川以降 推奨発注数 | R6: 発注合計 (札幌+石川以降) | S6: 発注金額 (税込小売換算) | T6: 欠品発生 会場 | U6: 最終発注期限 | V6: 基準日からの 残日数 | W6: 発注の緊急度 | X6: 優先度 | Y6: 運営 欠品報告 (7/28 SPJ様) | Z6: モデル×現場 突合 | AA6: 備考
A7: 1 | B7: 4515142545082 | C7: 呪術廻戦 メタリックポストカード 展示会キービジュアル | D7: 500 | E7: =①札幌予測確定!E7 -> 261 | F7: =①札幌予測確定!P7 -> 467 | G7: =①札幌予測確定!S7 -> 1000 | H7: =IFERROR(F7/G7,0) -> 0.467 | I7: =F7-G7 -> -533 | J7: =IF(I7>0,"要 追加発注",IF(H7>=0.9,"要注意(90%超)",IF(H7>=0.5,"適正","在庫余剰"))) -> 在庫余剰 | K7: =IF(I7>0,ROUNDUP(I7*(1+前提・入力!$B$35),0),0) -> 0 | L7: =③石川以降予測!N30 -> 3676 | M7: =③石川以降予測!S30 -> 533 | N7: =③石川以降予測!Q30 -> 2264 | O7: =L7-M7-N7 -> 879 | P7: =IF(O7>0,"要 追加生産",IF(L7=0,"—","在庫で充足")) -> 要 追加生産 | Q7: =③石川以降予測!X30 -> 967 | R7: =K7+Q7 -> 967 | S7: =R7*D7 -> 483500 | T7: 東京凱旋 東京建物ぴあホール | U7: =DATE(2027,4,1)-30-前提・入力!$B$38 -> 46434 | V7: =IF(OR(U7="",U7="再生産不可"),"",U7-前提・入力!$B$39) -> 201 | W7: =IF(T7="—","—",IF(U7="再生産不可","×再生産不可",_xlfn.IFS(V7<0,"★期限超過",V7<=30,"★至急(30日以内)",V7<=90,"要着手(90日以内)",TRUE(),"余裕あり"))) -> 余裕あり | X7: =IF(Y7<>"",IF(FALSE(),"S:現場欠品(追納不可)","S:現場欠品"),IF(I7>0,"A:会期中欠品",IF(O7>1000,"B:大口",IF(O7>0,"C:通常","D:不要")))) -> C:通常 | Z7: =IF(Y7<>"",IF(I7>0,"◎ 一致（モデルも会期中欠品を検知）",IF(H7>=0.7,"○ 整合（予測消化率70%超）","△ モデル未検知：現場報告を優先")),IF(I7>0,"▲ モデルのみ検知：現場に在庫状況を確認","—")) -> — | AA7: 博多会場で完売（実績が在庫上限で頭打ち＝予測は控えめ）
A8: 2 | B8: 4515142545099 | C8: 呪術廻戦 クリアファイル 展示会キービジュアル | D8: 600 | E8: =①札幌予測確定!E8 -> 283 | F8: =①札幌予測確定!P8 -> 509 | G8: =①札幌予測確定!S8 -> 1000 | H8: =IFERROR(F8/G8,0) -> 0.509 | I8: =F8-G8 -> -491 | J8: =IF(I8>0,"要 追加発注",IF(H8>=0.9,"要注意(90%超)",IF(H8>=0.5,"適正","在庫余剰"))) -> 適正 | K8: =IF(I8>0,ROUNDUP(I8*(1+前提・入力!$B$35),0),0) -> 0 | L8: =③石川以降予測!N31 -> 3642 | M8: =③石川以降予測!S31 -> 491 | N8: =③石川以降予測!Q31 -> 4037 | O8: =L8-M8-N8 -> -886 | P8: =IF(O8>0,"要 追加生産",IF(L8=0,"—","在庫で充足")) -> 在庫で充足 | Q8: =③石川以降予測!X31 -> 0 | R8: =K8+Q8 -> 0 | S8: =R8*D8 -> 0 | T8: — | V8: =IF(OR(U8="",U8="再生産不可"),"",U8-前提・入力!$B$39) | W8: =IF(T8="—","—",IF(U8="再生産不可","×再生産不可",_xlfn.IFS(V8<0,"★期限超過",V8<=30,"★至急(30日以内)",V8<=90,"要着手(90日以内)",TRUE(),"余裕あり"))) -> — | X8: =IF(Y8<>"",IF(FALSE(),"S:現場欠品(追納不可)","S:現場欠品"),IF(I8>0,"A:会期中欠品",IF(O8>1000,"B:大口",IF(O8>0,"C:通常","D:不要")))) -> D:不要 | Z8: =IF(Y8<>"",IF(I8>0,"◎ 一致（モデルも会期中欠品を検知）",IF(H8>=0.7,"○ 整合（予測消化率70%超）","△ モデル未検知：現場報告を優先")),IF(I8>0,"▲ モデルのみ検知：現場に在庫状況を確認","—")) -> —
A9: 3 | B9: 4515142545105 | C9: 呪術廻戦 懐玉・玉折 ポストカードセット（5枚入） | D9: 1000 | E9: =①札幌予測確定!E9 -> 102 | F9: =①札幌予測確定!P9 -> 163 | G9: =①札幌予測確定!S9 -> 450 | H9: =IFERROR(F9/G9,0) -> 0.36222222 | I9: =F9-G9 -> -287 | J9: =IF(I9>0,"要 追加発注",IF(H9>=0.9,"要注意(90%超)",IF(H9>=0.5,"適正","在庫余剰"))) -> 在庫余剰 | K9: =IF(I9>0,ROUNDUP(I9*(1+前提・入力!$B$35),0),0) -> 0 | L9: =③石川以降予測!N32 -> 1489 | M9: =③石川以降予測!S32 -> 287 | N9: =③石川以降予測!Q32 -> 5690 | O9: =L9-M9-N9 -> -4488 | P9: =IF(O9>0,"要 追加生産",IF(L9=0,"—","在庫で充足")) -> 在庫で充足 | Q9: =③石川以降予測!X32 -> 0 | R9: =K9+Q9 -> 0 | S9: =R9*D9 -> 0 | T9: — | V9: =IF(OR(U9="",U9="再生産不可"),"",U9-前提・入力!$B$39) | W9: =IF(T9="—","—",IF(U9="再生産不可","×再生産不可",_xlfn.IFS(V9<0,"★期限超過",V9<=30,"★至急(30日以内)",V9<=90,"要着手(90日以内)",TRUE(),"余裕あり"))) -> — | X9: =IF(Y9<>"",IF(FALSE(),"S:現場欠品(追納不可)","S:現場欠品"),IF(I9>0,"A:会期中欠品",IF(O9>1000,"B:大口",IF(O9>0,"C:通常","D:不要")))) -> D:不要 | Z9: =IF(Y9<>"",IF(I9>0,"◎ 一致（モデルも会期中欠品を検知）",IF(H9>=0.7,"○ 整合（予測消化率70%超）","△ モデル未検知：現場報告を優先")),IF(I9>0,"▲ モデルのみ検知：現場に在庫状況を確認","—")) -> —
A10: 4 | B10: 4515142545112 | C10: 呪術廻戦 渋谷事変 ポストカードセット（9枚入） | D10: 1800 | E10: =①札幌予測確定!E10 -> 144 | F10: =①札幌予測確定!P10 -> 229 | G10: =①札幌予測確定!S10 -> 800 | H10: =IFERROR(F10/G10,0) -> 0.28625 | I10: =F10-G10 -> -571 | J10: =IF(I10>0,"要 追加発注",IF(H10>=0.9,"要注意(90%超)",IF(H10>=0.5,"適正","在庫余剰"))) -> 在庫余剰 | K10: =IF(I10>0,ROUNDUP(I10*(1+前提・入力!$B$35),0),0) -> 0 | L10: =③石川以降予測!N33 -> 1912 | M10: =③石川以降予測!S33 -> 571 | N10: =③石川以降予測!Q33 -> 26711 | O10: =L10-M10-N10 -> -25370 | P10: =IF(O10>0,"要 追加生産",IF(L10=0,"—","在庫で充足")) -> 在庫で充足 | Q10: =③石川以降予測!X33 -> 0 | R10: =K10+Q10 -> 0 | S10: =R10*D10 -> 0 | T10: — | V10: =IF(OR(U10="",U10="再生産不可"),"",U10-前提・入力!$B$39) | W10: =IF(T10="—","—",IF(U10="再生産不可","×再生産不可",_xlfn.IFS(V10<0,"★期限超過",V10<=30,"★至急(30日以内)",V10<=90,"要着手(90日以内)",TRUE(),"余裕あり"))) -> — | X10: =IF(Y10<>"",IF(FALSE(),"S:現場欠品(追納不可)","S:現場欠品"),IF(I10>0,"A:会期中欠品",IF(O10>1000,"B:大口",IF(O10>0,"C:通常","D:不要")))) -> D:不要 | Z10: =IF(Y10<>"",IF(I10>0,"◎ 一致（モデルも会期中欠品を検知）",IF(H10>=0.7,"○ 整合（予測消化率70%超）","△ モデル未検知：現場報告を優先")),IF(I10>0,"▲ モデルのみ検知：現場に在庫状況を確認","—")) -> —
A11: 5 | B11: 4515142545129 | C11: 呪術廻戦 懐玉・玉折 ブラインド缶バッジ（全5種） | D11: 600 | E11: =①札幌予測確定!E11 -> 268 | F11: =①札幌予測確定!P11 -> 465 | G11: =①札幌予測確定!S11 -> 9000 | H11: =IFERROR(F11/G11,0) -> 0.051666667 | I11: =F11-G11 -> -8535 | J11: =IF(I11>0,"要 追加発注",IF(H11>=0.9,"要注意(90%超)",IF(H11>=0.5,"適正","在庫余剰"))) -> 在庫余剰 | K11: =IF(I11>0,ROUNDUP(I11*(1+前提・入力!$B$35),0),0) -> 0 | L11: =③石川以降予測!N34 -> 7909 | M11: =③石川以降予測!S34 -> 8535 | N11: =③石川以降予測!Q34 -> 30825 | O11: =L11-M11-N11 -> -31451 | P11: =IF(O11>0,"要 追加生産",IF(L11=0,"—","在庫で充足")) -> 在庫で充足 | Q11: =③石川以降予測!X34 -> 0 | R11: =K11+Q11 -> 0 | S11: =R11*D11 -> 0 | T11: — | V11: =IF(OR(U11="",U11="再生産不可"),"",U11-前提・入力!$B$39) | W11: =IF(T11="—","—",IF(U11="再生産不可","×再生産不可",_xlfn.IFS(V11<0,"★期限超過",V11<=30,"★至急(30日以内)",V11<=90,"要着手(90日以内)",TRUE(),"余裕あり"))) -> — | X11: =IF(Y11<>"",IF(FALSE(),"S:現場欠品(追納不可)","S:現場欠品"),IF(I11>0,"A:会期中欠品",IF(O11>1000,"B:大口",IF(O11>0,"C:通常","D:不要")))) -> D:不要 | Z11: =IF(Y11<>"",IF(I11>0,"◎ 一致（モデルも会期中欠品を検知）",IF(H11>=0.7,"○ 整合（予測消化率70%超）","△ モデル未検知：現場報告を優先")),IF(I11>0,"▲ モデルのみ検知：現場に在庫状況を確認","—")) -> — | AA11: 博多会場で完売（実績が在庫上限で頭打ち＝予測は控えめ）
A12: 6 | B12: 4515142545136 | C12: 呪術廻戦 渋谷事変 ブラインド缶バッジ（全9種） | D12: 600 | E12: =①札幌予測確定!E12 -> 704 | F12: =①札幌予測確定!P12 -> 1317 | G12: =①札幌予測確定!S12 -> 13991 | H12: =IFERROR(F12/G12,0) -> 0.094131942 | I12: =F12-G12 -> -12674 | J12: =IF(I12>0,"要 追加発注",IF(H12>=0.9,"要注意(90%超)",IF(H12>=0.5,"適正","在庫余剰"))) -> 在庫余剰 | K12: =IF(I12>0,ROUNDUP(I12*(1+前提・入力!$B$35),0),0) -> 0 | L12: =③石川以降予測!N35 -> 18104 | M12: =③石川以降予測!S35 -> 12674 | N12: =③石川以降予測!Q35 -> 36843 | O12: =L12-M12-N12 -> -31413 | P12: =IF(O12>0,"要 追加生産",IF(L12=0,"—","在庫で充足")) -> 在庫で充足 | Q12: =③石川以降予測!X35 -> 0 | R12: =K12+Q12 -> 0 | S12: =R12*D12 -> 0 | T12: — | V12: =IF(OR(U12="",U12="再生産不可"),"",U12-前提・入力!$B$39) | W12: =IF(T12="—","—",IF(U12="再生産不可","×再生産不可",_xlfn.IFS(V12<0,"★期限超過",V12<=30,"★至急(30日以内)",V12<=90,"要着手(90日以内)",TRUE(),"余裕あり"))) -> — | X12: =IF(Y12<>"",IF(FALSE(),"S:現場欠品(追納不可)","S:現場欠品"),IF(I12>0,"A:会期中欠品",IF(O12>1000,"B:大口",IF(O12>0,"C:通常","D:不要")))) -> D:不要 | Z12: =IF(Y12<>"",IF(I12>0,"◎ 一致（モデルも会期中欠品を検知）",IF(H12>=0.7,"○ 整合（予測消化率70%超）","△ モデル未検知：現場報告を優先")),IF(I12>0,"▲ モデルのみ検知：現場に在庫状況を確認","—")) -> — | AA12: 博多会場で完売（実績が在庫上限で頭打ち＝予測は控えめ）
A13: 7 | B13: 4515142545143 | C13: 呪術廻戦 懐玉・玉折 ブラインドダイカットステッカー（全5種） | D13: 600 | E13: =①札幌予測確定!E13 -> 108 | F13: =①札幌予測確定!P13 -> 194 | G13: =①札幌予測確定!S13 -> 350 | H13: =IFERROR(F13/G13,0) -> 0.55428571 | I13: =F13-G13 -> -156 | J13: =IF(I13>0,"要 追加発注",IF(H13>=0.9,"要注意(90%超)",IF(H13>=0.5,"適正","在庫余剰"))) -> 適正 | K13: =IF(I13>0,ROUNDUP(I13*(1+前提・入力!$B$35),0),0) -> 0 | L13: =③石川以降予測!N36 -> 1511 | M13: =③石川以降予測!S36 -> 156 | N13: =③石川以降予測!Q36 -> 4192 | O13: =L13-M13-N13 -> -2837 | P13: =IF(O13>0,"要 追加生産",IF(L13=0,"—","在庫で充足")) -> 在庫で充足 | Q13: =③石川以降予測!X36 -> 0 | R13: =K13+Q13 -> 0 | S13: =R13*D13 -> 0 | T13: — | V13: =IF(OR(U13="",U13="再生産不可"),"",U13-前提・入力!$B$39) | W13: =IF(T13="—","—",IF(U13="再生産不可","×再生産不可",_xlfn.IFS(V13<0,"★期限超過",V13<=30,"★至急(30日以内)",V13<=90,"要着手(90日以内)",TRUE(),"余裕あり"))) -> — | X13: =IF(Y13<>"",IF(FALSE(),"S:現場欠品(追納不可)","S:現場欠品"),IF(I13>0,"A:会期中欠品",IF(O13>1000,"B:大口",IF(O13>0,"C:通常","D:不要")))) -> D:不要 | Z13: =IF(Y13<>"",IF(I13>0,"◎ 一致（モデルも会期中欠品を検知）",IF(H13>=0.7,"○ 整合（予測消化率70%超）","△ モデル未検知：現場報告を優先")),IF(I13>0,"▲ モデルのみ検知：現場に在庫状況を確認","—")) -> — | AA13: 博多会場で完売（実績が在庫上限で頭打ち＝予測は控えめ）
A14: 8 | B14: 4515142545150 | C14: 呪術廻戦 渋谷事変 ブラインドダイカットステッカー（全9種） | D14: 600 | E14: =①札幌予測確定!E14 -> 173 | F14: =①札幌予測確定!P14 -> 321 | G14: =①札幌予測確定!S14 -> 900 | H14: =IFERROR(F14/G14,0) -> 0.35666667 | I14: =F14-G14 -> -579 | J14: =IF(I14>0,"要 追加発注",IF(H14>=0.9,"要注意(90%超)",IF(H14>=0.5,"適正","在庫余剰"))) -> 在庫余剰 | K14: =IF(I14>0,ROUNDUP(I14*(1+前提・入力!$B$35),0),0) -> 0 | L14: =③石川以降予測!N37 -> 2630 | M14: =③石川以降予測!S37 -> 579 | N14: =③石川以降予測!Q37 -> 7651 | O14: =L14-M14-N14 -> -5600 | P14: =IF(O14>0,"要 追加生産",IF(L14=0,"—","在庫で充足")) -> 在庫で充足 | Q14: =③石川以降予測!X37 -> 0 | R14: =K14+Q14 -> 0 | S14: =R14*D14 -> 0 | T14: — | V14: =IF(OR(U14="",U14="再生産不可"),"",U14-前提・入力!$B$39) | W14: =IF(T14="—","—",IF(U14="再生産不可","×再生産不可",_xlfn.IFS(V14<0,"★期限超過",V14<=30,"★至急(30日以内)",V14<=90,"要着手(90日以内)",TRUE(),"余裕あり"))) -> — | X14: =IF(Y14<>"",IF(FALSE(),"S:現場欠品(追納不可)","S:現場欠品"),IF(I14>0,"A:会期中欠品",IF(O14>1000,"B:大口",IF(O14>0,"C:通常","D:不要")))) -> D:不要 | Z14: =IF(Y14<>"",IF(I14>0,"◎ 一致（モデルも会期中欠品を検知）",IF(H14>=0.7,"○ 整合（予測消化率70%超）","△ モデル未検知：現場報告を優先")),IF(I14>0,"▲ モデルのみ検知：現場に在庫状況を確認","—")) -> — | AA14: 博多会場で完売（実績が在庫上限で頭打ち＝予測は控えめ）
A15: 9 | B15: 4515142545372 | C15: 呪術廻戦 懐玉・玉折 クリアファイル（五条 悟） | D15: 600 | E15: =①札幌予測確定!E15 -> 87 | F15: =①札幌予測確定!P15 -> 128 | G15: =①札幌予測確定!S15 -> 300 | H15: =IFERROR(F15/G15,0) -> 0.42666667 | I15: =F15-G15 -> -172 | J15: =IF(I15>0,"要 追加発注",IF(H15>=0.9,"要注意(90%超)",IF(H15>=0.5,"適正","在庫余剰"))) -> 在庫余剰 | K15: =IF(I15>0,ROUNDUP(I15*(1+前提・入力!$B$35),0),0) -> 0 | L15: =③石川以降予測!N38 -> 1076 | M15: =③石川以降予測!S38 -> 172 | N15: =③石川以降予測!Q38 -> 8459 | O15: =L15-M15-N15 -> -7555 | P15: =IF(O15>0,"要 追加生産",IF(L15=0,"—","在庫で充足")) -> 在庫で充足 | Q15: =③石川以降予測!X38 -> 0 | R15: =K15+Q15 -> 0 | S15: =R15*D15 -> 0 | T15: — | V15: =IF(OR(U15="",U15="再生産不可"),"",U15-前提・入力!$B$39) | W15: =IF(T15="—","—",IF(U15="再生産不可","×再生産不可",_xlfn.IFS(V15<0,"★期限超過",V15<=30,"★至急(30日以内)",V15<=90,"要着手(90日以内)",TRUE(),"余裕あり"))) -> — | X15: =IF(Y15<>"",IF(FALSE(),"S:現場欠品(追納不可)","S:現場欠品"),IF(I15>0,"A:会期中欠品",IF(O15>1000,"B:大口",IF(O15>0,"C:通常","D:不要")))) -> D:不要 | Z15: =IF(Y15<>"",IF(I15>0,"◎ 一致（モデルも会期中欠品を検知）",IF(H15>=0.7,"○ 整合（予測消化率70%超）","△ モデル未検知：現場報告を優先")),IF(I15>0,"▲ モデルのみ検知：現場に在庫状況を確認","—")) -> — | AA15: 博多会場で完売（実績が在庫上限で頭打ち＝予測は控えめ）
A16: 10 | B16: 4515142545389 | C16: 呪術廻戦 懐玉・玉折 クリアファイル（夏油 傑） | D16: 600 | E16: =①札幌予測確定!E16 -> 33 | F16: =①札幌予測確定!P16 -> 48 | G16: =①札幌予測確定!S16 -> 100 | H16: =IFERROR(F16/G16,0) -> 0.48 | I16: =F16-G16 -> -52 | J16: =IF(I16>0,"要 追加発注",IF(H16>=0.9,"要注意(90%超)",IF(H16>=0.5,"適正","在庫余剰"))) -> 在庫余剰 | K16: =IF(I16>0,ROUNDUP(I16*(1+前提・入力!$B$35),0),0) -> 0 | L16: =③石川以降予測!N39 -> 403 | M16: =③石川以降予測!S39 -> 52 | N16: =③石川以降予測!Q39 -> 4835 | O16: =L16-M16-N16 -> -4484 | P16: =IF(O16>0,"要 追加生産",IF(L16=0,"—","在庫で充足")) -> 在庫で充足 | Q16: =③石川以降予測!X39 -> 0 | R16: =K16+Q16 -> 0 | S16: =R16*D16 -> 0 | T16: — | V16: =IF(OR(U16="",U16="再生産不可"),"",U16-前提・入力!$B$39) | W16: =IF(T16="—","—",IF(U16="再生産不可","×再生産不可",_xlfn.IFS(V16<0,"★期限超過",V16<=30,"★至急(30日以内)",V16<=90,"要着手(90日以内)",TRUE(),"余裕あり"))) -> — | X16: =IF(Y16<>"",IF(FALSE(),"S:現場欠品(追納不可)","S:現場欠品"),IF(I16>0,"A:会期中欠品",IF(O16>1000,"B:大口",IF(O16>0,"C:通常","D:不要")))) -> D:不要 | Z16: =IF(Y16<>"",IF(I16>0,"◎ 一致（モデルも会期中欠品を検知）",IF(H16>=0.7,"○ 整合（予測消化率70%超）","△ モデル未検知：現場報告を優先")),IF(I16>0,"▲ モデルのみ検知：現場に在庫状況を確認","—")) -> —
A17: 11 | B17: 4515142545396 | C17: 呪術廻戦 懐玉・玉折 クリアファイル（家入 硝子） | D17: 600 | E17: =①札幌予測確定!E17 -> 10 | F17: =①札幌予測確定!P17 -> 24 | G17: =①札幌予測確定!S17 -> 50 | H17: =IFERROR(F17/G17,0) -> 0.48 | I17: =F17-G17 -> -26 | J17: =IF(I17>0,"要 追加発注",IF(H17>=0.9,"要注意(90%超)",IF(H17>=0.5,"適正","在庫余剰"))) -> 在庫余剰 | K17: =IF(I17>0,ROUNDUP(I17*(1+前提・入力!$B$35),0),0) -> 0 | L17: =③石川以降予測!N40 -> 162 | M17: =③石川以降予測!S40 -> 26 | N17: =③石川以降予測!Q40 -> 590 | O17: =L17-M17-N17 -> -454 | P17: =IF(O17>0,"要 追加生産",IF(L17=0,"—","在庫で充足")) -> 在庫で充足 | Q17: =③石川以降予測!X40 -> 0 | R17: =K17+Q17 -> 0 | S17: =R17*D17 -> 0 | T17: — | V17: =IF(OR(U17="",U17="再生産不可"),"",U17-前提・入力!$B$39) | W17: =IF(T17="—","—",IF(U17="再生産不可","×再生産不可",_xlfn.IFS(V17<0,"★期限超過",V17<=30,"★至急(30日以内)",V17<=90,"要着手(90日以内)",TRUE(),"余裕あり"))) -> — | X17: =IF(Y17<>"",IF(FALSE(),"S:現場欠品(追納不可)","S:現場欠品"),IF(I17>0,"A:会期中欠品",IF(O17>1000,"B:大口",IF(O17>0,"C:通常","D:不要")))) -> D:不要 | Z17: =IF(Y17<>"",IF(I17>0,"◎ 一致（モデルも会期中欠品を検知）",IF(H17>=0.7,"○ 整合（予測消化率70%超）","△ モデル未検知：現場報告を優先")),IF(I17>0,"▲ モデルのみ検知：現場に在庫状況を確認","—")) -> — | AA17: 博多会場で完売（実績が在庫上限で頭打ち＝予測は控えめ）
A18: 12 | B18: 4515142545402 | C18: 呪術廻戦 懐玉・玉折 クリアファイル（七海 建人） | D18: 600 | E18: =①札幌予測確定!E18 -> 19 | F18: =①札幌予測確定!P18 -> 34 | G18: =①札幌予測確定!S18 -> 50 | H18: =IFERROR(F18/G18,0) -> 0.68 | I18: =F18-G18 -> -16 | J18: =IF(I18>0,"要 追加発注",IF(H18>=0.9,"要注意(90%超)",IF(H18>=0.5,"適正","在庫余剰"))) -> 適正 | K18: =IF(I18>0,ROUNDUP(I18*(1+前提・入力!$B$35),0),0) -> 0 | L18: =③石川以降予測!N41 -> 251 | M18: =③石川以降予測!S41 -> 16 | N18: =③石川以降予測!Q41 -> 903 | O18: =L18-M18-N18 -> -668 | P18: =IF(O18>0,"要 追加生産",IF(L18=0,"—","在庫で充足")) -> 在庫で充足 | Q18: =③石川以降予測!X41 -> 0 | R18: =K18+Q18 -> 0 | S18: =R18*D18 -> 0 | T18: — | V18: =IF(OR(U18="",U18="再生産不可"),"",U18-前提・入力!$B$39) | W18: =IF(T18="—","—",IF(U18="再生産不可","×再生産不可",_xlfn.IFS(V18<0,"★期限超過",V18<=30,"★至急(30日以内)",V18<=90,"要着手(90日以内)",TRUE(),"余裕あり"))) -> — | X18: =IF(Y18<>"",IF(FALSE(),"S:現場欠品(追納不可)","S:現場欠品"),IF(I18>0,"A:会期中欠品",IF(O18>1000,"B:大口",IF(O18>0,"C:通常","D:不要")))) -> D:不要 | Z18: =IF(Y18<>"",IF(I18>0,"◎ 一致（モデルも会期中欠品を検知）",IF(H18>=0.7,"○ 整合（予測消化率70%超）","△ モデル未検知：現場報告を優先")),IF(I18>0,"▲ モデルのみ検知：現場に在庫状況を確認","—")) -> —
A19: 13 | B19: 4515142545419 | C19: 呪術廻戦 懐玉・玉折 クリアファイル（灰原 雄） | D19: 600 | E19: =①札幌予測確定!E19 -> 3 | F19: =①札幌予測確定!P19 -> 5 | G19: =①札幌予測確定!S19 -> 50 | H19: =IFERROR(F19/G19,0) -> 0.1 | I19: =F19-G19 -> -45 | J19: =IF(I19>0,"要 追加発注",IF(H19>=0.9,"要注意(90%超)",IF(H19>=0.5,"適正","在庫余剰"))) -> 在庫余剰 | K19: =IF(I19>0,ROUNDUP(I19*(1+前提・入力!$B$35),0),0) -> 0 | L19: =③石川以降予測!N42 -> 51 | M19: =③石川以降予測!S42 -> 45 | N19: =③石川以降予測!Q42 -> 270 | O19: =L19-M19-N19 -> -264 | P19: =IF(O19>0,"要 追加生産",IF(L19=0,"—","在庫で充足")) -> 在庫で充足 | Q19: =③石川以降予測!X42 -> 0 | R19: =K19+Q19 -> 0 | S19: =R19*D19 -> 0 | T19: — | V19: =IF(OR(U19="",U19="再生産不可"),"",U19-前提・入力!$B$39) | W19: =IF(T19="—","—",IF(U19="再生産不可","×再生産不可",_xlfn.IFS(V19<0,"★期限超過",V19<=30,"★至急(30日以内)",V19<=90,"要着手(90日以内)",TRUE(),"余裕あり"))) -> — | X19: =IF(Y19<>"",IF(FALSE(),"S:現場欠品(追納不可)","S:現場欠品"),IF(I19>0,"A:会期中欠品",IF(O19>1000,"B:大口",IF(O19>0,"C:通常","D:不要")))) -> D:不要 | Z19: =IF(Y19<>"",IF(I19>0,"◎ 一致（モデルも会期中欠品を検知）",IF(H19>=0.7,"○ 整合（予測消化率70%超）","△ モデル未検知：現場報告を優先")),IF(I19>0,"▲ モデルのみ検知：現場に在庫状況を確認","—")) -> —
A20: 14 | B20: 4515142545426 | C20: 呪術廻戦 渋谷事変 クリアファイル（虎杖 悠仁） | D20: 600 | E20: =①札幌予測確定!E20 -> 21 | F20: =①札幌予測確定!P20 -> 38 | G20: =①札幌予測確定!S20 -> 50 | H20: =IFERROR(F20/G20,0) -> 0.76 | I20: =F20-G20 -> -12 | J20: =IF(I20>0,"要 追加発注",IF(H20>=0.9,"要注意(90%超)",IF(H20>=0.5,"適正","在庫余剰"))) -> 適正 | K20: =IF(I20>0,ROUNDUP(I20*(1+前提・入力!$B$35),0),0) -> 0 | L20: =③石川以降予測!N43 -> 271 | M20: =③石川以降予測!S43 -> 12 | N20: =③石川以降予測!Q43 -> 1740 | O20: =L20-M20-N20 -> -1481 | P20: =IF(O20>0,"要 追加生産",IF(L20=0,"—","在庫で充足")) -> 在庫で充足 | Q20: =③石川以降予測!X43 -> 0 | R20: =K20+Q20 -> 0 | S20: =R20*D20 -> 0 | T20: — | V20: =IF(OR(U20="",U20="再生産不可"),"",U20-前提・入力!$B$39) | W20: =IF(T20="—","—",IF(U20="再生産不可","×再生産不可",_xlfn.IFS(V20<0,"★期限超過",V20<=30,"★至急(30日以内)",V20<=90,"要着手(90日以内)",TRUE(),"余裕あり"))) -> — | X20: =IF(Y20<>"",IF(FALSE(),"S:現場欠品(追納不可)","S:現場欠品"),IF(I20>0,"A:会期中欠品",IF(O20>1000,"B:大口",IF(O20>0,"C:通常","D:不要")))) -> S:現場欠品 | Y20: 欠品／近々欠品 | Z20: =IF(Y20<>"",IF(I20>0,"◎ 一致（モデルも会期中欠品を検知）",IF(H20>=0.7,"○ 整合（予測消化率70%超）","△ モデル未検知：現場報告を優先")),IF(I20>0,"▲ モデルのみ検知：現場に在庫状況を確認","—")) -> ○ 整合（予測消化率70%超） | AA20: 【7/28 運営報告】欠品／近々欠品 ／ 倉庫残1,740個 → ◎倉庫からの追加納品で対応可能（追加生産は不要） ／ 博多会場で完売（実績が在庫上限で頭打ち＝予測は控えめ）
A21: 15 | B21: 4515142545433 | C21: 呪術廻戦 渋谷事変 クリアファイル（伏黒 恵） | D21: 600 | E21: =①札幌予測確定!E21 -> 32 | F21: =①札幌予測確定!P21 -> 59 | G21: =①札幌予測確定!S21 -> 100 | H21: =IFERROR(F21/G21,0) -> 0.59 | I21: =F21-G21 -> -41 | J21: =IF(I21>0,"要 追加発注",IF(H21>=0.9,"要注意(90%超)",IF(H21>=0.5,"適正","在庫余剰"))) -> 適正 | K21: =IF(I21>0,ROUNDUP(I21*(1+前提・入力!$B$35),0),0) -> 0 | L21: =③石川以降予測!N44 -> 403 | M21: =③石川以降予測!S44 -> 41 | N21: =③石川以降予測!Q44 -> 2031 | O21: =L21-M21-N21 -> -1669 | P21: =IF(O21>0,"要 追加生産",IF(L21=0,"—","在庫で充足")) -> 在庫で充足 | Q21: =③石川以降予測!X44 -> 0 | R21: =K21+Q21 -> 0 | S21: =R21*D21 -> 0 | T21: — | V21: =IF(OR(U21="",U21="再生産不可"),"",U21-前提・入力!$B$39) | W21: =IF(T21="—","—",IF(U21="再生産不可","×再生産不可",_xlfn.IFS(V21<0,"★期限超過",V21<=30,"★至急(30日以内)",V21<=90,"要着手(90日以内)",TRUE(),"余裕あり"))) -> — | X21: =IF(Y21<>"",IF(FALSE(),"S:現場欠品(追納不可)","S:現場欠品"),IF(I21>0,"A:会期中欠品",IF(O21>1000,"B:大口",IF(O21>0,"C:通常","D:不要")))) -> D:不要 | Z21: =IF(Y21<>"",IF(I21>0,"◎ 一致（モデルも会期中欠品を検知）",IF(H21>=0.7,"○ 整合（予測消化率70%超）","△ モデル未検知：現場報告を優先")),IF(I21>0,"▲ モデルのみ検知：現場に在庫状況を確認","—")) -> — | AA21: 博多会場で完売（実績が在庫上限で頭打ち＝予測は控えめ）
A22: 16 | B22: 4515142545440 | C22: 呪術廻戦 渋谷事変 クリアファイル（釘崎 野薔薇） | D22: 600 | E22: =①札幌予測確定!E22 -> 7 | F22: =①札幌予測確定!P22 -> 15 | G22: =①札幌予測確定!S22 -> 50 | H22: =IFERROR(F22/G22,0) -> 0.3 | I22: =F22-G22 -> -35 | J22: =IF(I22>0,"要 追加発注",IF(H22>=0.9,"要注意(90%超)",IF(H22>=0.5,"適正","在庫余剰"))) -> 在庫余剰 | K22: =IF(I22>0,ROUNDUP(I22*(1+前提・入力!$B$35),0),0) -> 0 | L22: =③石川以降予測!N45 -> 112 | M22: =③石川以降予測!S45 -> 35 | N22: =③石川以降予測!Q45 -> 722 | O22: =L22-M22-N22 -> -645 | P22: =IF(O22>0,"要 追加生産",IF(L22=0,"—","在庫で充足")) -> 在庫で充足 | Q22: =③石川以降予測!X45 -> 0 | R22: =K22+Q22 -> 0 | S22: =R22*D22 -> 0 | T22: — | V22: =IF(OR(U22="",U22="再生産不可"),"",U22-前提・入力!$B$39) | W22: =IF(T22="—","—",IF(U22="再生産不可","×再生産不可",_xlfn.IFS(V22<0,"★期限超過",V22<=30,"★至急(30日以内)",V22<=90,"要着手(90日以内)",TRUE(),"余裕あり"))) -> — | X22: =IF(Y22<>"",IF(FALSE(),"S:現場欠品(追納不可)","S:現場欠品"),IF(I22>0,"A:会期中欠品",IF(O22>1000,"B:大口",IF(O22>0,"C:通常","D:不要")))) -> D:不要 | Z22: =IF(Y22<>"",IF(I22>0,"◎ 一致（モデルも会期中欠品を検知）",IF(H22>=0.7,"○ 整合（予測消化率70%超）","△ モデル未検知：現場報告を優先")),IF(I22>0,"▲ モデルのみ検知：現場に在庫状況を確認","—")) -> — | AA22: 名古屋会場で完売（実績が在庫上限で頭打ち＝予測は控えめ） ／ 博多会場で完売（実績が在庫上限で頭打ち＝予測は控えめ）
A23: 17 | B23: 4515142545457 | C23: 呪術廻戦 渋谷事変 クリアファイル（七海 建人） | D23: 600 | E23: =①札幌予測確定!E23 -> 53 | F23: =①札幌予測確定!P23 -> 93 | G23: =①札幌予測確定!S23 -> 100 | H23: =IFERROR(F23/G23,0) -> 0.93 | I23: =F23-G23 -> -7 | J23: =IF(I23>0,"要 追加発注",IF(H23>=0.9,"要注意(90%超)",IF(H23>=0.5,"適正","在庫余剰"))) -> 要注意(90%超) | K23: =IF(I23>0,ROUNDUP(I23*(1+前提・入力!$B$35),0),0) -> 0 | L23: =③石川以降予測!N46 -> 602 | M23: =③石川以降予測!S46 -> 7 | N23: =③石川以降予測!Q46 -> 2423 | O23: =L23-M23-N23 -> -1828 | P23: =IF(O23>0,"要 追加生産",IF(L23=0,"—","在庫で充足")) -> 在庫で充足 | Q23: =③石川以降予測!X46 -> 0 | R23: =K23+Q23 -> 0 | S23: =R23*D23 -> 0 | T23: — | V23: =IF(OR(U23="",U23="再生産不可"),"",U23-前提・入力!$B$39) | W23: =IF(T23="—","—",IF(U23="再生産不可","×再生産不可",_xlfn.IFS(V23<0,"★期限超過",V23<=30,"★至急(30日以内)",V23<=90,"要着手(90日以内)",TRUE(),"余裕あり"))) -> — | X23: =IF(Y23<>"",IF(FALSE(),"S:現場欠品(追納不可)","S:現場欠品"),IF(I23>0,"A:会期中欠品",IF(O23>1000,"B:大口",IF(O23>0,"C:通常","D:不要")))) -> S:現場欠品 | Y23: 欠品／近々欠品 | Z23: =IF(Y23<>"",IF(I23>0,"◎ 一致（モデルも会期中欠品を検知）",IF(H23>=0.7,"○ 整合（予測消化率70%超）","△ モデル未検知：現場報告を優先")),IF(I23>0,"▲ モデルのみ検知：現場に在庫状況を確認","—")) -> ○ 整合（予測消化率70%超） | AA23: 【7/28 運営報告】欠品／近々欠品 ／ 倉庫残2,423個 → ◎倉庫からの追加納品で対応可能（追加生産は不要） ／ 博多会場で完売（実績が在庫上限で頭打ち＝予測は控えめ）
A24: 18 | B24: 4515142545464 | C24: 呪術廻戦 渋谷事変 クリアファイル（五条 悟） | D24: 600 | E24: =①札幌予測確定!E24 -> 259 | F24: =①札幌予測確定!P24 -> 407 | G24: =①札幌予測確定!S24 -> 1500 | H24: =IFERROR(F24/G24,0) -> 0.27133333 | I24: =F24-G24 -> -1093 | J24: =IF(I24>0,"要 追加発注",IF(H24>=0.9,"要注意(90%超)",IF(H24>=0.5,"適正","在庫余剰"))) -> 在庫余剰 | K24: =IF(I24>0,ROUNDUP(I24*(1+前提・入力!$B$35),0),0) -> 0 | L24: =③石川以降予測!N47 -> 3201 | M24: =③石川以降予測!S47 -> 1093 | N24: =③石川以降予測!Q47 -> 8225 | O24: =L24-M24-N24 -> -6117 | P24: =IF(O24>0,"要 追加生産",IF(L24=0,"—","在庫で充足")) -> 在庫で充足 | Q24: =③石川以降予測!X47 -> 0 | R24: =K24+Q24 -> 0 | S24: =R24*D24 -> 0 | T24: — | V24: =IF(OR(U24="",U24="再生産不可"),"",U24-前提・入力!$B$39) | W24: =IF(T24="—","—",IF(U24="再生産不可","×再生産不可",_xlfn.IFS(V24<0,"★期限超過",V24<=30,"★至急(30日以内)",V24<=90,"要着手(90日以内)",TRUE(),"余裕あり"))) -> — | X24: =IF(Y24<>"",IF(FALSE(),"S:現場欠品(追納不可)","S:現場欠品"),IF(I24>0,"A:会期中欠品",IF(O24>1000,"B:大口",IF(O24>0,"C:通常","D:不要")))) -> D:不要 | Z24: =IF(Y24<>"",IF(I24>0,"◎ 一致（モデルも会期中欠品を検知）",IF(H24>=0.7,"○ 整合（予測消化率70%超）","△ モデル未検知：現場報告を優先")),IF(I24>0,"▲ モデルのみ検知：現場に在庫状況を確認","—")) -> — | AA24: 博多会場で完売（実績が在庫上限で頭打ち＝予測は控えめ）
A25: 19 | B25: 4515142545471 | C25: 呪術廻戦 渋谷事変 クリアファイル（夏油 傑） | D25: 600 | E25: =①札幌予測確定!E25 -> 10 | F25: =①札幌予測確定!P25 -> 16 | G25: =①札幌予測確定!S25 -> 50 | H25: =IFERROR(F25/G25,0) -> 0.32 | I25: =F25-G25 -> -34 | J25: =IF(I25>0,"要 追加発注",IF(H25>=0.9,"要注意(90%超)",IF(H25>=0.5,"適正","在庫余剰"))) -> 在庫余剰 | K25: =IF(I25>0,ROUNDUP(I25*(1+前提・入力!$B$35),0),0) -> 0 | L25: =③石川以降予測!N48 -> 104 | M25: =③石川以降予測!S48 -> 34 | N25: =③石川以降予測!Q48 -> 2190 | O25: =L25-M25-N25 -> -2120 | P25: =IF(O25>0,"要 追加生産",IF(L25=0,"—","在庫で充足")) -> 在庫で充足 | Q25: =③石川以降予測!X48 -> 0 | R25: =K25+Q25 -> 0 | S25: =R25*D25 -> 0 | T25: — | V25: =IF(OR(U25="",U25="再生産不可"),"",U25-前提・入力!$B$39) | W25: =IF(T25="—","—",IF(U25="再生産不可","×再生産不可",_xlfn.IFS(V25<0,"★期限超過",V25<=30,"★至急(30日以内)",V25<=90,"要着手(90日以内)",TRUE(),"余裕あり"))) -> — | X25: =IF(Y25<>"",IF(FALSE(),"S:現場欠品(追納不可)","S:現場欠品"),IF(I25>0,"A:会期中欠品",IF(O25>1000,"B:大口",IF(O25>0,"C:通常","D:不要")))) -> D:不要 | Z25: =IF(Y25<>"",IF(I25>0,"◎ 一致（モデルも会期中欠品を検知）",IF(H25>=0.7,"○ 整合（予測消化率70%超）","△ モデル未検知：現場報告を優先")),IF(I25>0,"▲ モデルのみ検知：現場に在庫状況を確認","—")) -> — | AA25: 博多会場で完売（実績が在庫上限で頭打ち＝予測は控えめ）
A26: 20 | B26: 4515142545488 | C26: 呪術廻戦 渋谷事変 クリアファイル（真人） | D26: 600 | E26: =①札幌予測確定!E26 -> 8 | F26: =①札幌予測確定!P26 -> 14 | G26: =①札幌予測確定!S26 -> 30 | H26: =IFERROR(F26/G26,0) -> 0.46666667 | I26: =F26-G26 -> -16 | J26: =IF(I26>0,"要 追加発注",IF(H26>=0.9,"要注意(90%超)",IF(H26>=0.5,"適正","在庫余剰"))) -> 在庫余剰 | K26: =IF(I26>0,ROUNDUP(I26*(1+前提・入力!$B$35),0),0) -> 0 | L26: =③石川以降予測!N49 -> 94 | M26: =③石川以降予測!S49 -> 16 | N26: =③石川以降予測!Q49 -> 271 | O26: =L26-M26-N26 -> -193 | P26: =IF(O26>0,"要 追加生産",IF(L26=0,"—","在庫で充足")) -> 在庫で充足 | Q26: =③石川以降予測!X49 -> 0 | R26: =K26+Q26 -> 0 | S26: =R26*D26 -> 0 | T26: — | V26: =IF(OR(U26="",U26="再生産不可"),"",U26-前提・入力!$B$39) | W26: =IF(T26="—","—",IF(U26="再生産不可","×再生産不可",_xlfn.IFS(V26<0,"★期限超過",V26<=30,"★至急(30日以内)",V26<=90,"要着手(90日以内)",TRUE(),"余裕あり"))) -> — | X26: =IF(Y26<>"",IF(FALSE(),"S:現場欠品(追納不可)","S:現場欠品"),IF(I26>0,"A:会期中欠品",IF(O26>1000,"B:大口",IF(O26>0,"C:通常","D:不要")))) -> D:不要 | Z26: =IF(Y26<>"",IF(I26>0,"◎ 一致（モデルも会期中欠品を検知）",IF(H26>=0.7,"○ 整合（予測消化率70%超）","△ モデル未検知：現場報告を優先")),IF(I26>0,"▲ モデルのみ検知：現場に在庫状況を確認","—")) -> — | AA26: 博多会場で完売（実績が在庫上限で頭打ち＝予測は控えめ）
A27: 21 | B27: 4515142545495 | C27: 呪術廻戦 渋谷事変 クリアファイル（脹相） | D27: 600 | E27: =①札幌予測確定!E27 -> 50 | F27: =①札幌予測確定!P27 -> 90 | G27: =①札幌予測確定!S27 -> 100 | H27: =IFERROR(F27/G27,0) -> 0.9 | I27: =F27-G27 -> -10 | J27: =IF(I27>0,"要 追加発注",IF(H27>=0.9,"要注意(90%超)",IF(H27>=0.5,"適正","在庫余剰"))) -> 要注意(90%超) | K27: =IF(I27>0,ROUNDUP(I27*(1+前提・入力!$B$35),0),0) -> 0 | L27: =③石川以降予測!N50 -> 583 | M27: =③石川以降予測!S50 -> 10 | N27: =③石川以降予測!Q50 -> 208 | O27: =L27-M27-N27 -> 365 | P27: =IF(O27>0,"要 追加生産",IF(L27=0,"—","在庫で充足")) -> 要 追加生産 | Q27: =③石川以降予測!X50 -> 402 | R27: =K27+Q27 -> 402 | S27: =R27*D27 -> 241200 | T27: 神戸阪急 | U27: =DATE(2026,12,16)-30-前提・入力!$B$38 -> 46328 | V27: =IF(OR(U27="",U27="再生産不可"),"",U27-前提・入力!$B$39) -> 95 | W27: =IF(T27="—","—",IF(U27="再生産不可","×再生産不可",_xlfn.IFS(V27<0,"★期限超過",V27<=30,"★至急(30日以内)",V27<=90,"要着手(90日以内)",TRUE(),"余裕あり"))) -> 余裕あり | X27: =IF(Y27<>"",IF(FALSE(),"S:現場欠品(追納不可)","S:現場欠品"),IF(I27>0,"A:会期中欠品",IF(O27>1000,"B:大口",IF(O27>0,"C:通常","D:不要")))) -> S:現場欠品 | Y27: 欠品／近々欠品 | Z27: =IF(Y27<>"",IF(I27>0,"◎ 一致（モデルも会期中欠品を検知）",IF(H27>=0.7,"○ 整合（予測消化率70%超）","△ モデル未検知：現場報告を優先")),IF(I27>0,"▲ モデルのみ検知：現場に在庫状況を確認","—")) -> ○ 整合（予測消化率70%超） | AA27: 【7/28 運営報告】欠品／近々欠品 ／ 倉庫残208個 → ◎倉庫からの追加納品で対応可能（追加生産は不要） ／ 名古屋会場で完売（実績が在庫上限で頭打ち＝予測は控えめ） ／ 博多会場で完売（実績が在庫上限で頭打ち＝予測は控えめ）
A28: 22 | B28: 4515142545501 | C28: 呪術廻戦 渋谷事変 クリアファイル（宿儺） | D28: 600 | E28: =①札幌予測確定!E28 -> 23 | F28: =①札幌予測確定!P28 -> 52 | G28: =①札幌予測確定!S28 -> 50 | H28: =IFERROR(F28/G28,0) -> 1.04 | I28: =F28-G28 -> 2 | J28: =IF(I28>0,"要 追加発注",IF(H28>=0.9,"要注意(90%超)",IF(H28>=0.5,"適正","在庫余剰"))) -> 要 追加発注 | K28: =IF(I28>0,ROUNDUP(I28*(1+前提・入力!$B$35),0),0) -> 3 | L28: =③石川以降予測!N51 -> 353 | M28: =③石川以降予測!S51 -> 0 | N28: =③石川以降予測!Q51 -> 1281 | O28: =L28-M28-N28 -> -928 | P28: =IF(O28>0,"要 追加生産",IF(L28=0,"—","在庫で充足")) -> 在庫で充足 | Q28: =③石川以降予測!X51 -> 0 | R28: =K28+Q28 -> 3 | S28: =R28*D28 -> 1800 | T28: — | V28: =IF(OR(U28="",U28="再生産不可"),"",U28-前提・入力!$B$39) | W28: =IF(T28="—","—",IF(U28="再生産不可","×再生産不可",_xlfn.IFS(V28<0,"★期限超過",V28<=30,"★至急(30日以内)",V28<=90,"要着手(90日以内)",TRUE(),"余裕あり"))) -> — | X28: =IF(Y28<>"",IF(FALSE(),"S:現場欠品(追納不可)","S:現場欠品"),IF(I28>0,"A:会期中欠品",IF(O28>1000,"B:大口",IF(O28>0,"C:通常","D:不要")))) -> S:現場欠品 | Y28: 欠品／近々欠品 | Z28: =IF(Y28<>"",IF(I28>0,"◎ 一致（モデルも会期中欠品を検知）",IF(H28>=0.7,"○ 整合（予測消化率70%超）","△ モデル未検知：現場報告を優先")),IF(I28>0,"▲ モデルのみ検知：現場に在庫状況を確認","—")) -> ◎ 一致（モデルも会期中欠品を検知） | AA28: 【7/28 運営報告】欠品／近々欠品 ／ 倉庫残1,281個 → ◎倉庫からの追加納品で対応可能（追加生産は不要） ／ 札幌会期中に欠品見込。至急スライド納品または追加発注 ／ 博多会場で完売（実績が在庫上限で頭打ち＝予測は控えめ）
