Workbook

Sheet サマリー
A1: アニメーション 呪術廻戦展「懐玉・玉折」「渋谷事変」
A2: LEGS／イベント記念商品 42SKU 全会場 販売分析・石川予測確定・仙台会場以降予測・追加発注判定
A3: 基準日：2026年8月26日 ／ 実績データ：東京(25日)・名古屋(19日)・博多(26日)・大阪(20日)・札幌(20日)＝全会期、石川＝8/25(会期12日目)まで ＋ SPJ様 欠品報告メール
A5: ■ 結論サマリー
A6: ① 石川 会期18日予測（確定値） | B6: LEGS42SKU 販売数 5,151個／販売金額 4,292,200円 ※博多・大阪・札幌 の実績倍率から算出
A7: 石川 全物販予測 | B7: 数量 24,559個／金額 25,161,149円 → 東京(初回)対比 7.0%
A8: 石川 入場者予測 | B8: 8,923人（初12日実績5,304人 × 札幌の初12日→20日 伸び率）
A9: ② LEGS物販構成比の推移 | B9: 金額：東京28.5%→名古屋29.9%→博多29.4%→大阪21.1%→札幌17.6%→石川17.1%(予測) 数量：38.7%→34.5%→40.0%→26.7%→21.8%→石川21.0%(予測)
A10: 構成比低下の主因 | B10: 大阪会場からの新商品106SKU投入（大阪の会期20日 金額シェア19.8%）。札幌・石川 は新規SKU 0で品揃えは大阪と同一
A11: ③ 仙台以降4会場 LEGS必要数 | B11: 61,617個（シナリオ①ユーザー指定：仙台13%・神戸阪急12%・鳥取島根9%・東京凱旋50%）
A12: シナリオ②企画概要書ベース | B12: 仙台15.60%・神戸阪急12.00%・鳥取島根9.00%・東京凱旋50.00%（企画概要書グッズ売上÷東京）→ 必要数 63,524個
A13: シナリオ③石川実績連動(保守) | B13: ②に石川の計画比達成率56.3%を乗算 → 仙台8.78%・神戸阪急6.75%・鳥取島根5.07%・東京凱旋50.00%（凱旋は据置）→ 必要数 51,789個
A14: ★残在庫想定の反映 | B14: 在庫フロー台帳の「梅田まで(SET)」列 276,521個を採用（梅田会場後の検品結果まで反映済み）。
A15: ★石川 への追納（実施済） | B15: 2026/8 石川(金沢)会場への札幌転送分＋8/22追納：札幌会場からの転送（LEGS 42SKU 計） 41,612個／宿儺の指風お菓子 20個 計41,632個（日報の販売可能数に反映済み）。倉庫在庫からの出荷なので全社在庫は不変
A16: 追納後になお必要な追納 | B16: 33個（会期20日予測が販売可能数を上回る残差）
A17: 仙台以降 供給可能在庫 | B17: 234,426個 ＝ 倉庫残197,962個 − 石川会期中の追納33個 ＋ 会期末の返送見込41,810個
... A34: 石川 会期中の追加発注 | B34: 3品目が会期内に在庫切れ見込：前髪ヘアバンド(不足20) 宿儺の指風お菓子(不足12) 夏油 傑 イメージリング（#15）(不足1)
A36: ■ 運営（SPJ様）欠品報告との突合 ※受領メール
A37: 報告された欠品／近々欠品 | B37: 0品目：
A38: ◎ モデルも会期中欠品を検知 | B38: 0品目：なし
A39: ○ モデルは高消化率で整合 | B39: 0品目：なし（予測消化率70%超。会期末までに枯渇する水準）
A40: △ モデル未検知（現場優先） | B40: 0品目：なし
A41: ▲ モデルのみ検知（現場未報告） | B41: 3品目：前髪ヘアバンド 宿儺の指風お菓子 夏油 傑 イメージリング（#15） → 現場に実在庫の確認を推奨
A42: ★追納不可と回答された品目 | B42: なし ＝ 前会場時点で「追納困難」と回答済。ただし7/8実在庫では倉庫残0個が確認できるため、下記の要確認事項を参照
A43: 突合の結論 | B43: 現場報告0品目のうち0品目がモデル側でも欠品または高消化率として検知されており、見落とし0・空振り0で完全に整合。
B44: 8/25（12日目）実績を織り込んだことで検知精度が上がり、予測モデルは現場実感と一致する水準にある。
B45: ④シートの「運営 欠品報告」「モデル×現場 突合」列で商品別に明示している（列位置は⑫シート参照）。
A46: ★倉庫在庫による解決可否 | B46: 報告0品目すべて2026/7/8時点で倉庫に在庫が残っており、追加生産ではなく倉庫からの追加納品で対応可能。
A47: 倉庫残（石川納品を除く）
A48: ※要確認 | B48: 「気分リフレッシュオルゴール」は倉庫残28個が存在する。前会場時の「追納困難」回答と実在庫が食い違うため、
B49: 出荷可否をSPJ様・倉庫に再確認のうえ、可能なら石川会場へ充当することを推奨。
A51: ■ 最重要リスクと打ち手
A52: 石川 の動員が計画比50% | B52: 初12日入場者5,304人（大阪同期間6,105人の86.9%）。物販売上も東京対比7.0%と、
B53: 仙台以降の会場比率も、この水準を踏まえて下方修正を検討すべき。
A54: 東京凱旋が必要数の60% | B54: 仙台以降 必要数61,617個のうち36,677個(60%)が東京凱旋。凱旋の50%前提が外れると発注量が大きくブレる。
B55: 発注は「仙台〜鳥取島根(3会場・24,940個)」を先行確定し、凱旋分は会期確定後に第2弾発注とするのが安全。
A56: ★過剰在庫のほうが深刻 | B56: 供給可能234,426個に対し仙台以降の必要数は61,617個。差引172,809個（供給可能の74%）が余剰となる見込み。
B57: 余剰上位：呪術廻戦 渋谷事変 ブラインド缶バッジ（全9 供給可能50,228個 vs 必要6,990個／呪術廻戦 懐玉・玉折 ブラインド缶バッジ（全 供給可能39,392個 vs 必要3,173個／呪術廻戦 懐玉・玉折 ブラインドミニ色紙（全 供給可能48,729個 vs 必要15,264個
B58: 追加発注よりも、余剰在庫の消化策（セット販売・ノベルティ転用等）の検討が急務。
A59: 不足はごく一部 | B59: 追加生産が必要なのは13品目・3,384個のみ。うち展示会キービジュアル クリアファイルが895個で全体の26%を占める。
...

Sheet 前提・入力
A1: 前提・入力パラメータ
A2: 青字・黄色セルが入力値です。変更すると①③④⑤シートの予測が自動再計算されます。
A4: ■ ①石川予測 モデルパラメータ
A5: 会期倍率g 加重：東京 | B5: 0 | C5: 【何に効くか】①シートO列「採用倍率g」の加重平均ウェイト。石川18日予測＝初12日(8/14-8/25)実績×採用倍率g。 【なぜ0か】東京は初動カーブが石川と大きく異なるため、ユーザー指示により倍率の算出根拠から除外している（0固定）。0以外にすると①の採用倍率g＝石川予測が全品変動する。
A6: 会期倍率g 加重：名古屋 | B6: 0 | C6: 【何に効くか】①シートO列「採用倍率g」の加重平均ウェイト。石川18日予測＝初12日(8/14-8/25)実績×採用倍率g。 【なぜ0か】名古屋は初動カーブが石川と大きく異なるため、ユーザー指示により倍率の算出根拠から除外している（0固定）。0以外にすると①の採用倍率g＝石川予測が全品変動する。
A7: 会期倍率g 加重：博多 | B7: 1 | C7: 【何に効くか】①シートO列「採用倍率g」の加重平均ウェイト。石川18日予測＝初12日(8/14-8/25)実績×採用倍率g。 【算出】博多③は26日会期のため、頭から18日分だけを切り出して倍率化する（18日累計 ÷ 初12日）。博多の倍率g＝1.413。会期構成が石川と異なるため加重1。
A8: 会期倍率g 加重：大阪 | B8: 1 | C8: 【何に効くか】①シートO列「採用倍率g」の加重平均ウェイト。石川18日予測＝初12日(8/14-8/25)実績×採用倍率g。 【算出】大阪④は20日会期のため、頭から18日分だけを切り出して倍率化する（18日累計 ÷ 初12日）。大阪の倍率g＝1.225。会期構成が石川と異なるため加重1。
A9: 会期倍率g 加重：札幌 | B9: 2 | C9: 【何に効くか】①シートO列「採用倍率g」の加重平均ウェイト。石川18日予測＝初12日(8/14-8/25)実績×採用倍率g。 【なぜ2倍か】札幌⑤は直前に終了した会場で、品揃えが石川と同一・会期20日と条件が最も近い。このため他会場の2倍の重みを置く。札幌の倍率g＝1.274（42品計）。
A10: 会期が18日に満たない参照会場の補完率 | B10: 0 | C10: 【何に効くか】会期が18日より短い参照会場（今回は該当なし）の倍率gの分子補正。 【算出】18日以上ある会場の「18日累計 ÷ その会場の会期日数までの累計」の伸び率の平均。短い会場の累計にこの率を掛けて18日相当に補完し、他会場と粒度を揃える。
A11: 全体倍率g（実績ゼロ品のフォールバック） | B11: 1.2962063 | C11: 【何に効くか】①シートの採用倍率gのIFERROR代替値。 【算出】42品計の初12日→18日 加重平均倍率＝1.296。参照会場（博多／大阪／札幌）のいずれにも初12日実績が無く商品別倍率を計算できない品にだけ適用する。
A12: ■ ②③会場比率 前提
A13: 東京(初回) 全物販売上（税込） | B13: 358193925 | C13: 【出所】東京(初回) 池袋サンシャインシティ 25日間の全物販実績（税込）。レジ袋代・音声ガイド・当日券を除いた商品売上のみ。 【何に効くか】③シートE列の基準額。本値×東京対比で次会場以降 各会場の物販売上を推定する。
A14: 東京(初回) 全物販 販売数量 | B14: 383342 | C14: 【出所】同上（東京25日間の全物販 販売数量）。 【何に効くか】②シートの「全物販 販売数量」の次会場以降 予測（＝本値×東京対比）と、LEGS数量構成比の母数。
A15: ★シナリオ選択（1〜4） | B15: 1 | C15: 1＝ユーザー指定／2＝企画概要書ベース／3＝石川実績連動(保守)／4＝手動入力(F列を使用)。 【何に効くか】下の「東京対比：〇〇」がINDEXで自動切替 → ③D列 → 会場売上 → 必要数 → ④の発注判定まで一気に連動する。4シナリオの結果比較は⑩シート。
A16: シナリオ別 東京対比比率 | C16: ①ユーザー指定 | D16: ②企画概要書ベース | E16: ③石川実績連動(保守) | F16: ④手動入力
A17: 仙台 Ebeans | B17: 26/9/5(土)-10/4(日)（30日間） | C17: 0.13 | D17: 0.156 | E17: 0.087805611 | F17: 0.13
A18: 神戸阪急 | B18: 26/12/16(水)-27/1/7(木)（21日間） | C18: 0.12 | D18: 0.12 | E18: 0.067542777 | F18: 0.12
A19: 鳥取島根 夢みなとタワー | B19: 27/3/15-4/4（21日間） | C19: 0.09 | D19: 0.09 | E19: 0.050657083 | F19: 0.09
A20: 東京凱旋 東京建物ぴあホール | B20: 27年4-5月（25日間） | C20: 0.5 | D20: 0.5 | E20: 0.5 | F20: 0.5
A21: ※③は企画概要書の計画値に石川の計画比達成率 56.3% を乗じたもの（凱旋は据置）
A23: 東京対比：仙台 Ebeans | B23: =INDEX(C17:F17,前提・入力!$B$15) -> 0.13 | C23: 【何に効くか】緑字＝シナリオ選択に応じて上表からINDEXで自動取得。仙台 Ebeansの物販売上を東京(初回)の13.00%＝46,565,210円と置く（③シートE列）。 【根拠】ユーザー指定値。会期が30日間と全会場で最長のため高めに設定している。同規模イベントのコナンカフェ2026では仙台は東京対比10.5%の実績。
A24: 東京対比：神戸阪急 | B24: =INDEX(C18:F18,前提・入力!$B$15) -> 0.12 | C24: 【何に効くか】緑字＝シナリオ選択に応じて上表からINDEXで自動取得。神戸阪急の物販売上を東京(初回)の12.00%＝42,983,271円と置く（③シートE列）。 【根拠】★要確認：指定も類似実績も無いため仮置き。確定したらシナリオ④の手動入力(F列)を書き換え、シナリオ選択＝4で反映させる。
A25: 東京対比：鳥取島根 夢みなとタワー | B25: =INDEX(C19:F19,前提・入力!$B$15) -> 0.09 | C25: 【何に効くか】緑字＝シナリオ選択に応じて上表からINDEXで自動取得。鳥取島根 夢みなとタワーの物販売上を東京(初回)の9.00%＝32,237,453円と置く（③シートE列）。 【根拠】商圏規模が小さく信頼できる類似実績も無いため、他の地方会場より低めに置いたユーザー指定値。
A26: 東京対比：東京凱旋 東京建物ぴあホール | B26: =INDEX(C20:F20,前提・入力!$B$15) -> 0.5 | C26: 【何に効くか】緑字＝シナリオ選択に応じて上表からINDEXで自動取得。東京凱旋 東京建物ぴあホールの物販売上を東京(初回)の50.00%＝179,096,962円と置く（③シートE列）。 【根拠】ユーザー指定「初回東京の50%」。全シナリオ共通で据置のためシナリオを切り替えても動かない。次会場以降の必要数の過半を占める、最も感度の高い前提。
A27: ［参考］コナンカフェ2026 東京対比 | C27: 【参考実績】大阪53.6%・名古屋26.8%・神奈川19.1%・北海道13.3%・仙台10.5%。地方会場は東京の10〜20%に収束する傾向がある。 上の東京対比の水準感が妥当かを検証するための参考値で、計算には使っていない。
A28: ■ ③仙台以降 LEGS構成比 前提
A29: LEGS 金額構成比（仙台以降） | B29: 0.17058839 | C29: 【意味】会場の全物販売上のうち LEGS 42SKU が占める金額シェア。 【推移】東京 28.5% → 名古屋 29.9% → 博多 29.4% → 大阪 21.1% → 札幌 17.6% → 石川18日予測 17.1%。大阪以降の新商品106SKU投入で低下しており、その到達点を次会場以降にも適用する。 【何に効くか】③シートF列＝E列(会場 全物販売上)×本値。
A30: LEGS 平均単価（税込） | B30: 833 | C30: 【算出】石川18日予測の金額 4,292,200円 ÷ 数量 5,151個 ≒ 833円（①シートQ49合計 ÷ P49合計）。新商品投入後の商品ミックスを反映した加重平均単価。 【何に効くか】③シートG列＝ROUND(F列 LEGS売上 ÷ 本単価,0)＝次会場以降の必要数量。
A31: 商品別按分：札幌20日実績の構成比ウェイト | B31: 0.5 | C31: 【何に効くか】③シートH列「採用 按分構成比」＝大阪構成比(E列)×本値 ＋ 石川構成比(G列)×下の値。総必要数をどの商品に何個振るかを決める。 【札幌を使う理由】直前に終了した会場で42品すべての確定実績（20日・8,891個）があり、品揃えも石川と同一。
A32: 商品別按分：石川18日予測の構成比ウェイト | B32: 0.5 | C32: 大阪ウェイトとの合計が100%になるよう設定する。 【石川を使う理由】新商品投入後のミックスで、次会場以降の品揃えに条件が近い（ただし予測値）。 【感度】総必要数は変わらず、品目別の偏りだけが動く。大阪100%に寄せると定番商品へ、石川100%に寄せると直近で伸びている商品へ配分が寄る。
A33: ■ ④追加発注 前提
A34: 安全率（不足数に対する上乗せ） | B34: 0.1 | C34: 【何に効くか】③④⑧⑪シートの推奨発注数＝IF(不足>0, ROUNDUP(不足数×(1+本率),0), 0)。 【根拠】輸送中の破損・検品不良・予測超過の緩衝として10%を上乗せしている。
A35: ［参考］残在庫想定 全品計（梅田まで(SET)） | B35: 276521 | C35: 【出所】在庫フロー台帳「【清算(卸値67％)】…_検品差異」シートの最終「実在庫」列（梅田まで(SET)）の42SKU合計。会場ごとの 追加発注→販売→レッグス検品 を積み上げた確定値で、直近会場の返送検品まで反映済み。石川会場への納品数と石川会場の販売数はまだ差し引かれていない。 【何に効くか】本セルは⑧シートH49合計へのリンク（表示用）。商品別の実数を③⑧⑩⑪シートが直接参照する。
A36: 石川 会期末残在庫のスライド率 | B36: 1 | C36: 【何に効くか】③シートS列「石川会期末 返送(スライド)」＝ROUND(①シートU列×本率,0)。次会場以降の供給可能在庫に加算される。 【100%の意味】石川終了在庫 41,810個を全量 次会場以降へ回せる前提。損傷・返送ロスを見込むなら下げる → 供給が減り追加生産が増える。
A37: 発注〜納品バッファ日数（輸送・検品） | B37: 14 | C37: 【何に効くか】④⑧⑪シートの最終発注期限＝欠品発生会場の会期初日 − 生産日数(か月×30日) − 本バッファ。 【内訳】14日＝工場出荷 → 国内輸送・入荷検品・会場搬入のリードタイム。
A38: 基準日 | B38: 46260 | C38: 【根拠】2026/08/26＝本分析の基準日（生産日数の提示は2026/7/28時点）。 【何に効くか】④⑧⑪シートの「基準日からの残日数」＝最終発注期限 − 本日付。日付を進めると残日数が減り、期限超過の判定が増える。

Sheet ①石川予測確定
A1: ① 石川会場 会期18日間（26/8/14(金)-8/31(月)）商品別 販売予測【確定値】
A2: 算出根拠：東京を除く名古屋①・博多②・大阪④の「18日累計 ÷ 初12日」倍率を商品別に加重平均し、石川の初12日(8/14-8/25)実績に乗算
A3: 加重：博多1・大阪1・札幌2（「前提・入力」シートで変更可）
A6: No. | B6: JAN | C6: 商品名 | D6: 税込 単価 | E6: 石川 初12日 8/14-8/25 | F6: 博多③ 初12日 | G6: 博多③ 18日累計 | H6: 博多 倍率g | I6: 大阪④ 初12日 | J6: 大阪④ 18日累計 | K6: 大阪 倍率g | L6: 札幌⑤ 初12日 | M6: 札幌⑤ 18日累計 | N6: 札幌 倍率g | O6: 採用 倍率g | P6: 石川 会期18日 予測販売数 | Q6: 石川 予測販売金額 | R6: 石川 数量構成比 | S6: 石川 販売可能数 (追納込) | T6: 予測 消化率 | U6: 会期末 残在庫 | V6: 会期中 過不足 | W6: 会期中 在庫判定
A7: 1 | B7: 4515142545082 | C7: 呪術廻戦 メタリックポストカード 展示会キービジュアル | D7: 500 | E7: 210 | F7: 719 | G7: 944 | H7: =IF(F7=0,"",G7/F7) -> 1.3129346 | I7: 1710 | J7: 2158 | K7: =IF(I7=0,"",J7/I7) -> 1.2619883 | L7: 343 | M7: 447 | N7: =IF(L7=0,"",M7/L7) -> 1.303207 | O7: =IFERROR((IF(H7="",0,H7*前提・入力!$B$7)+IF(K7="",0,K7*前提・入力!$B$8)+IF(N7="",0,N7*前提・入力!$B$9))/(IF(H7="",0,前提・入力!$B$7)+IF(K7="",0,前提・入力!$B$8)+IF(N7="",0,前提・入力!$B$9)),前提・入力!$B$11) -> 1.2953342 | P7: =ROUND(E7*O7,0) -> 272 | Q7: =P7*D7 -> 136000 | R7: =IFERROR(P7/P$49,0) -> 0.052805281 | S7: 693 | T7: =IFERROR(P7/S7,0) -> 0.39249639 | U7: =MAX(0,S7-P7) -> 421 | V7: =P7-S7 -> -421 | W7: =IF(V7>0,"会期中に在庫切れ",IF(T7>=0.9,"要注意(90%超)",IF(T7>=0.5,"適正","在庫余剰"))) -> 在庫余剰
A8: 2 | B8: 4515142545099 | C8: 呪術廻戦 クリアファイル 展示会キービジュアル | D8: 600 | E8: 250 | F8: 653 | G8: 850 | H8: =IF(F8=0,"",G8/F8) -> 1.3016845 | I8: 1500 | J8: 1781 | K8: =IF(I8=0,"",J8/I8) -> 1.1873333 | L8: 362 | M8: 492 | N8: =IF(L8=0,"",M8/L8) -> 1.359116 | O8: =IFERROR((IF(H8="",0,H8*前提・入力!$B$7)+IF(K8="",0,K8*前提・入力!$B$8)+IF(N8="",0,N8*前提・入力!$B$9))/(IF(H8="",0,前提・入力!$B$7)+IF(K8="",0,前提・入力!$B$8)+IF(N8="",0,前提・入力!$B$9)),前提・入力!$B$11) -> 1.3018125 | P8: =ROUND(E8*O8,0) -> 325 | Q8: =P8*D8 -> 195000 | R8: =IFERROR(P8/P$49,0) -> 0.063094545 | S8: 659 | T8: =IFERROR(P8/S8,0) -> 0.49317147 | U8: =MAX(0,S8-P8) -> 334 | V8: =P8-S8 -> -334 | W8: =IF(V8>0,"会期中に在庫切れ",IF(T8>=0.9,"要注意(90%超)",IF(T8>=0.5,"適正","在庫余剰"))) -> 在庫余剰
A9: 3 | B9: 4515142545105 | C9: 呪術廻戦 懐玉・玉折 ポストカードセット（5枚入） | D9: 1000 | E9: 92 | F9: 280 | G9: 368 | H9: =IF(F9=0,"",G9/F9) -> 1.3142857 | I9: 904 | J9: 1063 | K9: =IF(I9=0,"",J9/I9) -> 1.175885 | L9: 116 | M9: 152 | N9: =IF(L9=0,"",M9/L9) -> 1.3103448 | O9: =IFERROR((IF(H9="",0,H9*前提・入力!$B$7)+IF(K9="",0,K9*前提・入力!$B$8)+IF(N9="",0,N9*前提・入力!$B$9))/(IF(H9="",0,前提・入力!$B$7)+IF(K9="",0,前提・入力!$B$8)+IF(N9="",0,前提・入力!$B$9)),前提・入力!$B$11) -> 1.2777151 | P9: =ROUND(E9*O9,0) -> 118 | Q9: =P9*D9 -> 118000 | R9: =IFERROR(P9/P$49,0) -> 0.022908173 | S9: 381 | T9: =IFERROR(P9/S9,0) -> 0.30971129 | U9: =MAX(0,S9-P9) -> 263 | V9: =P9-S9 -> -263 | W9: =IF(V9>0,"会期中に在庫切れ",IF(T9>=0.9,"要注意(90%超)",IF(T9>=0.5,"適正","在庫余剰"))) -> 在庫余剰
A10: 4 | B10: 4515142545112 | C10: 呪術廻戦 渋谷事変 ポストカードセット（9枚入） | D10: 1800 | E10: 110 | F10: 353 | G10: 427 | H10: =IF(F10=0,"",G10/F10) -> 1.2096317 | I10: 1012 | J10: 1209 | K10: =IF(I10=0,"",J10/I10) -> 1.194664 | L10: 170 | M10: 209 | N10: =IF(L10=0,"",M10/L10) -> 1.2294118 | O10: =IFERROR((IF(H10="",0,H10*前提・入力!$B$7)+IF(K10="",0,K10*前提・入力!$B$8)+IF(N10="",0,N10*前提・入力!$B$9))/(IF(H10="",0,前提・入力!$B$7)+IF(K10="",0,前提・入力!$B$8)+IF(N10="",0,前提・入力!$B$9)),前提・入力!$B$11) -> 1.2157798 | P10: =ROUND(E10*O10,0) -> 134 | Q10: =P10*D10 -> 241200 | R10: =IFERROR(P10/P$49,0) -> 0.026014366 | S10: 772 | T10: =IFERROR(P10/S10,0) -> 0.17357513 | U10: =MAX(0,S10-P10) -> 638 | V10: =P10-S10 -> -638 | W10: =IF(V10>0,"会期中に在庫切れ",IF(T10>=0.9,"要注意(90%超)",IF(T10>=0.5,"適正","在庫余剰"))) -> 在庫余剰
A11: 5 | B11: 4515142545129 | C11: 呪術廻戦 懐玉・玉折 ブラインド缶バッジ（全5種） | D11: 600 | E11: 226 | F11: 3298 | G11: 5127 | H11: =IF(F11=0,"",G11/F11) -> 1.5545785 | I11: 7193 | J11: 8539 | K11: =IF(I11=0,"",J11/I11) -> 1.1871264 | L11: 322 | M11: 394 | N11: =IF(L11=0,"",M11/L11) -> 1.2236025 | O11: =IFERROR((IF(H11="",0,H11*前提・入力!$B$7)+IF(K11="",0,K11*前提・入力!$B$8)+IF(N11="",0,N11*前提・入力!$B$9))/(IF(H11="",0,前提・入力!$B$7)+IF(K11="",0,前提・入力!$B$8)+IF(N11="",0,前提・入力!$B$9)),前提・入力!$B$11) -> 1.2972275 | P11: =ROUND(E11*O11,0) -> 293 | Q11: =P11*D11 -> 175800 | R11: =IFERROR(P11/P$49,0) -> 0.056882159 | S11: 8790 | T11: =IFERROR(P11/S11,0) -> 0.033333333 | U11: =MAX(0,S11-P11) -> 8497 | V11: =P11-S11 -> -8497 | W11: =IF(V11>0,"会期中に在庫切れ",IF(T11>=0.9,"要注意(90%超)",IF(T11>=0.5,"適正","在庫余剰"))) -> 在庫余剰
A12: 6 | B12: 4515142545136 | C12: 呪術廻戦 渋谷事変 ブラインド缶バッジ（全9種） | D12: 600 | E12: 439 | F12: 4238 | G12: 6491 | H12: =IF(F12=0,"",G12/F12) -> 1.5316187 | I12: 13071 | J12: 17062 | K12: =IF(I12=0,"",J12/I12) -> 1.3053324 | L12: 860 | M12: 995 | N12: =IF(L12=0,"",M12/L12) -> 1.1569767 | O12: =IFERROR((IF(H12="",0,H12*前提・入力!$B$7)+IF(K12="",0,K12*前提・入力!$B$8)+IF(N12="",0,N12*前提・入力!$B$9))/(IF(H12="",0,前提・入力!$B$7)+IF(K12="",0,前提・入力!$B$8)+IF(N12="",0,前提・入力!$B$9)),前提・入力!$B$11) -> 1.2877261 | P12: =ROUND(E12*O12,0) -> 565 | Q12: =P12*D12 -> 339000 | R12: =IFERROR(P12/P$49,0) -> 0.10968744 | S12: 13249 | T12: =IFERROR(P12/S12,0) -> 0.042644728 | U12: =MAX(0,S12-P12) -> 12684 | V12: =P12-S12 -> -12684 | W12: =IF(V12>0,"会期中に在庫切れ",IF(T12>=0.9,"要注意(90%超)",IF(T12>=0.5,"適正","在庫余剰"))) -> 在庫余剰
A13: 7 | B13: 4515142545143 | C13: 呪術廻戦 懐玉・玉折 ブラインドダイカットステッカー（全5種） | D13: 600 | E13: 130 | F13: 239 | G13: 321 | H13: =IF(F13=0,"",G13/F13) -> 1.3430962 | I13: 727 | J13: 880 | K13: =IF(I13=0,"",J13/I13) -> 1.2104539 | L13: 134 | M13: 169 | N13: =IF(L13=0,"",M13/L13) -> 1.261194 | O13: =IFERROR((IF(H13="",0,H13*前提・入力!$B$7)+IF(K13="",0,K13*前提・入力!$B$8)+IF(N13="",0,N13*前提・入力!$B$9))/(IF(H13="",0,前提・入力!$B$7)+IF(K13="",0,前提・入力!$B$8)+IF(N13="",0,前提・入力!$B$9)),前提・入力!$B$11) -> 1.2689846 | P13: =ROUND(E13*O13,0) -> 165 | Q13: =P13*D13 -> 99000 | R13: =IFERROR(P13/P$49,0) -> 0.032032615 | S13: 463 | T13: =IFERROR(P13/S13,0) -> 0.35637149 | U13: =MAX(0,S13-P13) -> 298 | V13: =P13-S13 -> -298 | W13: =IF(V13>0,"会期中に在庫切れ",IF(T13>=0.9,"要注意(90%超)",IF(T13>=0.5,"適正","在庫余剰"))) -> 在庫余剰
A14: 8 | B14: 4515142545150 | C14: 呪術廻戦 渋谷事変 ブラインドダイカットステッカー（全9種） | D14: 600 | E14: 207 | F14: 435 | G14: 581 | H14: =IF(F14=0,"",G14/F14) -> 1.3356322 | I14: 1388 | J14: 1642 | K14: =IF(I14=0,"",J14/I14) -> 1.1829971 | L14: 222 | M14: 291 | N14: =IF(L14=0,"",M14/L14) -> 1.3108108 | O14: =IFERROR((IF(H14="",0,H14*前提・入力!$B$7)+IF(K14="",0,K14*前提・入力!$B$8)+IF(N14="",0,N14*前提・入力!$B$9))/(IF(H14="",0,前提・入力!$B$7)+IF(K14="",0,前提・入力!$B$8)+IF(N14="",0,前提・入力!$B$9)),前提・入力!$B$11) -> 1.2850627 | P14: =ROUND(E14*O14,0) -> 266 | Q14: =P14*D14 -> 159600 | R14: =IFERROR(P14/P$49,0) -> 0.051640458 | S14: 778 | T14: =IFERROR(P14/S14,0) -> 0.34190231 | U14: =MAX(0,S14-P14) -> 512 | V14: =P14-S14 -> -512 | W14: =IF(V14>0,"会期中に在庫切れ",IF(T14>=0.9,"要注意(90%超)",IF(T14>=0.5,"適正","在庫余剰"))) -> 在庫余剰
A15: 9 | B15: 4515142545372 | C15: 呪術廻戦 懐玉・玉折 クリアファイル（五条 悟） | D15: 600 | E15: 41 | F15: 223 | G15: 261 | H15: =IF(F15=0,"",G15/F15) -> 1.1704036 | I15: 615 | J15: 697 | K15: =IF(I15=0,"",J15/I15) -> 1.1333333 | L15: 106 | M15: 144 | N15: =IF(L15=0,"",M15/L15) -> 1.3584906 | O15: =IFERROR((IF(H15="",0,H15*前提・入力!$B$7)+IF(K15="",0,K15*前提・入力!$B$8)+IF(N15="",0,N15*前提・入力!$B$9))/(IF(H15="",0,前提・入力!$B$7)+IF(K15="",0,前提・入力!$B$8)+IF(N15="",0,前提・入力!$B$9)),前提・入力!$B$11) -> 1.2551795 | P15: =ROUND(E15*O15,0) -> 51 | Q15: =P15*D15 -> 30600 | R15: =IFERROR(P15/P$49,0) -> 0.0099009901 | S15: 740 | T15: =IFERROR(P15/S15,0) -> 0.068918919 | U15: =MAX(0,S15-P15) -> 689 | V15: =P15-S15 -> -689 | W15: =IF(V15>0,"会期中に在庫切れ",IF(T15>=0.9,"要注意(90%超)",IF(T15>=0.5,"適正","在庫余剰"))) -> 在庫余剰
A16: 10 | B16: 4515142545389 | C16: 呪術廻戦 懐玉・玉折 クリアファイル（夏油 傑） | D16: 600 | E16: 16 | F16: 93 | G16: 104 | H16: =IF(F16=0,"",G16/F16) -> 1.1182796 | I16: 219 | J16: 254 | K16: =IF(I16=0,"",J16/I16) -> 1.1598174 | L16: 38 | M16: 53 | N16: =IF(L16=0,"",M16/L16) -> 1.3947368 | O16: =IFERROR((IF(H16="",0,H16*前提・入力!$B$7)+IF(K16="",0,K16*前提・入力!$B$8)+IF(N16="",0,N16*前提・入力!$B$9))/(IF(H16="",0,前提・入力!$B$7)+IF(K16="",0,前提・入力!$B$8)+IF(N16="",0,前提・入力!$B$9)),前提・入力!$B$11) -> 1.2668927 | P16: =ROUND(E16*O16,0) -> 20 | Q16: =P16*D16 -> 12000 | R16: =IFERROR(P16/P$49,0) -> 0.0038827412 | S16: 541 | T16: =IFERROR(P16/S16,0) -> 0.036968577 | U16: =MAX(0,S16-P16) -> 521 | V16: =P16-S16 -> -521 | W16: =IF(V16>0,"会期中に在庫切れ",IF(T16>=0.9,"要注意(90%超)",IF(T16>=0.5,"適正","在庫余剰"))) -> 在庫余剰
A17: 11 | B17: 4515142545396 | C17: 呪術廻戦 懐玉・玉折 クリアファイル（家入 硝子） | D17: 600 | E17: 6 | F17: 27 | G17: 30 | H17: =IF(F17=0,"",G17/F17) -> 1.1111111 | I17: 54 | J17: 69 | K17: =IF(I17=0,"",J17/I17) -> 1.2777778 | L17: 11 | M17: 16 | N17: =IF(L17=0,"",M17/L17) -> 1.4545455 | O17: =IFERROR((IF(H17="",0,H17*前提・入力!$B$7)+IF(K17="",0,K17*前提・入力!$B$8)+IF(N17="",0,N17*前提・入力!$B$9))/(IF(H17="",0,前提・入力!$B$7)+IF(K17="",0,前提・入力!$B$8)+IF(N17="",0,前提・入力!$B$9)),前提・入力!$B$11) -> 1.3244949 | P17: =ROUND(E17*O17,0) -> 8 | Q17: =P17*D17 -> 4800 | R17: =IFERROR(P17/P$49,0) -> 0.0015530965 | S17: 79 | T17: =IFERROR(P17/S17,0) -> 0.10126582 | U17: =MAX(0,S17-P17) -> 71 | V17: =P17-S17 -> -71 | W17: =IF(V17>0,"会期中に在庫切れ",IF(T17>=0.9,"要注意(90%超)",IF(T17>=0.5,"適正","在庫余剰"))) -> 在庫余剰
A18: 12 | B18: 4515142545402 | C18: 呪術廻戦 懐玉・玉折 クリアファイル（七海 建人） | D18: 600 | E18: 13 | F18: 32 | G18: 42 | H18: =IF(F18=0,"",G18/F18) -> 1.3125 | I18: 107 | J18: 126 | K18: =IF(I18=0,"",J18/I18) -> 1.1775701 | L18: 27 | M18: 36 | N18: =IF(L18=0,"",M18/L18) -> 1.3333333 | O18: =IFERROR((IF(H18="",0,H18*前提・入力!$B$7)+IF(K18="",0,K18*前提・入力!$B$8)+IF(N18="",0,N18*前提・入力!$B$9))/(IF(H18="",0,前提・入力!$B$7)+IF(K18="",0,前提・入力!$B$8)+IF(N18="",0,前提・入力!$B$9)),前提・入力!$B$11) -> 1.2891842 | P18: =ROUND(E18*O18,0) -> 17 | Q18: =P18*D18 -> 10200 | R18: =IFERROR(P18/P$49,0) -> 0.00330033 | S18: 107 | T18: =IFERROR(P18/S18,0) -> 0.1588785 | U18: =MAX(0,S18-P18) -> 90 | V18: =P18-S18 -> -90 | W18: =IF(V18>0,"会期中に在庫切れ",IF(T18>=0.9,"要注意(90%超)",IF(T18>=0.5,"適正","在庫余剰"))) -> 在庫余剰
... A48: 42 | B48: 4515142545365 | C48: 伏黒 恵 イメージフラグメントケース | D48: 25000 | E48: 0 | F48: 2 | G48: 2 | H48: =IF(F48=0,"",G48/F48) -> 1 | I48: 5 | J48: 6 | K48: =IF(I48=0,"",J48/I48) -> 1.2 | L48: 1 | M48: 1 | N48: =IF(L48=0,"",M48/L48) -> 1 | O48: =IFERROR((IF(H48="",0,H48*前提・入力!$B$7)+IF(K48="",0,K48*前提・入力!$B$8)+IF(N48="",0,N48*前提・入力!$B$9))/(IF(H48="",0,前提・入力!$B$7)+IF(K48="",0,前提・入力!$B$8)+IF(N48="",0,前提・入力!$B$9)),前提・入力!$B$11) -> 1.05 | P48: =ROUND(E48*O48,0) -> 0 | Q48: =P48*D48 -> 0 | R48: =IFERROR(P48/P$49,0) -> 0 | S48: 15 | T48: =IFERROR(P48/S48,0) -> 0 | U48: =MAX(0,S48-P48) -> 15 | V48: =P48-S48 -> -15 | W48: =IF(V48>0,"会期中に在庫切れ",IF(T48>=0.9,"要注意(90%超)",IF(T48>=0.5,"適正","在庫余剰"))) -> 在庫余剰
C49: 合計（LEGS 42SKU） | E49: =SUM(E7:E48) -> 4022 | F49: =SUM(F7:F48) -> 19983 | G49: =SUM(G7:G48) -> 28231 | I49: =SUM(I7:I48) -> 48303 | J49: =SUM(J7:J48) -> 59166 | L49: =SUM(L7:L48) -> 6422 | M49: =SUM(M7:M48) -> 8179 | O49: =IFERROR(P49/E49,0) -> 1.2807061 | P49: =SUM(P7:P48) -> 5151 | Q49: =SUM(Q7:Q48) -> 4292200 | R49: 1 | S49: =SUM(S7:S48) -> 46928 | T49: =IFERROR(P49/S49,0) -> 0.10976389 | U49: =SUM(U7:U48) -> 41810 | V49: =SUM(V7:V48) -> -41777 | W49: =COUNTIF(W7:W48,"会期中に在庫切れ")&"品目" -> 3品目

Sheet ②会場別構成比
A1: ② 会場別 物販実績とLEGS構成比／東京対比 会場比率
A2: 物販売上＝レジ袋代・音声ガイド・当日券を除く商品売上（税込）。LEGS＝本42SKU（各会場の商品分類「レッグス」と完全一致）
A4: ■ 会場別 実績・予測サマリー
A5: 項目 | B5: 東京対比 算出根拠 | C5: 東京 | D5: 名古屋 | E5: 博多 | F5: 大阪 | G5: 札幌 | H5: 石川 | I5: 石川(予測) | J5: 仙台 Ebeans | K5: 神戸阪急 | L5: 鳥取島根 夢みなとタワー | M5: 東京凱旋 東京建物ぴあホール
A6: 会期 | C6: 25/12/5(金)-12/29(月) 池袋サンシャインシティ | D6: 26/3/18(水)-4/5(日) 松坂屋 | E6: 26/4/23(木)-5/18(月) 博多阪急 | F6: 26/6/10(水)-6/29(月) 阪急梅田 | G6: 26/7/22(水)-8/10(月) 札幌大丸 | H6: 26/8/14(金)-8/31(月) 香林坊大和(金沢) | I6: 26/8/14(金)-8/31(月) 会期18日 予測 | J6: 26/9/5(土)-10/4(日) 仙台 Ebeans | K6: 26/12/16(水)-27/1/7(木) 神戸阪急 | L6: 27/3/15-4/4 鳥取島根 夢みなとタワー | M6: 27年4-5月 東京凱旋 東京建物ぴあホール
A7: 会期日数 | C7: 25 | D7: 19 | E7: 26 | F7: 20 | G7: 20 | H7: 18 | I7: 18 | J7: 30 | K7: 21 | L7: 21 | M7: 25
A8: データ実績日数 | C8: 25 | D8: 19 | E8: 26 | F8: 20 | G8: 20 | H8: 12 | I8: 予測 | J8: 予測 | K8: 予測 | L8: 予測 | M8: 予測
A9: 入場者数 | C9: 47339 | D9: 19764 | E9: 18993 | F9: 31267 | G9: 10270 | H9: 5304 | I9: 8923
A10: 全物販 販売数量 | C10: 383342 | D10: 169802 | E10: 112198 | F10: 238658 | G10: 40818 | H10: 19113 | I10: =H10*1.284925 -> 24558.772 | J10: =前提・入力!$B$14*前提・入力!$B$23 -> 49834.46 | K10: =前提・入力!$B$14*前提・入力!$B$24 -> 46001.04 | L10: =前提・入力!$B$14*前提・入力!$B$25 -> 34500.78 | M10: =前提・入力!$B$14*前提・入力!$B$26 -> 191671
A11: 全物販 販売金額(税込) | C11: 358193925 | D11: 138575410 | E11: 105540655 | F11: 215184570 | G11: 41120210 | H11: 19691300 | I11: =H11*1.27778 -> 25161149 | J11: =前提・入力!$B$13*前提・入力!$B$23 -> 46565210 | K11: =前提・入力!$B$13*前提・入力!$B$24 -> 42983271 | L11: =前提・入力!$B$13*前提・入力!$B$25 -> 32237453 | M11: =前提・入力!$B$13*前提・入力!$B$26 -> 1.7909696e+08
A12: LEGS 販売数量 | C12: 148185 | D12: 58600 | E12: 44871 | F12: 63740 | G12: 8891 | H12: 4022 | I12: =①石川予測確定!P49 -> 5151 | J12: =ROUND(J13/前提・入力!$B$30,0) -> 9536 | K12: =ROUND(K13/前提・入力!$B$30,0) -> 8802 | L12: =ROUND(L13/前提・入力!$B$30,0) -> 6602 | M12: =ROUND(M13/前提・入力!$B$30,0) -> 36677
A13: LEGS 販売金額(税込) | C13: 102186200 | D13: 41479600 | E13: 31026800 | F13: 45507600 | G13: 7217000 | H13: 3388400 | I13: =①石川予測確定!Q49 -> 4292200 | J13: =J11*前提・入力!$B$29 -> 7943484.4 | K13: =K11*前提・入力!$B$29 -> 7332447.2 | L13: =L11*前提・入力!$B$29 -> 5499335.4 | M13: =M11*前提・入力!$B$29 -> 30551863
A14: LEGS 数量構成比 | C14: =C12/C10 -> 0.38656083 | D14: =D12/D10 -> 0.34510783 | E14: =E12/E10 -> 0.39992691 | F14: =F12/F10 -> 0.26707674 | G14: =G12/G10 -> 0.21782057 | H14: =H12/H10 -> 0.21043269 | I14: =I12/I10 -> 0.20974176 | J14: =J12/J10 -> 0.19135353 | ... M14: =M12/M10 -> 0.19135393
A15: LEGS 金額構成比 | C15: =C13/C11 -> 0.28528178 | D15: =D13/D11 -> 0.29932872 | E15: =E13/E11 -> 0.2939796 | F15: =F13/F11 -> 0.21148171 | G15: =G13/G11 -> 0.1755098 | H15: =H13/H11 -> 0.17207599 | I15: =I13/I11 -> 0.17058839 | J15: =J13/J11 -> 0.17058839 | ... M15: =M13/M11 -> 0.17058839
A16: 東京対比（数量） | C16: =C10/$C$10 -> 1 | D16: =D10/$C$10 -> 0.44295172 | E16: =E10/$C$10 -> 0.29268382 | F16: =F10/$C$10 -> 0.62257201 | G16: =G10/$C$10 -> 0.10647933 | H16: =H10/$C$10 -> 0.049858873 | I16: =I10/$C$10 -> 0.064064912 | J16: =J10/$C$10 -> 0.13 | ... M16: =M10/$C$10 -> 0.5
A17: 東京対比（金額） | B17: ユーザー指定／入力値 | C17: =C11/$C$11 -> 1 | D17: =D11/$C$11 -> 0.38687259 | E17: =E11/$C$11 -> 0.29464669 | F17: =F11/$C$11 -> 0.6007488 | G17: =G11/$C$11 -> 0.11479874 | H17: =H11/$C$11 -> 0.054973853 | I17: =I11/$C$11 -> 0.070244489 | J17: =前提・入力!$B$23 -> 0.13 | K17: =前提・入力!$B$24 -> 0.12 | L17: =前提・入力!$B$25 -> 0.09 | M17: =前提・入力!$B$26 -> 0.5
A18: LEGS平均単価 | C18: =IFERROR(C13/C12,0) -> 689.58532 | D18: =IFERROR(D13/D12,0) -> 707.843 | E18: =IFERROR(E13/E12,0) -> 691.46665 | F18: =IFERROR(F13/F12,0) -> 713.9567 | G18: =IFERROR(G13/G12,0) -> 811.71972 | H18: =IFERROR(H13/H12,0) -> 842.46643 | I18: =I13/I12 -> 833.27509 | J18: =J13/J12 -> 832.99962 | K18: =K13/K12 -> 833.0433 | L18: =L13/L12 -> 832.98021 | M18: =M13/M12 -> 832.99788
A21: ■ 供給元別 金額構成比（各会場 会期全体。石川は初12日実績）
A22: 供給元 | C22: 東京 | D22: 名古屋 | E22: 博多 | F22: 大阪 | G22: 札幌 | H22: 石川
A23: LEGS(42SKU) | C23: 0.28528178 | D23: 0.29932872 | E23: 0.2939796 | F23: 0.21148171 | G23: 0.1755098 | H23: 0.17207599
A24: ムービック | C24: 0.53383923 | D24: 0.35138442 | E24: 0.32105543 | F24: 0.41894519 | G24: 0.39083993 | H24: 0.41503303
A25: 東宝 | C25: 0.092163721 | D25: 0.078365491 | E25: 0.078289309 | F25: 0.15216207 | G25: 0.16841256 | H25: 0.1499901
A26: MAPPA | C26: 0 | D26: 0.23618072 | E26: 0.23252348 | F26: 0.14301109 | G26: 0.18539399 | H26: 0.17836202
A27: MBS | C27: 0.033272116 | D27: 0.034740651 | E27: 0.074152183 | F27: 0.074399944 | G27: 0.079843707 | H27: 0.084538857
A28: 書籍 | C28: 0.055443151 | D28: 0 | E28: 0 | F28: 0 | G28: 0 | H28: 0
A29: その他 | C29: 0 | D29: 0 | E29: 0 | F29: 0 | G29: 0 | H29: 0
A30: 合計 | C30: =SUM(C23:C29) -> 1 | D30: =SUM(D23:D29) -> 1 | E30: =SUM(E23:E29) -> 1 | F30: =SUM(F23:F29) -> 1 | G30: =SUM(G23:G29) -> 1 | H30: =SUM(H23:H29) -> 1
A32: ■ 新規SKU投入状況（前会場までに存在しなかったJAN）
A33: 会場 | C33: 総SKU数 | D33: 新規SKU数 | E33: 新規の金額シェア(初12日) | F33: LEGS金額構成比(初12日) | G33: 備考
A34: 東京 | C34: 332 | D34: 332 | E34: 1 | F34: 0.29591818 | G34: 初回会場
A35: 名古屋 | C35: 416 | D35: 85 | E35: 0.21120858 | F35: 0.30653237 | G35: MAPPA記念商品26SKU等を追加投入
A36: 博多 | C36: 435 | D36: 19 | E36: 0.14640066 | F36: 0.24448655 | G36: 小幅追加
A37: 大阪 | C37: 515 | D37: 106 | E37: 0.19145772 | F37: 0.20698479 | G37: ★新商品106SKU投入（東宝一般66・ムービック23・MAPPA16）
A38: 札幌 | C38: 382 | D38: 0 | E38: 0 | F38: 0.17555848 | G38: 新規なし。品揃えは大阪と同一
A39: 石川 | C39: 382 | D39: 0 | E39: 0 | F39: 0.17207599 | G39: 新規なし。品揃えは大阪と同一

Sheet ③仙台以降予測
A1: ③ 仙台会場以降 4会場 LEGS商品 需要予測
A2: 会場物販売上＝東京(初回)実績 × 東京対比比率 ／ LEGS売上＝会場物販売上 × LEGS金額構成比 ／ LEGS数量＝LEGS売上 ÷ LEGS平均単価
A3: 商品別按分＝札幌20日実績の数量構成比 × ウェイト ＋ 石川18日予測の数量構成比 × ウェイト（「前提・入力」で調整可）
A4: ※商品別表の必要数合計は、会場×商品ごとに整数丸めを行うため会場別表の合計と数個の差が生じる（発注判断に影響しない範囲）
A5: ■ 会場別 需要予測
A6: 会場 | B6: 会期 | C6: 日数 | D6: 東京対比 | E6: 会場 全物販売上 | F6: LEGS 売上 | G6: LEGS 数量 | H6: 構成比根拠
A7: 仙台 Ebeans | B7: 26/9/5(土)-10/4(日) | C7: 30 | D7: =前提・入力!$B$23 -> 0.13 | E7: =前提・入力!$B$13*D7 -> 46565210 | F7: =E7*前提・入力!$B$29 -> 7943484.4 | G7: =ROUND(F7/前提・入力!$B$30,0) -> 9536 | H7: ユーザー指定（コナン実績は10.5%）
A8: 神戸阪急 | B8: 26/12/16(水)-27/1/7(木) | C8: 21 | D8: =前提・入力!$B$24 -> 0.12 | E8: =前提・入力!$B$13*D8 -> 42983271 | F8: =E8*前提・入力!$B$29 -> 7332447.2 | G8: =ROUND(F8/前提・入力!$B$30,0) -> 8802 | H8: ★要確認：指定なきため仮置き
A9: 鳥取島根 夢みなとタワー | B9: 27/3/15-4/4 | C9: 21 | D9: =前提・入力!$B$25 -> 0.09 | E9: =前提・入力!$B$13*D9 -> 32237453 | F9: =E9*前提・入力!$B$29 -> 5499335.4 | G9: =ROUND(F9/前提・入力!$B$30,0) -> 6602 | H9: ユーザー指定
A10: 東京凱旋 東京建物ぴあホール | B10: 27年4-5月 | C10: 25 | D10: =前提・入力!$B$26 -> 0.5 | E10: =前提・入力!$B$13*D10 -> 1.7909696e+08 | F10: =E10*前提・入力!$B$29 -> 30551863 | G10: =ROUND(F10/前提・入力!$B$30,0) -> 36677 | H10: ユーザー指定（初回東京の50%）
A11: 仙台以降 4会場 合計 | D11: =SUM(D7:D10) -> 0.84 | E11: =SUM(E7:E10) -> 300882897 | F11: =SUM(F7:F10) -> 51327130 | G11: =SUM(G7:G10) -> 61617
A13: ■ 在庫収支（LEGS 42SKU 合計）
A14: 残在庫想定（台帳 梅田まで(SET)／総計） | B14: 276521 | C14: 在庫フロー台帳の最終「実在庫」列。会場ごとの追加発注→販売→検品を積み上げた値
A15: うち札幌会場へ納品 | B15: 50506 | C15: 札幌の販売可能数。台帳・ロジ在庫はこの出荷までを反映している
A16: ★倉庫残（札幌出荷後） | B16: =Q73 -> 197962 | C16: ロジ（倉庫WMS）2026/8/5時点の実棚を採用。台帳から計算した 226,015個 との差 -28053個
A17: 札幌 会期20日 実績販売数 | B17: 8891 | C17: 会期終了済みの確定値
A18: 札幌 会期末 残（実績） | B18: =R73 -> 41615 | C18: 販売可能数 − 実績販売数。石川会場へ転送された分と倉庫へ戻った分の合計
A19: うち販売不可（日報未反映の持出） | B19: 0 | C19: 日報に載っていない持出がある場合のみここで控除する。現在なし
A20: ［参考］会場での持出・不良・ｻﾝﾌﾟﾙ | B20: 58 | C20: 日報の「販売可能数＝納品数−持出・不良・ｻﾝﾌﾟﾙ」で既に控除済み。二重に引かないため供給可能在庫の計算には入れていない。内訳：東京 16個／名古屋 21個／博多 4個／大阪 13個／札幌 4個
A21: 石川へ納品（初回＋転送＋追納） | B21: =①石川予測確定!S49 -> 46928 | C21: 2026/8 石川(金沢)会場への札幌転送分＋8/22追納（日報の販売可能数に反映済み）を含む
A22: 石川 会期18日 予測販売数 | B22: =①石川予測確定!P49 -> 5151
A23: 仙台以降 供給可能在庫 合計 | B23: =B16+B18-B19-B22 -> 234426 | C23: ＝倉庫残 ＋ 札幌会期末残 − 販売不可 − 石川会期予測販売。石川への納品はこの2つから出ているので相殺される
A24: 確定済み追加発注（入荷予定） | B24: 1200 | C24: 発注判断済みの分。宿儺の指風お菓子 1,200SET（鳥取島根 夢みなとタワー入荷）
A25: 仙台以降 4会場 必要数 | B25: =G11 -> 61617
A26: 全体過不足（供給可能＋確定発注−必要） | B26: =B23+B24-B25 -> 174009 | C26: プラス＝全体では在庫充足。ただし商品別には過不足が生じる
A27: 追加生産 必要数（商品別不足の合計） | B27: =Y73 -> 3384 | C27: 下表の商品別「追加生産必要数」の合計。全体余剰でも品目別には不足が出る
A29: ■ 商品別 仙台以降 必要数と在庫過不足
A30: No. | B30: JAN | C30: 商品名 | D30: 札幌⑤ 20日実績 | E30: 札幌 構成比 | F30: 石川⑥ 18日予測 | G30: 石川 構成比 | H30: 採用 按分構成比 | I30: 仙台 必要数 | J30: 神戸阪急 必要数 | K30: 鳥取島根 必要数 | L30: 東京凱旋 必要数 | M30: 仙台以降 必要数 計 | N30: ★残在庫想定 (台帳 梅田まで) | O30: うち札幌 へ納品 | P30: ★ロジ在庫 (2026/8/5 実棚) | Q30: 差引 倉庫残 | R30: 札幌会期末 残（実績） | S30: 販売不可 (日報未反映) | T30: 石川へ納品 (初回+転送+追納) | U30: 石川 会期18日 予測販売 | V30: 仙台以降 供給可能計 | W30: 確定発注 (入荷予定) | X30: 過不足 (必要−供給可能−確定) | Y30: 追加生産 必要数 | Z30: 推奨発注数 (安全率込)
A31: 1 | B31: 4515142545082 | C31: 呪術廻戦 メタリックポストカード 展示会キービジュアル | D31: 507 | E31: =IFERROR(D31/D$73,0) -> 0.057023957 | F31: =①石川予測確定!P7 -> 272 | G31: =IFERROR(F31/F$73,0) -> 0.052805281 | H31: =E31*前提・入力!$B$31+G31*前提・入力!$B$32 -> 0.054914619 | I31: =ROUND($H31*③仙台以降予測!$G$7,0) -> 524 | J31: =ROUND($H31*③仙台以降予測!$G$8,0) -> 483 | K31: =ROUND($H31*③仙台以降予測!$G$9,0) -> 363 | L31: =ROUND($H31*③仙台以降予測!$G$10,0) -> 2014 | M31: =SUM(I31:L31) -> 3384 | N31: 3271 | O31: 1000 | P31: 2268 | Q31: =IF(P31="",N31-O31,P31) -> 2268 | R31: 493 | S31: 0 | T31: =①石川予測確定!S7 -> 693 | U31: =①石川予測確定!P7 -> 272 | V31: =Q31+R31-S31-U31 -> 2489 | W31: 0 | X31: =M31-V31-W31 -> 895 | Y31: =MAX(0,X31) -> 895 | Z31: =IF(Y31>0,ROUNDUP(Y31*(1+前提・入力!$B$34),0),0) -> 985
A32: 2 | B32: 4515142545099 | C32: 呪術廻戦 クリアファイル 展示会キービジュアル | D32: 541 | E32: =IFERROR(D32/D$73,0) -> 0.060848049 | F32: =①石川予測確定!P8 -> 325 | G32: =IFERROR(F32/F$73,0) -> 0.063094545 | H32: =E32*前提・入力!$B$31+G32*前提・入力!$B$32 -> 0.061971297 | I32: =ROUND($H32*③仙台以降予測!$G$7,0) -> 591 | J32: =ROUND($H32*③仙台以降予測!$G$8,0) -> 545 | K32: =ROUND($H32*③仙台以降予測!$G$9,0) -> 409 | L32: =ROUND($H32*③仙台以降予測!$G$10,0) -> 2273 | M32: =SUM(I32:L32) -> 3818 | N32: 5038 | O32: 1000 | P32: 4036 | Q32: =IF(P32="",N32-O32,P32) -> 4036 | R32: 459 | S32: 0 | T32: =①石川予測確定!S8 -> 659 | U32: =①石川予測確定!P8 -> 325 | V32: =Q32+R32-S32-U32 -> 4170 | W32: 0 | X32: =M32-V32-W32 -> -352 | Y32: =MAX(0,X32) -> 0 | Z32: =IF(Y32>0,ROUNDUP(Y32*(1+前提・入力!$B$34),0),0) -> 0
A33: 3 | B33: 4515142545105 | C33: 呪術廻戦 懐玉・玉折 ポストカードセット（5枚入） | D33: 169 | E33: =IFERROR(D33/D$73,0) -> 0.019007986 | F33: =①石川予測確定!P9 -> 118 | G33: =IFERROR(F33/F$73,0) -> 0.022908173 | H33: =E33*前提・入力!$B$31+G33*前提・入力!$B$32 -> 0.020958079 | I33: =ROUND($H33*③仙台以降予測!$G$7,0) -> 200 | J33: =ROUND($H33*③仙台以降予測!$G$8,0) -> 184 | K33: =ROUND($H33*③仙台以降予測!$G$9,0) -> 138 | L33: =ROUND($H33*③仙台以降予測!$G$10,0) -> 769 | M33: =SUM(I33:L33) -> 1291 | N33: 6140 | O33: 450 | P33: 1694 | Q33: =IF(P33="",N33-O33,P33) -> 1694 | R33: 281 | S33: 0 | T33: =①石川予測確定!S9 -> 381 | U33: =①石川予測確定!P9 -> 118 | V33: =Q33+R33-S33-U33 -> 1857 | W33: 0 | X33: =M33-V33-W33 -> -566 | Y33: =MAX(0,X33) -> 0 | Z33: =IF(Y33>0,ROUNDUP(Y33*(1+前提・入力!$B$34),0),0) -> 0
A34: 4 | B34: 4515142545112 | C34: 呪術廻戦 渋谷事変 ポストカードセット（9枚入） | D34: 228 | E34: =IFERROR(D34/D$73,0) -> 0.02564391 | F34: =①石川予測確定!P10 -> 134 | G34: =IFERROR(F34/F$73,0) -> 0.026014366 | H34: =E34*前提・入力!$B$31+G34*前提・入力!$B$32 -> 0.025829138 | I34: =ROUND($H34*③仙台以降予測!$G$7,0) -> 246 | J34: =ROUND($H34*③仙台以降予測!$G$8,0) -> 227 | K34: =ROUND($H34*③仙台以降予測!$G$9,0) -> 171 | L34: =ROUND($H34*③仙台以降予測!$G$10,0) -> 947 | M34: =SUM(I34:L34) -> 1591 | N34: 27511 | O34: 800 | P34: 2715 | Q34: =IF(P34="",N34-O34,P34) -> 2715 | R34: 572 | S34: 0 | T34: =①石川予測確定!S10 -> 772 | U34: =①石川予測確定!P10 -> 134 | V34: =Q34+R34-S34-U34 -> 3153 | W34: 0 | X34: =M34-V34-W34 -> -1562 | Y34: =MAX(0,X34) -> 0 | Z34: =IF(Y34>0,ROUNDUP(Y34*(1+前提・入力!$B$34),0),0) -> 0
A35: 5 | B35: 4515142545129 | C35: 呪術廻戦 懐玉・玉折 ブラインド缶バッジ（全5種） | D35: 410 | E35: =IFERROR(D35/D$73,0) -> 0.046114048 | F35: =①石川予測確定!P11 -> 293 | G35: =IFERROR(F35/F$73,0) -> 0.056882159 | H35: =E35*前提・入力!$B$31+G35*前提・入力!$B$32 -> 0.051498103 | I35: =ROUND($H35*③仙台以降予測!$G$7,0) -> 491 | J35: =ROUND($H35*③仙台以降予測!$G$8,0) -> 453 | K35: =ROUND($H35*③仙台以降予測!$G$9,0) -> 340 | L35: =ROUND($H35*③仙台以降予測!$G$10,0) -> 1889 | M35: =SUM(I35:L35) -> 3173 | N35: 40108 | O35: 9000 | P35: 31095 | Q35: =IF(P35="",N35-O35,P35) -> 31095 | R35: 8590 | S35: 0 | T35: =①石川予測確定!S11 -> 8790 | U35: =①石川予測確定!P11 -> 293 | V35: =Q35+R35-S35-U35 -> 39392 | W35: 0 | X35: =M35-V35-W35 -> -36219 | Y35: =MAX(0,X35) -> 0 | Z35: =IF(Y35>0,ROUNDUP(Y35*(1+前提・入力!$B$34),0),0) -> 0
A36: 6 | B36: 4515142545136 | C36: 呪術廻戦 渋谷事変 ブラインド缶バッジ（全9種） | D36: 1042 | E36: =IFERROR(D36/D$73,0) -> 0.11719717 | F36: =①石川予測確定!P12 -> 565 | G36: =IFERROR(F36/F$73,0) -> 0.10968744 | H36: =E36*前提・入力!$B$31+G36*前提・入力!$B$32 -> 0.1134423 | I36: =ROUND($H36*③仙台以降予測!$G$7,0) -> 1082 | J36: =ROUND($H36*③仙台以降予測!$G$8,0) -> 999 | K36: =ROUND($H36*③仙台以降予測!$G$9,0) -> 749 | L36: =ROUND($H36*③仙台以降予測!$G$10,0) -> 4161 | M36: =SUM(I36:L36) -> 6991 | N36: 51840 | O36: 13991 | P36: 37844 | Q36: =IF(P36="",N36-O36,P36) -> 37844 | R36: 12949 | S36: 0 | T36: =①石川予測確定!S12 -> 13249 | U36: =①石川予測確定!P12 -> 565 | V36: =Q36+R36-S36-U36 -> 50228 | W36: 0 | X36: =M36-V36-W36 -> -43237 | Y36: =MAX(0,X36) -> 0 | Z36: =IF(Y36>0,ROUNDUP(Y36*(1+前提・入力!$B$34),0),0) -> 0
A37: 7 | B37: 4515142545143 | C37: 呪術廻戦 懐玉・玉折 ブラインドダイカットステッカー（全5種） | D37: 187 | E37: =IFERROR(D37/D$73,0) -> 0.021032505 | F37: =①石川予測確定!P13 -> 165 | G37: =IFERROR(F37/F$73,0) -> 0.032032615 | H37: =E37*前提・入力!$B$31+G37*前提・入力!$B$32 -> 0.02653256 | I37: =ROUND($H37*③仙台以降予測!$G$7,0) -> 253 | J37: =ROUND($H37*③仙台以降予測!$G$8,0) -> 234 | K37: =ROUND($H37*③仙台以降予測!$G$9,0) -> 175 | L37: =ROUND($H37*③仙台以降予測!$G$10,0) -> 973 | M37: =SUM(I37:L37) -> 1635 | N37: 4601 | O37: 350 | P37: 4251 | Q37: =IF(P37="",N37-O37,P37) -> 4251 | R37: 163 | S37: 0 | T37: =①石川予測確定!S13 -> 463 | U37: =①石川予測確定!P13 -> 165 | V37: =Q37+R37-S37-U37 -> 4249 | W37: 0 | X37: =M37-V37-W37 -> -2614 | Y37: =MAX(0,X37) -> 0 | Z37: =IF(Y37>0,ROUNDUP(Y37*(1+前提・入力!$B$34),0),0) -> 0
A38: 8 | B38: 4515142545150 | C38: 呪術廻戦 渋谷事変 ブラインドダイカットステッカー（全9種） | D38: 322 | E38: =IFERROR(D38/D$73,0) -> 0.036216399 | F38: =①石川予測確定!P14 -> 266 | G38: =IFERROR(F38/F$73,0) -> 0.051640458 | H38: =E38*前提・入力!$B$31+G38*前提・入力!$B$32 -> 0.043928428 | I38: =ROUND($H38*③仙台以降予測!$G$7,0) -> 419 | J38: =ROUND($H38*③仙台以降予測!$G$8,0) -> 387 | K38: =ROUND($H38*③仙台以降予測!$G$9,0) -> 290 | L38: =ROUND($H38*③仙台以降予測!$G$10,0) -> 1611 | M38: =SUM(I38:L38) -> 2707 | N38: 8622 | O38: 900 | P38: 7722 | Q38: =IF(P38="",N38-O38,P38) -> 7722 | R38: 578 | S38: 0 | T38: =①石川予測確定!S14 -> 778 | U38: =①石川予測確定!P14 -> 266 | V38: =Q38+R38-S38-U38 -> 8034 | W38: 0 | X38: =M38-V38-W38 -> -5327 | Y38: =MAX(0,X38) -> 0 | Z38: =IF(Y38>0,ROUNDUP(Y38*(1+前提・入力!$B$34),0),0) -> 0
A39: 9 | B39: 4515142545372 | C39: 呪術廻戦 懐玉・玉折 クリアファイル（五条 悟） | D39: 160 | E39: =IFERROR(D39/D$73,0) -> 0.017995726 | F39: =①石川予測確定!P15 -> 51 | G39: =IFERROR(F39/F$73,0) -> 0.0099009901 | H39: =E39*前提・入力!$B$31+G39*前提・入力!$B$32 -> 0.013948358 | I39: =ROUND($H39*③仙台以降予測!$G$7,0) -> 133 | J39: =ROUND($H39*③仙台以降予測!$G$8,0) -> 123 | K39: =ROUND($H39*③仙台以降予測!$G$9,0) -> 92 | L39: =ROUND($H39*③仙台以降予測!$G$10,0) -> 512 | M39: =SUM(I39:L39) -> 860 | N39: 8760 | O39: 300 | P39: 8458 | Q39: =IF(P39="",N39-O39,P39) -> 8458 | R39: 140 | S39: 0 | T39: =①石川予測確定!S15 -> 740 | U39: =①石川予測確定!P15 -> 51 | V39: =Q39+R39-S39-U39 -> 8547 | W39: 0 | X39: =M39-V39-W39 -> -7687 | Y39: =MAX(0,X39) -> 0 | Z39: =IF(Y39>0,ROUNDUP(Y39*(1+前提・入力!$B$34),0),0) -> 0
A40: 10 | B40: 4515142545389 | C40: 呪術廻戦 懐玉・玉折 クリアファイル（夏油 傑） | D40: 59 | E40: =IFERROR(D40/D$73,0) -> 0.006635924 | F40: =①石川予測確定!P16 -> 20 | G40: =IFERROR(F40/F$73,0) -> 0.0038827412 | H40: =E40*前提・入力!$B$31+G40*前提・入力!$B$32 -> 0.0052593326 | I40: =ROUND($H40*③仙台以降予測!$G$7,0) -> 50 | J40: =ROUND($H40*③仙台以降予測!$G$8,0) -> 46 | K40: =ROUND($H40*③仙台以降予測!$G$9,0) -> 35 | L40: =ROUND($H40*③仙台以降予測!$G$10,0) -> 193 | M40: =SUM(I40:L40) -> 324 | N40: 4934 | O40: 100 | P40: 4835 | Q40: =IF(P40="",N40-O40,P40) -> 4835 | R40: 41 | S40: 0 | T40: =①石川予測確定!S16 -> 541 | U40: =①石川予測確定!P16 -> 20 | V40: =Q40+R40-S40-U40 -> 4856 | W40: 0 | X40: =M40-V40-W40 -> -4532 | Y40: =MAX(0,X40) -> 0 | Z40: =IF(Y40>0,ROUNDUP(Y40*(1+前提・入力!$B$34),0),0) -> 0
A41: 11 | B41: 4515142545396 | C41: 呪術廻戦 懐玉・玉折 クリアファイル（家入 硝子） | D41: 21 | E41: =IFERROR(D41/D$73,0) -> 0.002361939 | F41: =①石川予測確定!P17 -> 8 | G41: =IFERROR(F41/F$73,0) -> 0.0015530965 | H41: =E41*前提・入力!$B$31+G41*前提・入力!$B$32 -> 0.0019575178 | I41: =ROUND($H41*③仙台以降予測!$G$7,0) -> 19 | J41: =ROUND($H41*③仙台以降予測!$G$8,0) -> 17 | K41: =ROUND($H41*③仙台以降予測!$G$9,0) -> 13 | L41: =ROUND($H41*③仙台以降予測!$G$10,0) -> 72 | M41: =SUM(I41:L41) -> 121 | N41: 640 | O41: 50 | P41: 588 | Q41: =IF(P41="",N41-O41,P41) -> 588 | R41: 29 | S41: 0 | T41: =①石川予測確定!S17 -> 79 | U41: =①石川予測確定!P17 -> 8 | V41: =Q41+R41-S41-U41 -> 609 | W41: 0 | X41: =M41-V41-W41 -> -488 | Y41: =MAX(0,X41) -> 0 | Z41: =IF(Y41>0,ROUNDUP(Y41*(1+前提・入力!$B$34),0),0) -> 0
A42: 12 | B42: 4515142545402 | C42: 呪術廻戦 懐玉・玉折 クリアファイル（七海 建人） | D42: 43 | E42: =IFERROR(D42/D$73,0) -> 0.0048363514 | F42: =①石川予測確定!P18 -> 17 | G42: =IFERROR(F42/F$73,0) -> 0.00330033 | H42: =E42*前提・入力!$B$31+G42*前提・入力!$B$32 -> 0.0040683407 | I42: =ROUND($H42*③仙台以降予測!$G$7,0) -> 39 | J42: =ROUND($H42*③仙台以降予測!$G$8,0) -> 36 | K42: =ROUND($H42*③仙台以降予測!$G$9,0) -> 27 | L42: =ROUND($H42*③仙台以降予測!$G$10,0) -> 149 | M42: =SUM(I42:L42) -> 251 | N42: 953 | O42: 50 | P42: 901 | Q42: =IF(P42="",N42-O42,P42) -> 901 | R42: 7 | S42: 0 | T42: =①石川予測確定!S18 -> 107 | U42: =①石川予測確定!P18 -> 17 | V42: =Q42+R42-S42-U42 -> 891 | W42: 0 | X42: =M42-V42-W42 -> -640 | Y42: =MAX(0,X42) -> 0 | Z42: =IF(Y42>0,ROUNDUP(Y42*(1+前提・入力!$B$34),0),0) -> 0
...

Sheet ④追加発注判定
A1: ④ 追加発注 必要有無の判定（石川会期中 ＋ 仙台以降4会場）
A2: 【石川会期中】会期18日予測 vs 石川への納品済 販売可能数 ／ 【仙台以降】4会場必要数 vs 倉庫在庫＋石川会期末残在庫
A3: 推奨発注数＝不足数×(1+安全率10%)を切り上げ。欠品発生会場・最終発注期限（会期初日−生産日数−バッファ）・残日数・緊急度を右側に記載
A6: No. | B6: JAN | C6: 商品名 | D6: 税込単価 | E6: 石川 初12日実績 | F6: 石川 会期18日予測 | G6: 石川 販売可能数 (転送・追納込) | H6: 石川 予測消化率 | I6: 石川会期中 過不足 | J6: 石川会期中 判定 | K6: 石川会期中 推奨発注数 | L6: 仙台以降 必要数 | M6: 仙台以降 供給可能在庫 | N6: 確定発注 (入荷予定) | O6: 仙台以降 過不足 | P6: 仙台以降 判定 | Q6: 仙台以降 推奨発注数 | R6: 発注合計 (石川+仙台以降) | S6: 発注金額 (税込小売換算) | T6: 欠品発生 会場 | U6: 最終発注期限 | V6: 基準日からの 残日数 | W6: 発注の緊急度 | X6: 優先度 | Y6: 運営 欠品報告 (受領なし) | Z6: モデル×現場 突合 | AA6: 備考
A7: 1 | B7: 4515142545082 | C7: 呪術廻戦 メタリックポストカード 展示会キービジュアル | D7: 500 | E7: =①石川予測確定!E7 -> 210 | F7: =①石川予測確定!P7 -> 272 | G7: =①石川予測確定!S7 -> 693 | H7: =IFERROR(F7/G7,0) -> 0.39249639 | I7: =F7-G7 -> -421 | J7: =IF(I7>0,"要 追加発注",IF(H7>=0.9,"要注意(90%超)",IF(H7>=0.5,"適正","在庫余剰"))) -> 在庫余剰 | K7: =IF(I7>0,ROUNDUP(I7*(1+前提・入力!$B$34),0),0) -> 0 | L7: =③仙台以降予測!M31 -> 3384 | M7: =③仙台以降予測!V31 -> 2489 | N7: =③仙台以降予測!W31 -> 0 | O7: =L7-M7-N7 -> 895 | P7: =IF(O7>0,"要 追加生産",IF(L7=0,"—","在庫で充足")) -> 要 追加生産 | Q7: =③仙台以降予測!Z31 -> 985 | R7: =K7+Q7 -> 985 | S7: =R7*D7 -> 492500 | T7: 東京凱旋 東京建物ぴあホール | U7: =DATE(2027,4,1)-30-前提・入力!$B$37 -> 46434 | V7: =IF(OR(U7="",U7="再生産不可"),"",U7-前提・入力!$B$38) -> 174 | W7: =IF(T7="—","—",IF(U7="再生産不可","×再生産不可",_xlfn.IFS(V7<0,"★期限超過",V7<=30,"★至急(30日以内)",V7<=90,"要着手(90日以内)",TRUE(),"余裕あり"))) -> 余裕あり | X7: =IF(Y7<>"",IF(FALSE(),"S:現場欠品(追納不可)","S:現場欠品"),IF(I7>0,"A:会期中欠品",IF(O7>1000,"B:大口",IF(O7>0,"C:通常","D:不要")))) -> C:通常 | Z7: =IF(Y7<>"",IF(I7>0,"◎ 一致（モデルも会期中欠品を検知）",IF(H7>=0.7,"○ 整合（予測消化率70%超）","△ モデル未検知：現場報告を優先")),IF(I7>0,"▲ モデルのみ検知：現場に在庫状況を確認","—")) -> — | AA7: 博多会場で完売（実績が在庫上限で頭打ち＝予測は控えめ）
A8: 2 | B8: 4515142545099 | C8: 呪術廻戦 クリアファイル 展示会キービジュアル | D8: 600 | E8: =①石川予測確定!E8 -> 250 | F8: =①石川予測確定!P8 -> 325 | G8: =①石川予測確定!S8 -> 659 | H8: =IFERROR(F8/G8,0) -> 0.49317147 | I8: =F8-G8 -> -334 | J8: =IF(I8>0,"要 追加発注",IF(H8>=0.9,"要注意(90%超)",IF(H8>=0.5,"適正","在庫余剰"))) -> 在庫余剰 | K8: =IF(I8>0,ROUNDUP(I8*(1+前提・入力!$B$34),0),0) -> 0 | L8: =③仙台以降予測!M32 -> 3818 | M8: =③仙台以降予測!V32 -> 4170 | N8: =③仙台以降予測!W32 -> 0 | O8: =L8-M8-N8 -> -352 | P8: =IF(O8>0,"要 追加生産",IF(L8=0,"—","在庫で充足")) -> 在庫で充足 | Q8: =③仙台以降予測!Z32 -> 0 | R8: =K8+Q8 -> 0 | S8: =R8*D8 -> 0 | T8: — | V8: =IF(OR(U8="",U8="再生産不可"),"",U8-前提・入力!$B$38) | W8: =IF(T8="—","—",IF(U8="再生産不可","×再生産不可",_xlfn.IFS(V8<0,"★期限超過",V8<=30,"★至急(30日以内)",V8<=90,"要着手(90日以内)",TRUE(),"余裕あり"))) -> — | X8: =IF(Y8<>"",IF(FALSE(),"S:現場欠品(追納不可)","S:現場欠品"),IF(I8>0,"A:会期中欠品",IF(O8>1000,"B:大口",IF(O8>0,"C:通常","D:不要")))) -> D:不要 | Z8: =IF(Y8<>"",IF(I8>0,"◎ 一致（モデルも会期中欠品を検知）",IF(H8>=0.7,"○ 整合（予測消化率70%超）","△ モデル未検知：現場報告を優先")),IF(I8>0,"▲ モデルのみ検知：現場に在庫状況を確認","—")) -> —
A9: 3 | B9: 4515142545105 | C9: 呪術廻戦 懐玉・玉折 ポストカードセット（5枚入） | D9: 1000 | E9: =①石川予測確定!E9 -> 92 | F9: =①石川予測確定!P9 -> 118 | G9: =①石川予測確定!S9 -> 381 | H9: =IFERROR(F9/G9,0) -> 0.30971129 | I9: =F9-G9 -> -263 | J9: =IF(I9>0,"要 追加発注",IF(H9>=0.9,"要注意(90%超)",IF(H9>=0.5,"適正","在庫余剰"))) -> 在庫余剰 | K9: =IF(I9>0,ROUNDUP(I9*(1+前提・入力!$B$34),0),0) -> 0 | L9: =③仙台以降予測!M33 -> 1291 | M9: =③仙台以降予測!V33 -> 1857 | N9: =③仙台以降予測!W33 -> 0 | O9: =L9-M9-N9 -> -566 | P9: =IF(O9>0,"要 追加生産",IF(L9=0,"—","在庫で充足")) -> 在庫で充足 | Q9: =③仙台以降予測!Z33 -> 0 | R9: =K9+Q9 -> 0 | S9: =R9*D9 -> 0 | T9: — | V9: =IF(OR(U9="",U9="再生産不可"),"",U9-前提・入力!$B$38) | W9: =IF(T9="—","—",IF(U9="再生産不可","×再生産不可",_xlfn.IFS(V9<0,"★期限超過",V9<=30,"★至急(30日以内)",V9<=90,"要着手(90日以内)",TRUE(),"余裕あり"))) -> — | X9: =IF(Y9<>"",IF(FALSE(),"S:現場欠品(追納不可)","S:現場欠品"),IF(I9>0,"A:会期中欠品",IF(O9>1000,"B:大口",IF(O9>0,"C:通常","D:不要")))) -> D:不要 | Z9: =IF(Y9<>"",IF(I9>0,"◎ 一致（モデルも会期中欠品を検知）",IF(H9>=0.7,"○ 整合（予測消化率70%超）","△ モデル未検知：現場報告を優先")),IF(I9>0,"▲ モデルのみ検知：現場に在庫状況を確認","—")) -> —
A10: 4 | B10: 4515142545112 | C10: 呪術廻戦 渋谷事変 ポストカードセット（9枚入） | D10: 1800 | E10: =①石川予測確定!E10 -> 110 | F10: =①石川予測確定!P10 -> 134 | G10: =①石川予測確定!S10 -> 772 | H10: =IFERROR(F10/G10,0) -> 0.17357513 | I10: =F10-G10 -> -638 | J10: =IF(I10>0,"要 追加発注",IF(H10>=0.9,"要注意(90%超)",IF(H10>=0.5,"適正","在庫余剰"))) -> 在庫余剰 | K10: =IF(I10>0,ROUNDUP(I10*(1+前提・入力!$B$34),0),0) -> 0 | L10: =③仙台以降予測!M34 -> 1591 | M10: =③仙台以降予測!V34 -> 3153 | N10: =③仙台以降予測!W34 -> 0 | O10: =L10-M10-N10 -> -1562 | P10: =IF(O10>0,"要 追加生産",IF(L10=0,"—","在庫で充足")) -> 在庫で充足 | Q10: =③仙台以降予測!Z34 -> 0 | R10: =K10+Q10 -> 0 | S10: =R10*D10 -> 0 | T10: — | V10: =IF(OR(U10="",U10="再生産不可"),"",U10-前提・入力!$B$38) | W10: =IF(T10="—","—",IF(U10="再生産不可","×再生産不可",_xlfn.IFS(V10<0,"★期限超過",V10<=30,"★至急(30日以内)",V10<=90,"要着手(90日以内)",TRUE(),"余裕あり"))) -> — | X10: =IF(Y10<>"",IF(FALSE(),"S:現場欠品(追納不可)","S:現場欠品"),IF(I10>0,"A:会期中欠品",IF(O10>1000,"B:大口",IF(O10>0,"C:通常","D:不要")))) -> D:不要 | Z10: =IF(Y10<>"",IF(I10>0,"◎ 一致（モデルも会期中欠品を検知）",IF(H10>=0.7,"○ 整合（予測消化率70%超）","△ モデル未検知：現場報告を優先")),IF(I10>0,"▲ モデルのみ検知：現場に在庫状況を確認","—")) -> —
A11: 5 | B11: 4515142545129 | C11: 呪術廻戦 懐玉・玉折 ブラインド缶バッジ（全5種） | D11: 600 | E11: =①石川予測確定!E11 -> 226 | F11: =①石川予測確定!P11 -> 293 | G11: =①石川予測確定!S11 -> 8790 | H11: =IFERROR(F11/G11,0) -> 0.033333333 | I11: =F11-G11 -> -8497 | J11: =IF(I11>0,"要 追加発注",IF(H11>=0.9,"要注意(90%超)",IF(H11>=0.5,"適正","在庫余剰"))) -> 在庫余剰 | K11: =IF(I11>0,ROUNDUP(I11*(1+前提・入力!$B$34),0),0) -> 0 | L11: =③仙台以降予測!M35 -> 3173 | M11: =③仙台以降予測!V35 -> 39392 | N11: =③仙台以降予測!W35 -> 0 | O11: =L11-M11-N11 -> -36219 | P11: =IF(O11>0,"要 追加生産",IF(L11=0,"—","在庫で充足")) -> 在庫で充足 | Q11: =③仙台以降予測!Z35 -> 0 | R11: =K11+Q11 -> 0 | S11: =R11*D11 -> 0 | T11: — | V11: =IF(OR(U11="",U11="再生産不可"),"",U11-前提・入力!$B$38) | W11: =IF(T11="—","—",IF(U11="再生産不可","×再生産不可",_xlfn.IFS(V11<0,"★期限超過",V11<=30,"★至急(30日以内)",V11<=90,"要着手(90日以内)",TRUE(),"余裕あり"))) -> — | X11: =IF(Y11<>"",IF(FALSE(),"S:現場欠品(追納不可)","S:現場欠品"),IF(I11>0,"A:会期中欠品",IF(O11>1000,"B:大口",IF(O11>0,"C:通常","D:不要")))) -> D:不要 | Z11: =IF(Y11<>"",IF(I11>0,"◎ 一致（モデルも会期中欠品を検知）",IF(H11>=0.7,"○ 整合（予測消化率70%超）","△ モデル未検知：現場報告を優先")),IF(I11>0,"▲ モデルのみ検知：現場に在庫状況を確認","—")) -> — | AA11: 博多会場で完売（実績が在庫上限で頭打ち＝予測は控えめ）
A12: 6 | B12: 4515142545136 | C12: 呪術廻戦 渋谷事変 ブラインド缶バッジ（全9種） | D12: 600 | E12: =①石川予測確定!E12 -> 439 | F12: =①石川予測確定!P12 -> 565 | G12: =①石川予測確定!S12 -> 13249 | H12: =IFERROR(F12/G12,0) -> 0.042644728 | I12: =F12-G12 -> -12684 | J12: =IF(I12>0,"要 追加発注",IF(H12>=0.9,"要注意(90%超)",IF(H12>=0.5,"適正","在庫余剰"))) -> 在庫余剰 | K12: =IF(I12>0,ROUNDUP(I12*(1+前提・入力!$B$34),0),0) -> 0 | L12: =③仙台以降予測!M36 -> 6991 | M12: =③仙台以降予測!V36 -> 50228 | N12: =③仙台以降予測!W36 -> 0 | O12: =L12-M12-N12 -> -43237 | P12: =IF(O12>0,"要 追加生産",IF(L12=0,"—","在庫で充足")) -> 在庫で充足 | Q12: =③仙台以降予測!Z36 -> 0 | R12: =K12+Q12 -> 0 | S12: =R12*D12 -> 0 | T12: — | V12: =IF(OR(U12="",U12="再生産不可"),"",U12-前提・入力!$B$38) | W12: =IF(T12="—","—",IF(U12="再生産不可","×再生産不可",_xlfn.IFS(V12<0,"★期限超過",V12<=30,"★至急(30日以内)",V12<=90,"要着手(90日以内)",TRUE(),"余裕あり"))) -> — | X12: =IF(Y12<>"",IF(FALSE(),"S:現場欠品(追納不可)","S:現場欠品"),IF(I12>0,"A:会期中欠品",IF(O12>1000,"B:大口",IF(O12>0,"C:通常","D:不要")))) -> D:不要 | Z12: =IF(Y12<>"",IF(I12>0,"◎ 一致（モデルも会期中欠品を検知）",IF(H12>=0.7,"○ 整合（予測消化率70%超）","△ モデル未検知：現場報告を優先")),IF(I12>0,"▲ モデルのみ検知：現場に在庫状況を確認","—")) -> — | AA12: 博多会場で完売（実績が在庫上限で頭打ち＝予測は控えめ）
A13: 7 | B13: 4515142545143 | C13: 呪術廻戦 懐玉・玉折 ブラインドダイカットステッカー（全5種） | D13: 600 | E13: =①石川予測確定!E13 -> 130 | F13: =①石川予測確定!P13 -> 165 | G13: =①石川予測確定!S13 -> 463 | H13: =IFERROR(F13/G13,0) -> 0.35637149 | I13: =F13-G13 -> -298 | J13: =IF(I13>0,"要 追加発注",IF(H13>=0.9,"要注意(90%超)",IF(H13>=0.5,"適正","在庫余剰"))) -> 在庫余剰 | K13: =IF(I13>0,ROUNDUP(I13*(1+前提・入力!$B$34),0),0) -> 0 | L13: =③仙台以降予測!M37 -> 1635 | M13: =③仙台以降予測!V37 -> 4249 | N13: =③仙台以降予測!W37 -> 0 | O13: =L13-M13-N13 -> -2614 | P13: =IF(O13>0,"要 追加生産",IF(L13=0,"—","在庫で充足")) -> 在庫で充足 | Q13: =③仙台以降予測!Z37 -> 0 | R13: =K13+Q13 -> 0 | S13: =R13*D13 -> 0 | T13: — | V13: =IF(OR(U13="",U13="再生産不可"),"",U13-前提・入力!$B$38) | W13: =IF(T13="—","—",IF(U13="再生産不可","×再生産不可",_xlfn.IFS(V13<0,"★期限超過",V13<=30,"★至急(30日以内)",V13<=90,"要着手(90日以内)",TRUE(),"余裕あり"))) -> — | X13: =IF(Y13<>"",IF(FALSE(),"S:現場欠品(追納不可)","S:現場欠品"),IF(I13>0,"A:会期中欠品",IF(O13>1000,"B:大口",IF(O13>0,"C:通常","D:不要")))) -> D:不要 | Z13: =IF(Y13<>"",IF(I13>0,"◎ 一致（モデルも会期中欠品を検知）",IF(H13>=0.7,"○ 整合（予測消化率70%超）","△ モデル未検知：現場報告を優先")),IF(I13>0,"▲ モデルのみ検知：現場に在庫状況を確認","—")) -> — | AA13: 博多会場で完売（実績が在庫上限で頭打ち＝予測は控えめ）
A14: 8 | B14: 4515142545150 | C14: 呪術廻戦 渋谷事変 ブラインドダイカットステッカー（全9種） | D14: 600 | E14: =①石川予測確定!E14 -> 207 | F14: =①石川予測確定!P14 -> 266 | G14: =①石川予測確定!S14 -> 778 | H14: =IFERROR(F14/G14,0) -> 0.34190231 | I14: =F14-G14 -> -512 | J14: =IF(I14>0,"要 追加発注",IF(H14>=0.9,"要注意(90%超)",IF(H14>=0.5,"適正","在庫余剰"))) -> 在庫余剰 | K14: =IF(I14>0,ROUNDUP(I14*(1+前提・入力!$B$34),0),0) -> 0 | L14: =③仙台以降予測!M38 -> 2707 | M14: =③仙台以降予測!V38 -> 8034 | N14: =③仙台以降予測!W38 -> 0 | O14: =L14-M14-N14 -> -5327 | P14: =IF(O14>0,"要 追加生産",IF(L14=0,"—","在庫で充足")) -> 在庫で充足 | Q14: =③仙台以降予測!Z38 -> 0 | R14: =K14+Q14 -> 0 | S14: =R14*D14 -> 0 | T14: — | V14: =IF(OR(U14="",U14="再生産不可"),"",U14-前提・入力!$B$38) | W14: =IF(T14="—","—",IF(U14="再生産不可","×再生産不可",_xlfn.IFS(V14<0,"★期限超過",V14<=30,"★至急(30日以内)",V14<=90,"要着手(90日以内)",TRUE(),"余裕あり"))) -> — | X14: =IF(Y14<>"",IF(FALSE(),"S:現場欠品(追納不可)","S:現場欠品"),IF(I14>0,"A:会期中欠品",IF(O14>1000,"B:大口",IF(O14>0,"C:通常","D:不要")))) -> D:不要 | Z14: =IF(Y14<>"",IF(I14>0,"◎ 一致（モデルも会期中欠品を検知）",IF(H14>=0.7,"○ 整合（予測消化率70%超）","△ モデル未検知：現場報告を優先")),IF(I14>0,"▲ モデルのみ検知：現場に在庫状況を確認","—")) -> — | AA14: 博多会場で完売（実績が在庫上限で頭打ち＝予測は控えめ）
A15: 9 | B15: 4515142545372 | C15: 呪術廻戦 懐玉・玉折 クリアファイル（五条 悟） | D15: 600 | E15: =①石川予測確定!E15 -> 41 | F15: =①石川予測確定!P15 -> 51 | G15: =①石川予測確定!S15 -> 740 | H15: =IFERROR(F15/G15,0) -> 0.068918919 | I15: =F15-G15 -> -689 | J15: =IF(I15>0,"要 追加発注",IF(H15>=0.9,"要注意(90%超)",IF(H15>=0.5,"適正","在庫余剰"))) -> 在庫余剰 | K15: =IF(I15>0,ROUNDUP(I15*(1+前提・入力!$B$34),0),0) -> 0 | L15: =③仙台以降予測!M39 -> 860 | M15: =③仙台以降予測!V39 -> 8547 | N15: =③仙台以降予測!W39 -> 0 | O15: =L15-M15-N15 -> -7687 | P15: =IF(O15>0,"要 追加生産",IF(L15=0,"—","在庫で充足")) -> 在庫で充足 | Q15: =③仙台以降予測!Z39 -> 0 | R15: =K15+Q15 -> 0 | S15: =R15*D15 -> 0 | T15: — | V15: =IF(OR(U15="",U15="再生産不可"),"",U15-前提・入力!$B$38) | W15: =IF(T15="—","—",IF(U15="再生産不可","×再生産不可",_xlfn.IFS(V15<0,"★期限超過",V15<=30,"★至急(30日以内)",V15<=90,"要着手(90日以内)",TRUE(),"余裕あり"))) -> — | X15: =IF(Y15<>"",IF(FALSE(),"S:現場欠品(追納不可)","S:現場欠品"),IF(I15>0,"A:会期中欠品",IF(O15>1000,"B:大口",IF(O15>0,"C:通常","D:不要")))) -> D:不要 | Z15: =IF(Y15<>"",IF(I15>0,"◎ 一致（モデルも会期中欠品を検知）",IF(H15>=0.7,"○ 整合（予測消化率70%超）","△ モデル未検知：現場報告を優先")),IF(I15>0,"▲ モデルのみ検知：現場に在庫状況を確認","—")) -> — | AA15: 博多会場で完売（実績が在庫上限で頭打ち＝予測は控えめ）
A16: 10 | B16: 4515142545389 | C16: 呪術廻戦 懐玉・玉折 クリアファイル（夏油 傑） | D16: 600 | E16: =①石川予測確定!E16 -> 16 | F16: =①石川予測確定!P16 -> 20 | G16: =①石川予測確定!S16 -> 541 | H16: =IFERROR(F16/G16,0) -> 0.036968577 | I16: =F16-G16 -> -521 | J16: =IF(I16>0,"要 追加発注",IF(H16>=0.9,"要注意(90%超)",IF(H16>=0.5,"適正","在庫余剰"))) -> 在庫余剰 | K16: =IF(I16>0,ROUNDUP(I16*(1+前提・入力!$B$34),0),0) -> 0 | L16: =③仙台以降予測!M40 -> 324 | M16: =③仙台以降予測!V40 -> 4856 | N16: =③仙台以降予測!W40 -> 0 | O16: =L16-M16-N16 -> -4532 | P16: =IF(O16>0,"要 追加生産",IF(L16=0,"—","在庫で充足")) -> 在庫で充足 | Q16: =③仙台以降予測!Z40 -> 0 | R16: =K16+Q16 -> 0 | S16: =R16*D16 -> 0 | T16: — | V16: =IF(OR(U16="",U16="再生産不可"),"",U16-前提・入力!$B$38) | W16: =IF(T16="—","—",IF(U16="再生産不可","×再生産不可",_xlfn.IFS(V16<0,"★期限超過",V16<=30,"★至急(30日以内)",V16<=90,"要着手(90日以内)",TRUE(),"余裕あり"))) -> — | X16: =IF(Y16<>"",IF(FALSE(),"S:現場欠品(追納不可)","S:現場欠品"),IF(I16>0,"A:会期中欠品",IF(O16>1000,"B:大口",IF(O16>0,"C:通常","D:不要")))) -> D:不要 | Z16: =IF(Y16<>"",IF(I16>0,"◎ 一致（モデルも会期中欠品を検知）",IF(H16>=0.7,"○ 整合（予測消化率70%超）","△ モデル未検知：現場報告を優先")),IF(I16>0,"▲ モデルのみ検知：現場に在庫状況を確認","—")) -> —
A17: 11 | B17: 4515142545396 | C17: 呪術廻戦 懐玉・玉折 クリアファイル（家入 硝子） | D17: 600 | E17: =①石川予測確定!E17 -> 6 | F17: =①石川予測確定!P17 -> 8 | G17: =①石川予測確定!S17 -> 79 | H17: =IFERROR(F17/G17,0) -> 0.10126582 | I17: =F17-G17 -> -71 | J17: =IF(I17>0,"要 追加発注",IF(H17>=0.9,"要注意(90%超)",IF(H17>=0.5,"適正","在庫余剰"))) -> 在庫余剰 | K17: =IF(I17>0,ROUNDUP(I17*(1+前提・入力!$B$34),0),0) -> 0 | L17: =③仙台以降予測!M41 -> 121 | M17: =③仙台以降予測!V41 -> 609 | N17: =③仙台以降予測!W41 -> 0 | O17: =L17-M17-N17 -> -488 | P17: =IF(O17>0,"要 追加生産",IF(L17=0,"—","在庫で充足")) -> 在庫で充足 | Q17: =③仙台以降予測!Z41 -> 0 | R17: =K17+Q17 -> 0 | S17: =R17*D17 -> 0 | T17: — | V17: =IF(OR(U17="",U17="再生産不可"),"",U17-前提・入力!$B$38) | W17: =IF(T17="—","—",IF(U17="再生産不可","×再生産不可",_xlfn.IFS(V17<0,"★期限超過",V17<=30,"★至急(30日以内)",V17<=90,"要着手(90日以内)",TRUE(),"余裕あり"))) -> — | X17: =IF(Y17<>"",IF(FALSE(),"S:現場欠品(追納不可)","S:現場欠品"),IF(I17>0,"A:会期中欠品",IF(O17>1000,"B:大口",IF(O17>0,"C:通常","D:不要")))) -> D:不要 | Z17: =IF(Y17<>"",IF(I17>0,"◎ 一致（モデルも会期中欠品を検知）",IF(H17>=0.7,"○ 整合（予測消化率70%超）","△ モデル未検知：現場報告を優先")),IF(I17>0,"▲ モデルのみ検知：現場に在庫状況を確認","—")) -> — | AA17: 博多会場で完売（実績が在庫上限で頭打ち＝予測は控えめ）
A18: 12 | B18: 4515142545402 | C18: 呪術廻戦 懐玉・玉折 クリアファイル（七海 建人） | D18: 600 | E18: =①石川予測確定!E18 -> 13 | F18: =①石川予測確定!P18 -> 17 | G18: =①石川予測確定!S18 -> 107 | H18: =IFERROR(F18/G18,0) -> 0.1588785 | I18: =F18-G18 -> -90 | J18: =IF(I18>0,"要 追加発注",IF(H18>=0.9,"要注意(90%超)",IF(H18>=0.5,"適正","在庫余剰"))) -> 在庫余剰 | K18: =IF(I18>0,ROUNDUP(I18*(1+前提・入力!$B$34),0),0) -> 0 | L18: =③仙台以降予測!M42 -> 251 | M18: =③仙台以降予測!V42 -> 891 | N18: =③仙台以降予測!W42 -> 0 | O18: =L18-M18-N18 -> -640 | P18: =IF(O18>0,"要 追加生産",IF(L18=0,"—","在庫で充足")) -> 在庫で充足 | Q18: =③仙台以降予測!Z42 -> 0 | R18: =K18+Q18 -> 0 | S18: =R18*D18 -> 0 | T18: — | V18: =IF(OR(U18="",U18="再生産不可"),"",U18-前提・入力!$B$38) | W18: =IF(T18="—","—",IF(U18="再生産不可","×再生産不可",_xlfn.IFS(V18<0,"★期限超過",V18<=30,"★至急(30日以内)",V18<=90,"要着手(90日以内)",TRUE(),"余裕あり"))) -> — | X18: =IF(Y18<>"",IF(FALSE(),"S:現場欠品(追納不可)","S:現場欠品"),IF(I18>0,"A:会期中欠品",IF(O18>1000,"B:大口",IF(O18>0,"C:通常","D:不要")))) -> D:不要 | Z18: =IF(Y18<>"",IF(I18>0,"◎ 一致（モデルも会期中欠品を検知）",IF(H18>=0.7,"○ 整合（予測消化率70%超）","△ モデル未検知：現場報告を優先")),IF(I18>0,"▲ モデルのみ検知：現場に在庫状況を確認","—")) -> —
A19: 13 | B19: 4515142545419 | C19: 呪術廻戦 懐玉・玉折 クリアファイル（灰原 雄） | D19: 600 | E19: =①石川予測確定!E19 -> 5 | F19: =①石川予測確定!P19 -> 6 | G19: =①石川予測確定!S19 -> 52 | H19: =IFERROR(F19/G19,0) -> 0.11538462 | I19: =F19-G19 -> -46 | J19: =IF(I19>0,"要 追加発注",IF(H19>=0.9,"要注意(90%超)",IF(H19>=0.5,"適正","在庫余剰"))) -> 在庫余剰 | K19: =IF(I19>0,ROUNDUP(I19*(1+前提・入力!$B$34),0),0) -> 0 | L19: =③仙台以降予測!M43 -> 64 | M19: =③仙台以降予測!V43 -> 305 | N19: =③仙台以降予測!W43 -> 0 | O19: =L19-M19-N19 -> -241 | P19: =IF(O19>0,"要 追加生産",IF(L19=0,"—","在庫で充足")) -> 在庫で充足 | Q19: =③仙台以降予測!Z43 -> 0 | R19: =K19+Q19 -> 0 | S19: =R19*D19 -> 0 | T19: — | V19: =IF(OR(U19="",U19="再生産不可"),"",U19-前提・入力!$B$38) | W19: =IF(T19="—","—",IF(U19="再生産不可","×再生産不可",_xlfn.IFS(V19<0,"★期限超過",V19<=30,"★至急(30日以内)",V19<=90,"要着手(90日以内)",TRUE(),"余裕あり"))) -> — | X19: =IF(Y19<>"",IF(FALSE(),"S:現場欠品(追納不可)","S:現場欠品"),IF(I19>0,"A:会期中欠品",IF(O19>1000,"B:大口",IF(O19>0,"C:通常","D:不要")))) -> D:不要 | Z19: =IF(Y19<>"",IF(I19>0,"◎ 一致（モデルも会期中欠品を検知）",IF(H19>=0.7,"○ 整合（予測消化率70%超）","△ モデル未検知：現場報告を優先")),IF(I19>0,"▲ モデルのみ検知：現場に在庫状況を確認","—")) -> —
A20: 14 | B20: 4515142545426 | C20: 呪術廻戦 渋谷事変 クリアファイル（虎杖 悠仁） | D20: 600 | E20: =①石川予測確定!E20 -> 10 | F20: =①石川予測確定!P20 -> 14 | G20: =①石川予測確定!S20 -> 53 | H20: =IFERROR(F20/G20,0) -> 0.26415094 | I20: =F20-G20 -> -39 | J20: =IF(I20>0,"要 追加発注",IF(H20>=0.9,"要注意(90%超)",IF(H20>=0.5,"適正","在庫余剰"))) -> 在庫余剰 | K20: =IF(I20>0,ROUNDUP(I20*(1+前提・入力!$B$34),0),0) -> 0 | L20: =③仙台以降予測!M44 -> 246 | M20: =③仙台以降予測!V44 -> 1729 | N20: =③仙台以降予測!W44 -> 0 | O20: =L20-M20-N20 -> -1483 | P20: =IF(O20>0,"要 追加生産",IF(L20=0,"—","在庫で充足")) -> 在庫で充足 | Q20: =③仙台以降予測!Z44 -> 0 | R20: =K20+Q20 -> 0 | S20: =R20*D20 -> 0 | T20: — | V20: =IF(OR(U20="",U20="再生産不可"),"",U20-前提・入力!$B$38) | W20: =IF(T20="—","—",IF(U20="再生産不可","×再生産不可",_xlfn.IFS(V20<0,"★期限超過",V20<=30,"★至急(30日以内)",V20<=90,"要着手(90日以内)",TRUE(),"余裕あり"))) -> — | X20: =IF(Y20<>"",IF(FALSE(),"S:現場欠品(追納不可)","S:現場欠品"),IF(I20>0,"A:会期中欠品",IF(O20>1000,"B:大口",IF(O20>0,"C:通常","D:不要")))) -> D:不要 | Z20: =IF(Y20<>"",IF(I20>0,"◎ 一致（モデルも会期中欠品を検知）",IF(H20>=0.7,"○ 整合（予測消化率70%超）","△ モデル未検知：現場報告を優先")),IF(I20>0,"▲ モデルのみ検知：現場に在庫状況を確認","—")) -> — | AA20: 博多会場で完売（実績が在庫上限で頭打ち＝予測は控えめ）
A21: 15 | B21: 4515142545433 | C21: 呪術廻戦 渋谷事変 クリアファイル（伏黒 恵） | D21: 600 | E21: =①石川予測確定!E21 -> 17 | F21: =①石川予測確定!P21 -> 23 | G21: =①石川予測確定!S21 -> 96 | H21: =IFERROR(F21/G21,0) -> 0.23958333 | I21: =F21-G21 -> -73 | J21: =IF(I21>0,"要 追加発注",IF(H21>=0.9,"要注意(90%超)",IF(H21>=0.5,"適正","在庫余剰"))) -> 在庫余剰 | K21: =IF(I21>0,ROUNDUP(I21*(1+前提・入力!$B$34),0),0) -> 0 | L21: =③仙台以降予測!M45 -> 324 | M21: =③仙台以降予測!V45 -> 2054 | N21: =③仙台以降予測!W45 -> 0 | O21: =L21-M21-N21 -> -1730 | P21: =IF(O21>0,"要 追加生産",IF(L21=0,"—","在庫で充足")) -> 在庫で充足 | Q21: =③仙台以降予測!Z45 -> 0 | R21: =K21+Q21 -> 0 | S21: =R21*D21 -> 0 | T21: — | V21: =IF(OR(U21="",U21="再生産不可"),"",U21-前提・入力!$B$38) | W21: =IF(T21="—","—",IF(U21="再生産不可","×再生産不可",_xlfn.IFS(V21<0,"★期限超過",V21<=30,"★至急(30日以内)",V21<=90,"要着手(90日以内)",TRUE(),"余裕あり"))) -> — | X21: =IF(Y21<>"",IF(FALSE(),"S:現場欠品(追納不可)","S:現場欠品"),IF(I21>0,"A:会期中欠品",IF(O21>1000,"B:大口",IF(O21>0,"C:通常","D:不要")))) -> D:不要 | Z21: =IF(Y21<>"",IF(I21>0,"◎ 一致（モデルも会期中欠品を検知）",IF(H21>=0.7,"○ 整合（予測消化率70%超）","△ モデル未検知：現場報告を優先")),IF(I21>0,"▲ モデルのみ検知：現場に在庫状況を確認","—")) -> — | AA21: 博多会場で完売（実績が在庫上限で頭打ち＝予測は控えめ）
A22: 16 | B22: 4515142545440 | C22: 呪術廻戦 渋谷事変 クリアファイル（釘崎 野薔薇） | D22: 600 | E22: =①石川予測確定!E22 -> 4 | F22: =①石川予測確定!P22 -> 6 | G22: =①石川予測確定!S22 -> 78 | H22: =IFERROR(F22/G22,0) -> 0.076923077 | I22: =F22-G22 -> -72 | J22: =IF(I22>0,"要 追加発注",IF(H22>=0.9,"要注意(90%超)",IF(H22>=0.5,"適正","在庫余剰"))) -> 在庫余剰 | K22: =IF(I22>0,ROUNDUP(I22*(1+前提・入力!$B$34),0),0) -> 0 | L22: =③仙台以降予測!M46 -> 112 | M22: =③仙台以降予測!V46 -> 744 | N22: =③仙台以降予測!W46 -> 0 | O22: =L22-M22-N22 -> -632 | P22: =IF(O22>0,"要 追加生産",IF(L22=0,"—","在庫で充足")) -> 在庫で充足 | Q22: =③仙台以降予測!Z46 -> 0 | R22: =K22+Q22 -> 0 | S22: =R22*D22 -> 0 | T22: — | V22: =IF(OR(U22="",U22="再生産不可"),"",U22-前提・入力!$B$38) | W22: =IF(T22="—","—",IF(U22="再生産不可","×再生産不可",_xlfn.IFS(V22<0,"★期限超過",V22<=30,"★至急(30日以内)",V22<=90,"要着手(90日以内)",TRUE(),"余裕あり"))) -> — | X22: =IF(Y22<>"",IF(FALSE(),"S:現場欠品(追納不可)","S:現場欠品"),IF(I22>0,"A:会期中欠品",IF(O22>1000,"B:大口",IF(O22>0,"C:通常","D:不要")))) -> D:不要 | Z22: =IF(Y22<>"",IF(I22>0,"◎ 一致（モデルも会期中欠品を検知）",IF(H22>=0.7,"○ 整合（予測消化率70%超）","△ モデル未検知：現場報告を優先")),IF(I22>0,"▲ モデルのみ検知：現場に在庫状況を確認","—")) -> — | AA22: 名古屋会場で完売（実績が在庫上限で頭打ち＝予測は控えめ） ／ 博多会場で完売（実績が在庫上限で頭打ち＝予測は控えめ）
A23: 17 | B23: 4515142545457 | C23: 呪術廻戦 渋谷事変 クリアファイル（七海 建人） | D23: 600 | E23: =①石川予測確定!E23 -> 30 | F23: =①石川予測確定!P23 -> 41 | G23: =①石川予測確定!S23 -> 200 | H23: =IFERROR(F23/G23,0) -> 0.205 | I23: =F23-G23 -> -159 | J23: =IF(I23>0,"要 追加発注",IF(H23>=0.9,"要注意(90%超)",IF(H23>=0.5,"適正","在庫余剰"))) -> 在庫余剰 | K23: =IF(I23>0,ROUNDUP(I23*(1+前提・入力!$B$34),0),0) -> 0 | L23: =③仙台以降予測!M47 -> 592 | M23: =③仙台以降予測!V47 -> 2380 | N23: =③仙台以降予測!W47 -> 0 | O23: =L23-M23-N23 -> -1788 | P23: =IF(O23>0,"要 追加生産",IF(L23=0,"—","在庫で充足")) -> 在庫で充足 | Q23: =③仙台以降予測!Z47 -> 0 | R23: =K23+Q23 -> 0 | S23: =R23*D23 -> 0 | T23: — | V23: =IF(OR(U23="",U23="再生産不可"),"",U23-前提・入力!$B$38) | W23: =IF(T23="—","—",IF(U23="再生産不可","×再生産不可",_xlfn.IFS(V23<0,"★期限超過",V23<=30,"★至急(30日以内)",V23<=90,"要着手(90日以内)",TRUE(),"余裕あり"))) -> — | X23: =IF(Y23<>"",IF(FALSE(),"S:現場欠品(追納不可)","S:現場欠品"),IF(I23>0,"A:会期中欠品",IF(O23>1000,"B:大口",IF(O23>0,"C:通常","D:不要")))) -> D:不要 | Z23: =IF(Y23<>"",IF(I23>0,"◎ 一致（モデルも会期中欠品を検知）",IF(H23>=0.7,"○ 整合（予測消化率70%超）","△ モデル未検知：現場報告を優先")),IF(I23>0,"▲ モデルのみ検知：現場に在庫状況を確認","—")) -> — | AA23: 博多会場で完売（実績が在庫上限で頭打ち＝予測は控えめ）
A24: 18 | B24: 4515142545464 | C24: 呪術廻戦 渋谷事変 クリアファイル（五条 悟） | D24: 600 | E24: =①石川予測確定!E24 -> 122 | F24: =①石川予測確定!P24 -> 152 | G24: =①石川予測確定!S24 -> 1157 | H24: =IFERROR(F24/G24,0) -> 0.13137424 | I24: =F24-G24 -> -1005 | J24: =IF(I24>0,"要 追加発注",IF(H24>=0.9,"要注意(90%超)",IF(H24>=0.5,"適正","在庫余剰"))) -> 在庫余剰 | K24: =IF(I24>0,ROUNDUP(I24*(1+前提・入力!$B$34),0),0) -> 0 | L24: =③仙台以降予測!M48 -> 2444 | M24: =③仙台以降予測!V48 -> 9130 | N24: =③仙台以降予測!W48 -> 0 | O24: =L24-M24-N24 -> -6686 | P24: =IF(O24>0,"要 追加生産",IF(L24=0,"—","在庫で充足")) -> 在庫で充足 | Q24: =③仙台以降予測!Z48 -> 0 | R24: =K24+Q24 -> 0 | S24: =R24*D24 -> 0 | T24: — | V24: =IF(OR(U24="",U24="再生産不可"),"",U24-前提・入力!$B$38) | W24: =IF(T24="—","—",IF(U24="再生産不可","×再生産不可",_xlfn.IFS(V24<0,"★期限超過",V24<=30,"★至急(30日以内)",V24<=90,"要着手(90日以内)",TRUE(),"余裕あり"))) -> — | X24: =IF(Y24<>"",IF(FALSE(),"S:現場欠品(追納不可)","S:現場欠品"),IF(I24>0,"A:会期中欠品",IF(O24>1000,"B:大口",IF(O24>0,"C:通常","D:不要")))) -> D:不要 | Z24: =IF(Y24<>"",IF(I24>0,"◎ 一致（モデルも会期中欠品を検知）",IF(H24>=0.7,"○ 整合（予測消化率70%超）","△ モデル未検知：現場報告を優先")),IF(I24>0,"▲ モデルのみ検知：現場に在庫状況を確認","—")) -> — | AA24: 博多会場で完売（実績が在庫上限で頭打ち＝予測は控えめ）
A25: 19 | B25: 4515142545471 | C25: 呪術廻戦 渋谷事変 クリアファイル（夏油 傑） | D25: 600 | E25: =①石川予測確定!E25 -> 4 | F25: =①石川予測確定!P25 -> 5 | G25: =①石川予測確定!S25 -> 129 | H25: =IFERROR(F25/G25,0) -> 0.03875969 | I25: =F25-G25 -> -124 | J25: =IF(I25>0,"要 追加発注",IF(H25>=0.9,"要注意(90%超)",IF(H25>=0.5,"適正","在庫余剰"))) -> 在庫余剰 | K25: =IF(I25>0,ROUNDUP(I25*(1+前提・入力!$B$34),0),0) -> 0 | L25: =③仙台以降予測!M49 -> 103 | M25: =③仙台以降予測!V49 -> 2214 | N25: =③仙台以降予測!W49 -> 0 | O25: =L25-M25-N25 -> -2111 | P25: =IF(O25>0,"要 追加生産",IF(L25=0,"—","在庫で充足")) -> 在庫で充足 | Q25: =③仙台以降予測!Z49 -> 0 | R25: =K25+Q25 -> 0 | S25: =R25*D25 -> 0 | T25: — | V25: =IF(OR(U25="",U25="再生産不可"),"",U25-前提・入力!$B$38) | W25: =IF(T25="—","—",IF(U25="再生産不可","×再生産不可",_xlfn.IFS(V25<0,"★期限超過",V25<=30,"★至急(30日以内)",V25<=90,"要着手(90日以内)",TRUE(),"余裕あり"))) -> — | X25: =IF(Y25<>"",IF(FALSE(),"S:現場欠品(追納不可)","S:現場欠品"),IF(I25>0,"A:会期中欠品",IF(O25>1000,"B:大口",IF(O25>0,"C:通常","D:不要")))) -> D:不要 | Z25: =IF(Y25<>"",IF(I25>0,"◎ 一致（モデルも会期中欠品を検知）",IF(H25>=0.7,"○ 整合（予測消化率70%超）","△ モデル未検知：現場報告を優先")),IF(I25>0,"▲ モデルのみ検知：現場に在庫状況を確認","—")) -> — | AA25: 博多会場で完売（実績が在庫上限で頭打ち＝予測は控えめ）
A26: 20 | B26: 4515142545488 | C26: 呪術廻戦 渋谷事変 クリアファイル（真人） | D26: 600 | E26: =①石川予測確定!E26 -> 5 | F26: =①石川予測確定!P26 -> 7 | G26: =①石川予測確定!S26 -> 17 | H26: =IFERROR(F26/G26,0) -> 0.41176471 | I26: =F26-G26 -> -10 | J26: =IF(I26>0,"要 追加発注",IF(H26>=0.9,"要注意(90%超)",IF(H26>=0.5,"適正","在庫余剰"))) -> 在庫余剰 | K26: =IF(I26>0,ROUNDUP(I26*(1+前提・入力!$B$34),0),0) -> 0 | L26: =③仙台以降予測!M50 -> 104 | M26: =③仙台以降予測!V50 -> 276 | N26: =③仙台以降予測!W50 -> 0 | O26: =L26-M26-N26 -> -172 | P26: =IF(O26>0,"要 追加生産",IF(L26=0,"—","在庫で充足")) -> 在庫で充足 | Q26: =③仙台以降予測!Z50 -> 0 | R26: =K26+Q26 -> 0 | S26: =R26*D26 -> 0 | T26: — | V26: =IF(OR(U26="",U26="再生産不可"),"",U26-前提・入力!$B$38) | W26: =IF(T26="—","—",IF(U26="再生産不可","×再生産不可",_xlfn.IFS(V26<0,"★期限超過",V26<=30,"★至急(30日以内)",V26<=90,"要着手(90日以内)",TRUE(),"余裕あり"))) -> — | X26: =IF(Y26<>"",IF(FALSE(),"S:現場欠品(追納不可)","S:現場欠品"),IF(I26>0,"A:会期中欠品",IF(O26>1000,"B:大口",IF(O26>0,"C:通常","D:不要")))) -> D:不要 | Z26: =IF(Y26<>"",IF(I26>0,"◎ 一致（モデルも会期中欠品を検知）",IF(H26>=0.7,"○ 整合（予測消化率70%超）","△ モデル未検知：現場報告を優先")),IF(I26>0,"▲ モデルのみ検知：現場に在庫状況を確認","—")) -> — | AA26: 博多会場で完売（実績が在庫上限で頭打ち＝予測は控えめ）
A27: 21 | B27: 4515142545495 | C27: 呪術廻戦 渋谷事変 クリアファイル（脹相） | D27: 600 | E27: =①石川予測確定!E27 -> 23 | F27: =①石川予測確定!P27 -> 30 | G27: =①石川予測確定!S27 -> 32 | H27: =IFERROR(F27/G27,0) -> 0.9375 | I27: =F27-G27 -> -2 | J27: =IF(I27>0,"要 追加発注",IF(H27>=0.9,"要注意(90%超)",IF(H27>=0.5,"適正","在庫余剰"))) -> 要注意(90%超) | K27: =IF(I27>0,ROUNDUP(I27*(1+前提・入力!$B$34),0),0) -> 0 | L27: =③仙台以降予測!M51 -> 484 | M27: =③仙台以降予測!V51 -> 190 | N27: =③仙台以降予測!W51 -> 0 | O27: =L27-M27-N27 -> 294 | P27: =IF(O27>0,"要 追加生産",IF(L27=0,"—","在庫で充足")) -> 要 追加生産 | Q27: =③仙台以降予測!Z51 -> 324 | R27: =K27+Q27 -> 324 | S27: =R27*D27 -> 194400 | T27: 鳥取島根 夢みなとタワー | U27: =DATE(2027,3,15)-30-前提・入力!$B$37 -> 46417 | V27: =IF(OR(U27="",U27="再生産不可"),"",U27-前提・入力!$B$38) -> 157 | W27: =IF(T27="—","—",IF(U27="再生産不可","×再生産不可",_xlfn.IFS(V27<0,"★期限超過",V27<=30,"★至急(30日以内)",V27<=90,"要着手(90日以内)",TRUE(),"余裕あり"))) -> 余裕あり | X27: =IF(Y27<>"",IF(FALSE(),"S:現場欠品(追納不可)","S:現場欠品"),IF(I27>0,"A:会期中欠品",IF(O27>1000,"B:大口",IF(O27>0,"C:通常","D:不要")))) -> C:通常 | Z27: =IF(Y27<>"",IF(I27>0,"◎ 一致（モデルも会期中欠品を検知）",IF(H27>=0.7,"○ 整合（予測消化率70%超）","△ モデル未検知：現場報告を優先")),IF(I27>0,"▲ モデルのみ検知：現場に在庫状況を確認","—")) -> — | AA27: 名古屋会場で完売（実績が在庫上限で頭打ち＝予測は控えめ） ／ 博多会場で完売（実績が在庫上限で頭打ち＝予測は控えめ）
