Workbook

Sheet サマリー
A1: アニメーション 呪術廻戦展「懐玉・玉折」「渋谷事変」 札幌会場
A2: レッグス／イベント記念商品 42SKU 商品別 販売構成比 ＆ 追加発注判定レポート
A3: 基準日：2026年7月26日（日）会期5日目終了時点 ／ 作成日：2026年7月28日
A6: ■ 主要結論
A7: 追加発注 要 | B7: 5品目（不足合計 242個 ／ 安全率10%込みの推奨発注合計 268個）
A8: 該当商品 | B8: 前髪ヘアバンド(+78) 宿儺の指風お菓子(+67) 呪術廻戦 渋谷事変 クリアファイル（脹相）(+49) 脱兎！ポーチ入りクリップセット(+45) 気分リフレッシュオルゴール(+3)
A9: 要注意（消化率90%以上見込） | B9: 2品目：呪術廻戦 渋谷事変 クリアファイル（七海 建人） 呪術廻戦 渋谷事変 クリアファイル（宿儺）
A10: 在庫余剰見込（予測消化率50%未満） | B10: 21品目。特にブラインド缶バッジ2種は札幌の構成比が名古屋・博多の1/3〜2/3に留まる
A11: 42SKU計 販売状況 | B11: 7/22-7/26 販売 4,189個 ／ 販売可能数 50,196個 ／ 現在消化率 8.3% ／ 会期20日予測 10,859個・予測消化率 21.6%
A12: 構成比の会場間差（初週） | B12: 札幌はクリアファイル／ポストカード系の構成比が名古屋・博多の約2倍。
B13: 一方でブラインド缶バッジ（懐玉・玉折）は札幌5.9%に対し名古屋18.3%・博多17.6%と大きく下振れ。
B14: ブラインドミニ色紙（懐玉・玉折）は3会場とも22〜25%で最大構成比という点は共通。
A16: ■ 対象・前提
A17: 対象商品 | B17: レッグス／イベント記念商品 42SKU（指定ラインナップのみ。JAN 4515142545082〜545501）
A18: データ出典 | B18: 各会場「レジ通過単品売上」シート（日次販売日報の集計元データ）
A19: 札幌会場（今回） | B19: 2026/7/22(水)〜8/10(月) 全20日間 ／ 日報実績は7/26(日)＝5日目まで
A20: 名古屋会場①（比較） | B20: 2026/3/18(水)〜4/5(日) 全19日間 ／ 日報実績は3/31(火)＝14日目まで
A21: 博多会場②（比較） | B21: 2026/4/23(木)〜5/18(月) 全26日間 ／ 全日実績あり
A22: 「初日」の定義 | B22: 各会場の会期初日1日のみ（札幌7/22・名古屋3/18・博多4/23）
A23: 「初週」の定義 | B23: 初日〜初週の日曜日まで。札幌7/22-7/26(5日)・名古屋3/18-3/22(5日)・博多4/23-4/26(4日)
A24: 構成比の分母 | B24: 上記42SKUの合計販売数（＝42品内シェア）。会場全ラインナップ合計ではない点に注意
A26: ■ 追加発注の予測モデル
A27: 考え方 | B27: 「初5日販売数 × 会期倍率g」で会期20日間の最終販売数を予測し、販売可能数と比較
A28: 会期倍率 g | B28: g＝20日累計販売数÷初5日販売数。名古屋・博多それぞれの実績から算出し平均を採用
A29: 名古屋のg補正 | B29: 名古屋は14日目までしかデータが無いため、15〜20日目分を博多の実績比率で補完
A30: 博多 15-20日目補完率 | B30: 0.45321382
A31: 全体倍率 g（42品計） | B31: 2.689506
A32: 判定基準 | B32: 予測会期累計販売数 ＞ 販売可能数 → 「要 追加発注」／予測消化率90%以上 → 「要注意」
A33: 推奨発注数 | B33: 不足数 × 1.1（安全率10%）を切り上げ
A35: ■ シート構成
A36: ①-1 初日構成比 | B36: 7/22（初日）のみの販売数と構成比率。名古屋①・博多②の初日と比較
A37: ①-2 初週構成比 | B37: 7/26までの累計販売数と構成比率。名古屋①・博多②の初週（初日〜初週日曜）と比較
A38: ①-3 金額構成比 | B38: 販売金額（税込）ベースの構成比率
A39: ②札幌日別明細 | B39: 7/22〜7/26の商品別 日次販売数と日別構成比
A40: ③追加発注判定 | B40: 会期20日間の需要予測と販売可能数の突合、追加発注要否・推奨数量
A41: ④全データ統合リスト | B41: 上記すべての指標を商品別1行にまとめたマスターリスト
A43: ■ 留意事項
A44: 比較会場の売切れ影響 | B44: 名古屋・博多で消化率が高い（≒売切れた）商品は、その会場の後半販売数が在庫制約で
B45: 頭打ちになっているため、算出されるgが過小＝札幌の需要予測も過小になる可能性がある。
B46: ③シートの「比較会場売切れ」列で該当商品を明示している。
...

Sheet ①-1 初日構成比
A1: ① 初日のみ 商品別 販売構成比率（数量ベース）
A2: 札幌 7/22(水) ｜ 名古屋① 3/18(水) ｜ 博多② 4/23(木) ※各会場の会期初日1日のみの販売日報データ
A3: 構成比率＝当該商品の販売数 ÷ 対象42SKU合計販売数
A5: No. | B5: JAN | C5: 商品名 | D5: 税込 単価 | E5: 札幌③ 初日 7/22(水) | H5: 名古屋① 初日 3/18(水) | K5: 博多② 初日 4/23(木) | N5: 構成比 差分（札幌 − 比較会場）
E6: 販売数 | F6: 構成比率 | G6: 順位 | H6: 販売数 | I6: 構成比率 | J6: 順位 | K6: 販売数 | L6: 構成比率 | M6: 順位 | N6: vs 名古屋① | O6: vs 博多②
A7: 1 | B7: 4515142545082 | C7: 呪術廻戦 メタリックポストカード 展示会キービジュアル | D7: 500 | E7: 72 | F7: =IFERROR(E7/E$49,0) -> 0.04040404 | G7: =IF(E7=0,"-",RANK(E7,E$7:E$48)) -> 6 | H7: 159 | I7: =IFERROR(H7/H$49,0) -> 0.025579151 | J7: =IF(H7=0,"-",RANK(H7,H$7:H$48)) -> 8 | K7: 107 | L7: =IFERROR(K7/K$49,0) -> 0.027893639 | M7: =IF(K7=0,"-",RANK(K7,K$7:K$48)) -> 6 | N7: =F7-I7 -> 0.01482489 | O7: =F7-L7 -> 0.012510401
A8: 2 | B8: 4515142545099 | C8: 呪術廻戦 クリアファイル 展示会キービジュアル | D8: 600 | E8: 66 | F8: =IFERROR(E8/E$49,0) -> 0.037037037 | G8: =IF(E8=0,"-",RANK(E8,E$7:E$48)) -> 7 | H8: 154 | I8: =IFERROR(H8/H$49,0) -> 0.024774775 | J8: =IF(H8=0,"-",RANK(H8,H$7:H$48)) -> 9 | K8: 88 | L8: =IFERROR(K8/K$49,0) -> 0.022940563 | M8: =IF(K8=0,"-",RANK(K8,K$7:K$48)) -> 7 | N8: =F8-I8 -> 0.012262262 | O8: =F8-L8 -> 0.014096474
A9: 3 | B9: 4515142545105 | C9: 呪術廻戦 懐玉・玉折 ポストカードセット（5枚入） | D9: 1000 | E9: 39 | F9: =IFERROR(E9/E$49,0) -> 0.021885522 | G9: =IF(E9=0,"-",RANK(E9,E$7:E$48)) -> 9 | H9: 103 | I9: =IFERROR(H9/H$49,0) -> 0.016570142 | J9: =IF(H9=0,"-",RANK(H9,H$7:H$48)) -> 11 | K9: 42 | L9: =IFERROR(K9/K$49,0) -> 0.010948905 | M9: =IF(K9=0,"-",RANK(K9,K$7:K$48)) -> 13 | N9: =F9-I9 -> 0.0053153803 | O9: =F9-L9 -> 0.010936617
A10: 4 | B10: 4515142545112 | C10: 呪術廻戦 渋谷事変 ポストカードセット（9枚入） | D10: 1800 | E10: 52 | F10: =IFERROR(E10/E$49,0) -> 0.029180696 | G10: =IF(E10=0,"-",RANK(E10,E$7:E$48)) -> 8 | H10: 196 | I10: =IFERROR(H10/H$49,0) -> 0.031531532 | J10: =IF(H10=0,"-",RANK(H10,H$7:H$48)) -> 6 | K10: 66 | L10: =IFERROR(K10/K$49,0) -> 0.017205422 | M10: =IF(K10=0,"-",RANK(K10,K$7:K$48)) -> 11 | N10: =F10-I10 -> -0.0023508357 | O10: =F10-L10 -> 0.011975274
A11: 5 | B11: 4515142545129 | C11: 呪術廻戦 懐玉・玉折 ブラインド缶バッジ（全5種） | D11: 600 | E11: 174 | F11: =IFERROR(E11/E$49,0) -> 0.097643098 | G11: =IF(E11=0,"-",RANK(E11,E$7:E$48)) -> 4 | H11: 1089 | I11: =IFERROR(H11/H$49,0) -> 0.17519305 | J11: =IF(H11=0,"-",RANK(H11,H$7:H$48)) -> 3 | K11: 618 | L11: =IFERROR(K11/K$49,0) -> 0.16110532 | M11: =IF(K11=0,"-",RANK(K11,K$7:K$48)) -> 3 | N11: =F11-I11 -> -0.077549953 | O11: =F11-L11 -> -0.06346222
A12: 6 | B12: 4515142545136 | C12: 呪術廻戦 渋谷事変 ブラインド缶バッジ（全9種） | D12: 600 | E12: 407 | F12: =IFERROR(E12/E$49,0) -> 0.22839506 | G12: =IF(E12=0,"-",RANK(E12,E$7:E$48)) -> 1 | H12: 1543 | I12: =IFERROR(H12/H$49,0) -> 0.24823037 | J12: =IF(H12=0,"-",RANK(H12,H$7:H$48)) -> 1 | K12: 942 | L12: =IFERROR(K12/K$49,0) -> 0.2455683 | M12: =IF(K12=0,"-",RANK(K12,K$7:K$48)) -> 1 | N12: =F12-I12 -> -0.019835312 | O12: =F12-L12 -> -0.017173239
A13: 7 | B13: 4515142545143 | C13: 呪術廻戦 懐玉・玉折 ブラインドダイカットステッカー（全5種） | D13: 600 | E13: 28 | F13: =IFERROR(E13/E$49,0) -> 0.015712682 | G13: =IF(E13=0,"-",RANK(E13,E$7:E$48)) -> 12 | H13: 70 | I13: =IFERROR(H13/H$49,0) -> 0.011261261 | J13: =IF(H13=0,"-",RANK(H13,H$7:H$48)) -> 13 | K13: 72 | L13: =IFERROR(K13/K$49,0) -> 0.018769552 | M13: =IF(K13=0,"-",RANK(K13,K$7:K$48)) -> 10 | N13: =F13-I13 -> 0.0044514211 | O13: =F13-L13 -> -0.0030568692
A14: 8 | B14: 4515142545150 | C14: 呪術廻戦 渋谷事変 ブラインドダイカットステッカー（全9種） | D14: 600 | E14: 39 | F14: =IFERROR(E14/E$49,0) -> 0.021885522 | G14: =IF(E14=0,"-",RANK(E14,E$7:E$48)) -> 9 | H14: 106 | I14: =IFERROR(H14/H$49,0) -> 0.017052767 | J14: =IF(H14=0,"-",RANK(H14,H$7:H$48)) -> 10 | K14: 82 | L14: =IFERROR(K14/K$49,0) -> 0.021376434 | M14: =IF(K14=0,"-",RANK(K14,K$7:K$48)) -> 9 | N14: =F14-I14 -> 0.0048327548 | O14: =F14-L14 -> 0.0005090881
A15: 9 | B15: 4515142545372 | C15: 呪術廻戦 懐玉・玉折 クリアファイル（五条 悟） | D15: 600 | E15: 28 | F15: =IFERROR(E15/E$49,0) -> 0.015712682 | G15: =IF(E15=0,"-",RANK(E15,E$7:E$48)) -> 12 | H15: 73 | I15: =IFERROR(H15/H$49,0) -> 0.011743887 | J15: =IF(H15=0,"-",RANK(H15,H$7:H$48)) -> 12 | K15: 50 | L15: =IFERROR(K15/K$49,0) -> 0.013034411 | M15: =IF(K15=0,"-",RANK(K15,K$7:K$48)) -> 12 | N15: =F15-I15 -> 0.0039687956 | O15: =F15-L15 -> 0.0026782715
A16: 10 | B16: 4515142545389 | C16: 呪術廻戦 懐玉・玉折 クリアファイル（夏油 傑） | D16: 600 | E16: 18 | F16: =IFERROR(E16/E$49,0) -> 0.01010101 | G16: =IF(E16=0,"-",RANK(E16,E$7:E$48)) -> 16 | H16: 24 | I16: =IFERROR(H16/H$49,0) -> 0.0038610039 | J16: =IF(H16=0,"-",RANK(H16,H$7:H$48)) -> 18 | K16: 28 | L16: =IFERROR(K16/K$49,0) -> 0.0072992701 | M16: =IF(K16=0,"-",RANK(K16,K$7:K$48)) -> 16 | N16: =F16-I16 -> 0.0062400062 | O16: =F16-L16 -> 0.00280174
A17: 11 | B17: 4515142545396 | C17: 呪術廻戦 懐玉・玉折 クリアファイル（家入 硝子） | D17: 600 | E17: 0 | F17: =IFERROR(E17/E$49,0) -> 0 | G17: =IF(E17=0,"-",RANK(E17,E$7:E$48)) -> - | H17: 2 | I17: =IFERROR(H17/H$49,0) -> 0.00032175032 | J17: =IF(H17=0,"-",RANK(H17,H$7:H$48)) -> 36 | K17: 4 | L17: =IFERROR(K17/K$49,0) -> 0.0010427529 | M17: =IF(K17=0,"-",RANK(K17,K$7:K$48)) -> 27 | N17: =F17-I17 -> -0.00032175032 | O17: =F17-L17 -> -0.0010427529
A18: 12 | B18: 4515142545402 | C18: 呪術廻戦 懐玉・玉折 クリアファイル（七海 建人） | D18: 600 | E18: 1 | F18: =IFERROR(E18/E$49,0) -> 0.00056116723 | G18: =IF(E18=0,"-",RANK(E18,E$7:E$48)) -> 30 | H18: 9 | I18: =IFERROR(H18/H$49,0) -> 0.0014478764 | J18: =IF(H18=0,"-",RANK(H18,H$7:H$48)) -> 27 | K18: 6 | L18: =IFERROR(K18/K$49,0) -> 0.0015641293 | M18: =IF(K18=0,"-",RANK(K18,K$7:K$48)) -> 24 | N18: =F18-I18 -> -0.00088670922 | O18: =F18-L18 -> -0.0010029621
... A48: 42 | B48: 4515142545365 | C48: 伏黒 恵 イメージフラグメントケース | D48: 25000 | E48: 0 | F48: =IFERROR(E48/E$49,0) -> 0 | G48: =IF(E48=0,"-",RANK(E48,E$7:E$48)) -> - | H48: 2 | I48: =IFERROR(H48/H$49,0) -> 0.00032175032 | J48: =IF(H48=0,"-",RANK(H48,H$7:H$48)) -> 36 | K48: 1 | L48: =IFERROR(K48/K$49,0) -> 0.00026068822 | M48: =IF(K48=0,"-",RANK(K48,K$7:K$48)) -> 35 | N48: =F48-I48 -> -0.00032175032 | O48: =F48-L48 -> -0.00026068822
C49: 合計（対象42SKU） | E49: =SUM(E7:E48) -> 1782 | F49: =IFERROR(E49/E49,0) -> 1 | H49: =SUM(H7:H48) -> 6216 | I49: =IFERROR(H49/H49,0) -> 1 | K49: =SUM(K7:K48) -> 3836 | L49: =IFERROR(K49/K49,0) -> 1

Sheet ①-2 初週構成比
A1: ① 初日〜初週日曜まで累計 商品別 販売構成比率（数量ベース）
A2: 札幌 7/22-7/26(5日) ｜ 名古屋① 3/18-3/22(5日) ｜ 博多② 4/23-4/26(4日) ※各会場「初日〜初週の日曜日」までの累計
A3: 構成比率＝当該商品の販売数 ÷ 対象42SKU合計販売数
A5: No. | B5: JAN | C5: 商品名 | D5: 税込 単価 | E5: 札幌③ 7/22-7/26 (5日) | H5: 名古屋① 3/18-3/22 (5日) | K5: 博多② 4/23-4/26 (4日) | N5: 構成比 差分（札幌 − 比較会場）
E6: 販売数 | F6: 構成比率 | G6: 順位 | H6: 販売数 | I6: 構成比率 | J6: 順位 | K6: 販売数 | L6: 構成比率 | M6: 順位 | N6: vs 名古屋① | O6: vs 博多②
A7: 1 | B7: 4515142545082 | C7: 呪術廻戦 メタリックポストカード 展示会キービジュアル | D7: 500 | E7: 205 | F7: =IFERROR(E7/E$49,0) -> 0.048937694 | G7: =IF(E7=0,"-",RANK(E7,E$7:E$48)) -> 7 | H7: 605 | I7: =IFERROR(H7/H$49,0) -> 0.021817526 | J7: =IF(H7=0,"-",RANK(H7,H$7:H$48)) -> 7 | K7: 361 | L7: =IFERROR(K7/K$49,0) -> 0.033043478 | M7: =IF(K7=0,"-",RANK(K7,K$7:K$48)) -> 5 | N7: =F7-I7 -> 0.027120168 | O7: =F7-L7 -> 0.015894216
A8: 2 | B8: 4515142545099 | C8: 呪術廻戦 クリアファイル 展示会キービジュアル | D8: 600 | E8: 233 | F8: =IFERROR(E8/E$49,0) -> 0.055621867 | G8: =IF(E8=0,"-",RANK(E8,E$7:E$48)) -> 5 | H8: 616 | I8: =IFERROR(H8/H$49,0) -> 0.022214208 | J8: =IF(H8=0,"-",RANK(H8,H$7:H$48)) -> 6 | K8: 307 | L8: =IFERROR(K8/K$49,0) -> 0.028100686 | M8: =IF(K8=0,"-",RANK(K8,K$7:K$48)) -> 7 | N8: =F8-I8 -> 0.033407658 | O8: =F8-L8 -> 0.02752118
A9: 3 | B9: 4515142545105 | C9: 呪術廻戦 懐玉・玉折 ポストカードセット（5枚入） | D9: 1000 | E9: 84 | F9: =IFERROR(E9/E$49,0) -> 0.020052519 | G9: =IF(E9=0,"-",RANK(E9,E$7:E$48)) -> 12 | H9: 349 | I9: =IFERROR(H9/H$49,0) -> 0.012585647 | J9: =IF(H9=0,"-",RANK(H9,H$7:H$48)) -> 11 | K9: 141 | L9: =IFERROR(K9/K$49,0) -> 0.012906178 | M9: =IF(K9=0,"-",RANK(K9,K$7:K$48)) -> 12 | N9: =F9-I9 -> 0.0074668712 | O9: =F9-L9 -> 0.00714634
A10: 4 | B10: 4515142545112 | C10: 呪術廻戦 渋谷事変 ポストカードセット（9枚入） | D10: 1800 | E10: 122 | F10: =IFERROR(E10/E$49,0) -> 0.029123896 | G10: =IF(E10=0,"-",RANK(E10,E$7:E$48)) -> 10 | H10: 553 | I10: =IFERROR(H10/H$49,0) -> 0.019942301 | J10: =IF(H10=0,"-",RANK(H10,H$7:H$48)) -> 8 | K10: 188 | L10: =IFERROR(K10/K$49,0) -> 0.017208238 | M10: =IF(K10=0,"-",RANK(K10,K$7:K$48)) -> 9 | N10: =F10-I10 -> 0.0091815952 | O10: =F10-L10 -> 0.011915658
A11: 5 | B11: 4515142545129 | C11: 呪術廻戦 懐玉・玉折 ブラインド缶バッジ（全5種） | D11: 600 | E11: 247 | F11: =IFERROR(E11/E$49,0) -> 0.058963953 | G11: =IF(E11=0,"-",RANK(E11,E$7:E$48)) -> 4 | H11: 5070 | I11: =IFERROR(H11/H$49,0) -> 0.18283448 | J11: =IF(H11=0,"-",RANK(H11,H$7:H$48)) -> 3 | K11: 1927 | L11: =IFERROR(K11/K$49,0) -> 0.17638444 | M11: =IF(K11=0,"-",RANK(K11,K$7:K$48)) -> 3 | N11: =F11-I11 -> -0.12387052 | O11: =F11-L11 -> -0.11742049
A12: 6 | B12: 4515142545136 | C12: 呪術廻戦 渋谷事変 ブラインド缶バッジ（全9種） | D12: 600 | E12: 616 | F12: =IFERROR(E12/E$49,0) -> 0.1470518 | G12: =IF(E12=0,"-",RANK(E12,E$7:E$48)) -> 2 | H12: 6714 | I12: =IFERROR(H12/H$49,0) -> 0.24212045 | J12: =IF(H12=0,"-",RANK(H12,H$7:H$48)) -> 1 | K12: 2531 | L12: =IFERROR(K12/K$49,0) -> 0.23167048 | M12: =IF(K12=0,"-",RANK(K12,K$7:K$48)) -> 1 | N12: =F12-I12 -> -0.095068645 | O12: =F12-L12 -> -0.084618678
A13: 7 | B13: 4515142545143 | C13: 呪術廻戦 懐玉・玉折 ブラインドダイカットステッカー（全5種） | D13: 600 | E13: 79 | F13: =IFERROR(E13/E$49,0) -> 0.018858916 | G13: =IF(E13=0,"-",RANK(E13,E$7:E$48)) -> 13 | H13: 209 | I13: =IFERROR(H13/H$49,0) -> 0.0075369636 | J13: =IF(H13=0,"-",RANK(H13,H$7:H$48)) -> 14 | K13: 133 | L13: =IFERROR(K13/K$49,0) -> 0.012173913 | M13: =IF(K13=0,"-",RANK(K13,K$7:K$48)) -> 13 | N13: =F13-I13 -> 0.011321953 | O13: =F13-L13 -> 0.0066850032
A14: 8 | B14: 4515142545150 | C14: 呪術廻戦 渋谷事変 ブラインドダイカットステッカー（全9種） | D14: 600 | E14: 135 | F14: =IFERROR(E14/E$49,0) -> 0.032227262 | G14: =IF(E14=0,"-",RANK(E14,E$7:E$48)) -> 8 | H14: 432 | I14: =IFERROR(H14/H$49,0) -> 0.015578796 | J14: =IF(H14=0,"-",RANK(H14,H$7:H$48)) -> 9 | K14: 201 | L14: =IFERROR(K14/K$49,0) -> 0.018398169 | M14: =IF(K14=0,"-",RANK(K14,K$7:K$48)) -> 8 | N14: =F14-I14 -> 0.016648466 | O14: =F14-L14 -> 0.013829093
A15: 9 | B15: 4515142545372 | C15: 呪術廻戦 懐玉・玉折 クリアファイル（五条 悟） | D15: 600 | E15: 75 | F15: =IFERROR(E15/E$49,0) -> 0.017904034 | G15: =IF(E15=0,"-",RANK(E15,E$7:E$48)) -> 14 | H15: 197 | I15: =IFERROR(H15/H$49,0) -> 0.0071042193 | J15: =IF(H15=0,"-",RANK(H15,H$7:H$48)) -> 15 | K15: 127 | L15: =IFERROR(K15/K$49,0) -> 0.011624714 | M15: =IF(K15=0,"-",RANK(K15,K$7:K$48)) -> 14 | N15: =F15-I15 -> 0.010799815 | O15: =F15-L15 -> 0.0062793204
A16: 10 | B16: 4515142545389 | C16: 呪術廻戦 懐玉・玉折 クリアファイル（夏油 傑） | D16: 600 | E16: 30 | F16: =IFERROR(E16/E$49,0) -> 0.0071616138 | G16: =IF(E16=0,"-",RANK(E16,E$7:E$48)) -> 19 | H16: 78 | I16: =IFERROR(H16/H$49,0) -> 0.0028128381 | J16: =IF(H16=0,"-",RANK(H16,H$7:H$48)) -> 18 | K16: 61 | L16: =IFERROR(K16/K$49,0) -> 0.005583524 | M16: =IF(K16=0,"-",RANK(K16,K$7:K$48)) -> 17 | N16: =F16-I16 -> 0.0043487757 | O16: =F16-L16 -> 0.0015780897
A17: 11 | B17: 4515142545396 | C17: 呪術廻戦 懐玉・玉折 クリアファイル（家入 硝子） | D17: 600 | E17: 8 | F17: =IFERROR(E17/E$49,0) -> 0.0019097637 | G17: =IF(E17=0,"-",RANK(E17,E$7:E$48)) -> 28 | H17: 8 | I17: =IFERROR(H17/H$49,0) -> 0.00028849621 | J17: =IF(H17=0,"-",RANK(H17,H$7:H$48)) -> 33 | K17: 10 | L17: =IFERROR(K17/K$49,0) -> 0.00091533181 | M17: =IF(K17=0,"-",RANK(K17,K$7:K$48)) -> 28 | N17: =F17-I17 -> 0.0016212675 | O17: =F17-L17 -> 0.00099443186
A18: 12 | B18: 4515142545402 | C18: 呪術廻戦 懐玉・玉折 クリアファイル（七海 建人） | D18: 600 | E18: 12 | F18: =IFERROR(E18/E$49,0) -> 0.0028646455 | G18: =IF(E18=0,"-",RANK(E18,E$7:E$48)) -> 26 | H18: 33 | I18: =IFERROR(H18/H$49,0) -> 0.0011900469 | J18: =IF(H18=0,"-",RANK(H18,H$7:H$48)) -> 26 | K18: 13 | L18: =IFERROR(K18/K$49,0) -> 0.0011899314 | M18: =IF(K18=0,"-",RANK(K18,K$7:K$48)) -> 27 | N18: =F18-I18 -> 0.0016745986 | O18: =F18-L18 -> 0.0016747142
... A48: 42 | B48: 4515142545365 | C48: 伏黒 恵 イメージフラグメントケース | D48: 25000 | E48: 1 | F48: =IFERROR(E48/E$49,0) -> 0.00023872046 | G48: =IF(E48=0,"-",RANK(E48,E$7:E$48)) -> 33 | H48: 3 | I48: =IFERROR(H48/H$49,0) -> 0.00010818608 | J48: =IF(H48=0,"-",RANK(H48,H$7:H$48)) -> 36 | K48: 1 | L48: =IFERROR(K48/K$49,0) -> 9.1533181e-05 | M48: =IF(K48=0,"-",RANK(K48,K$7:K$48)) -> 40 | N48: =F48-I48 -> 0.00013053438 | O48: =F48-L48 -> 0.00014718728
C49: 合計（対象42SKU） | E49: =SUM(E7:E48) -> 4189 | F49: =IFERROR(E49/E49,0) -> 1 | H49: =SUM(H7:H48) -> 27730 | I49: =IFERROR(H49/H49,0) -> 1 | K49: =SUM(K7:K48) -> 10925 | L49: =IFERROR(K49/K49,0) -> 1

Sheet ①-3 金額構成比
A1: ① 初週累計 商品別 販売金額構成比率（税込金額ベース）
A2: 札幌 7/22-7/26(5日) ｜ 名古屋① 3/18-3/22(5日) ｜ 博多② 4/23-4/26(4日) ※販売数×税込単価で算出
A3: 構成比率＝当該商品の販売金額 ÷ 対象42SKU合計販売金額
A5: No. | B5: JAN | C5: 商品名 | D5: 税込 単価 | E5: 札幌③ 7/22-7/26 (5日) | H5: 名古屋① 3/18-3/22 (5日) | K5: 博多② 4/23-4/26 (4日) | N5: 構成比 差分（札幌 − 比較会場）
E6: 販売金額 | F6: 構成比率 | G6: 順位 | H6: 販売金額 | I6: 構成比率 | J6: 順位 | K6: 販売金額 | L6: 構成比率 | M6: 順位 | N6: vs 名古屋① | O6: vs 博多②
A7: 1 | B7: 4515142545082 | C7: 呪術廻戦 メタリックポストカード 展示会キービジュアル | D7: 500 | E7: 102500 | F7: =IFERROR(E7/E$49,0) -> 0.030880935 | G7: =IF(E7=0,"-",RANK(E7,E$7:E$48)) -> 10 | H7: 302500 | I7: =IFERROR(H7/H$49,0) -> 0.014461575 | J7: =IF(H7=0,"-",RANK(H7,H$7:H$48)) -> 14 | K7: 180500 | L7: =IFERROR(K7/K$49,0) -> 0.021844895 | M7: =IF(K7=0,"-",RANK(K7,K$7:K$48)) -> 11 | N7: =F7-I7 -> 0.01641936 | O7: =F7-L7 -> 0.00903604
A8: 2 | B8: 4515142545099 | C8: 呪術廻戦 クリアファイル 展示会キービジュアル | D8: 600 | E8: 139800 | F8: =IFERROR(E8/E$49,0) -> 0.042118583 | G8: =IF(E8=0,"-",RANK(E8,E$7:E$48)) -> 8 | H8: 369600 | I8: =IFERROR(H8/H$49,0) -> 0.017669416 | J8: =IF(H8=0,"-",RANK(H8,H$7:H$48)) -> 10 | K8: 184200 | L8: =IFERROR(K8/K$49,0) -> 0.022292685 | M8: =IF(K8=0,"-",RANK(K8,K$7:K$48)) -> 10 | N8: =F8-I8 -> 0.024449167 | O8: =F8-L8 -> 0.019825898
A9: 3 | B9: 4515142545105 | C9: 呪術廻戦 懐玉・玉折 ポストカードセット（5枚入） | D9: 1000 | E9: 84000 | F9: =IFERROR(E9/E$49,0) -> 0.025307303 | G9: =IF(E9=0,"-",RANK(E9,E$7:E$48)) -> 13 | H9: 349000 | I9: =IFERROR(H9/H$49,0) -> 0.016684594 | J9: =IF(H9=0,"-",RANK(H9,H$7:H$48)) -> 12 | K9: 141000 | L9: =IFERROR(K9/K$49,0) -> 0.017064433 | M9: =IF(K9=0,"-",RANK(K9,K$7:K$48)) -> 12 | N9: =F9-I9 -> 0.0086227087 | O9: =F9-L9 -> 0.0082428696
A10: 4 | B10: 4515142545112 | C10: 呪術廻戦 渋谷事変 ポストカードセット（9枚入） | D10: 1800 | E10: 219600 | F10: =IFERROR(E10/E$49,0) -> 0.066160521 | G10: =IF(E10=0,"-",RANK(E10,E$7:E$48)) -> 5 | H10: 995400 | I10: =IFERROR(H10/H$49,0) -> 0.047586949 | J10: =IF(H10=0,"-",RANK(H10,H$7:H$48)) -> 5 | K10: 338400 | L10: =IFERROR(K10/K$49,0) -> 0.04095464 | M10: =IF(K10=0,"-",RANK(K10,K$7:K$48)) -> 5 | N10: =F10-I10 -> 0.018573572 | O10: =F10-L10 -> 0.025205881
A11: 5 | B11: 4515142545129 | C11: 呪術廻戦 懐玉・玉折 ブラインド缶バッジ（全5種） | D11: 600 | E11: 148200 | F11: =IFERROR(E11/E$49,0) -> 0.044649313 | G11: =IF(E11=0,"-",RANK(E11,E$7:E$48)) -> 7 | H11: 3042000 | I11: =IFERROR(H11/H$49,0) -> 0.14542847 | J11: =IF(H11=0,"-",RANK(H11,H$7:H$48)) -> 3 | K11: 1156200 | L11: =IFERROR(K11/K$49,0) -> 0.13992835 | M11: =IF(K11=0,"-",RANK(K11,K$7:K$48)) -> 3 | N11: =F11-I11 -> -0.10077916 | O11: =F11-L11 -> -0.09527904
A12: 6 | B12: 4515142545136 | C12: 呪術廻戦 渋谷事変 ブラインド缶バッジ（全9種） | D12: 600 | E12: 369600 | F12: =IFERROR(E12/E$49,0) -> 0.11135213 | G12: =IF(E12=0,"-",RANK(E12,E$7:E$48)) -> 2 | H12: 4028400 | I12: =IFERROR(H12/H$49,0) -> 0.19258516 | J12: =IF(H12=0,"-",RANK(H12,H$7:H$48)) -> 1 | K12: 1518600 | L12: =IFERROR(K12/K$49,0) -> 0.18378758 | M12: =IF(K12=0,"-",RANK(K12,K$7:K$48)) -> 1 | N12: =F12-I12 -> -0.081233023 | O12: =F12-L12 -> -0.072435445
A13: 7 | B13: 4515142545143 | C13: 呪術廻戦 懐玉・玉折 ブラインドダイカットステッカー（全5種） | D13: 600 | E13: 47400 | F13: =IFERROR(E13/E$49,0) -> 0.01428055 | G13: =IF(E13=0,"-",RANK(E13,E$7:E$48)) -> 17 | H13: 125400 | I13: =IFERROR(H13/H$49,0) -> 0.0059949803 | J13: =IF(H13=0,"-",RANK(H13,H$7:H$48)) -> 20 | K13: 79800 | L13: =IFERROR(K13/K$49,0) -> 0.0096577431 | M13: =IF(K13=0,"-",RANK(K13,K$7:K$48)) -> 20 | N13: =F13-I13 -> 0.0082855693 | O13: =F13-L13 -> 0.0046228064
A14: 8 | B14: 4515142545150 | C14: 呪術廻戦 渋谷事変 ブラインドダイカットステッカー（全9種） | D14: 600 | E14: 81000 | F14: =IFERROR(E14/E$49,0) -> 0.024403471 | G14: =IF(E14=0,"-",RANK(E14,E$7:E$48)) -> 14 | H14: 259200 | I14: =IFERROR(H14/H$49,0) -> 0.012391538 | J14: =IF(H14=0,"-",RANK(H14,H$7:H$48)) -> 16 | K14: 120600 | L14: =IFERROR(K14/K$49,0) -> 0.014595537 | M14: =IF(K14=0,"-",RANK(K14,K$7:K$48)) -> 14 | N14: =F14-I14 -> 0.012011933 | O14: =F14-L14 -> 0.0098079341
A15: 9 | B15: 4515142545372 | C15: 呪術廻戦 懐玉・玉折 クリアファイル（五条 悟） | D15: 600 | E15: 45000 | F15: =IFERROR(E15/E$49,0) -> 0.013557484 | G15: =IF(E15=0,"-",RANK(E15,E$7:E$48)) -> 18 | H15: 118200 | I15: =IFERROR(H15/H$49,0) -> 0.0056507709 | J15: =IF(H15=0,"-",RANK(H15,H$7:H$48)) -> 21 | K15: 76200 | L15: =IFERROR(K15/K$49,0) -> 0.0092220555 | M15: =IF(K15=0,"-",RANK(K15,K$7:K$48)) -> 22 | N15: =F15-I15 -> 0.0079067128 | O15: =F15-L15 -> 0.0043354283
A16: 10 | B16: 4515142545389 | C16: 呪術廻戦 懐玉・玉折 クリアファイル（夏油 傑） | D16: 600 | E16: 18000 | F16: =IFERROR(E16/E$49,0) -> 0.0054229935 | G16: =IF(E16=0,"-",RANK(E16,E$7:E$48)) -> 26 | H16: 46800 | I16: =IFERROR(H16/H$49,0) -> 0.0022373611 | J16: =IF(H16=0,"-",RANK(H16,H$7:H$48)) -> 30 | K16: 36600 | L16: =IFERROR(K16/K$49,0) -> 0.0044294912 | M16: =IF(K16=0,"-",RANK(K16,K$7:K$48)) -> 27 | N16: =F16-I16 -> 0.0031856324 | O16: =F16-L16 -> 0.00099350228
A17: 11 | B17: 4515142545396 | C17: 呪術廻戦 懐玉・玉折 クリアファイル（家入 硝子） | D17: 600 | E17: 4800 | F17: =IFERROR(E17/E$49,0) -> 0.0014461316 | G17: =IF(E17=0,"-",RANK(E17,E$7:E$48)) -> 32 | H17: 4800 | I17: =IFERROR(H17/H$49,0) -> 0.00022947293 | J17: =IF(H17=0,"-",RANK(H17,H$7:H$48)) -> 41 | K17: 6000 | L17: =IFERROR(K17/K$49,0) -> 0.0007261461 | M17: =IF(K17=0,"-",RANK(K17,K$7:K$48)) -> 38 | N17: =F17-I17 -> 0.0012166587 | O17: =F17-L17 -> 0.0007199855
A18: 12 | B18: 4515142545402 | C18: 呪術廻戦 懐玉・玉折 クリアファイル（七海 建人） | D18: 600 | E18: 7200 | F18: =IFERROR(E18/E$49,0) -> 0.0021691974 | G18: =IF(E18=0,"-",RANK(E18,E$7:E$48)) -> 31 | H18: 19800 | I18: =IFERROR(H18/H$49,0) -> 0.00094657583 | J18: =IF(H18=0,"-",RANK(H18,H$7:H$48)) -> 37 | K18: 7800 | L18: =IFERROR(K18/K$49,0) -> 0.00094398993 | M18: =IF(K18=0,"-",RANK(K18,K$7:K$48)) -> 37 | N18: =F18-I18 -> 0.0012226216 | O18: =F18-L18 -> 0.0012252075
... A48: 42 | B48: 4515142545365 | C48: 伏黒 恵 イメージフラグメントケース | D48: 25000 | E48: 25000 | F48: =IFERROR(E48/E$49,0) -> 0.0075319354 | G48: =IF(E48=0,"-",RANK(E48,E$7:E$48)) -> 23 | H48: 75000 | I48: =IFERROR(H48/H$49,0) -> 0.0035855145 | J48: =IF(H48=0,"-",RANK(H48,H$7:H$48)) -> 29 | K48: 25000 | L48: =IFERROR(K48/K$49,0) -> 0.0030256088 | M48: =IF(K48=0,"-",RANK(K48,K$7:K$48)) -> 30 | N48: =F48-I48 -> 0.0039464209 | O48: =F48-L48 -> 0.0045063267
C49: 合計（対象42SKU） | E49: =SUM(E7:E48) -> 3319200 | F49: =IFERROR(E49/E49,0) -> 1 | H49: =SUM(H7:H48) -> 20917500 | I49: =IFERROR(H49/H49,0) -> 1 | K49: =SUM(K7:K48) -> 8262800 | L49: =IFERROR(K49/K49,0) -> 1

Sheet ②札幌日別明細
A1: ② 札幌会場 商品別 日別販売実績（7/22〜7/26）
A2: 各日の構成比率＝当該商品のその日の販売数 ÷ 対象42SKUのその日の合計販売数
A5: No. | B5: JAN | C5: 商品名 | D5: 税込 単価 | E5: 日別 販売数 | J5: 日別 構成比率 | O5: 5日累計
E6: 7/22(水) | F6: 7/23(木) | G6: 7/24(金) | H6: 7/25(土) | I6: 7/26(日) | J6: 7/22(水) | K6: 7/23(木) | L6: 7/24(金) | M6: 7/25(土) | N6: 7/26(日) | O6: 販売数 | P6: 構成比率 | Q6: 販売金額(税込)
A7: 1 | B7: 4515142545082 | C7: 呪術廻戦 メタリックポストカード 展示会キービジュアル | D7: 500 | E7: 72 | F7: 23 | G7: 26 | H7: 49 | I7: 35 | J7: =IFERROR(E7/E$49,0) -> 0.04040404 | K7: =IFERROR(F7/F$49,0) -> 0.054373522 | L7: =IFERROR(G7/G$49,0) -> 0.050096339 | M7: =IFERROR(H7/H$49,0) -> 0.053846154 | N7: =IFERROR(I7/I$49,0) -> 0.063063063 | O7: =SUM(E7:I7) -> 205 | P7: =IFERROR(O7/O$49,0) -> 0.048937694 | Q7: =O7*D7 -> 102500
A8: 2 | B8: 4515142545099 | C8: 呪術廻戦 クリアファイル 展示会キービジュアル | D8: 600 | E8: 66 | F8: 23 | G8: 31 | H8: 61 | I8: 52 | J8: =IFERROR(E8/E$49,0) -> 0.037037037 | K8: =IFERROR(F8/F$49,0) -> 0.054373522 | L8: =IFERROR(G8/G$49,0) -> 0.05973025 | M8: =IFERROR(H8/H$49,0) -> 0.067032967 | N8: =IFERROR(I8/I$49,0) -> 0.093693694 | O8: =SUM(E8:I8) -> 233 | P8: =IFERROR(O8/O$49,0) -> 0.055621867 | Q8: =O8*D8 -> 139800
A9: 3 | B9: 4515142545105 | C9: 呪術廻戦 懐玉・玉折 ポストカードセット（5枚入） | D9: 1000 | E9: 39 | F9: 12 | G9: 7 | H9: 16 | I9: 10 | J9: =IFERROR(E9/E$49,0) -> 0.021885522 | K9: =IFERROR(F9/F$49,0) -> 0.028368794 | L9: =IFERROR(G9/G$49,0) -> 0.013487476 | M9: =IFERROR(H9/H$49,0) -> 0.017582418 | N9: =IFERROR(I9/I$49,0) -> 0.018018018 | O9: =SUM(E9:I9) -> 84 | P9: =IFERROR(O9/O$49,0) -> 0.020052519 | Q9: =O9*D9 -> 84000
A10: 4 | B10: 4515142545112 | C10: 呪術廻戦 渋谷事変 ポストカードセット（9枚入） | D10: 1800 | E10: 52 | F10: 13 | G10: 13 | H10: 28 | I10: 16 | J10: =IFERROR(E10/E$49,0) -> 0.029180696 | K10: =IFERROR(F10/F$49,0) -> 0.030732861 | L10: =IFERROR(G10/G$49,0) -> 0.02504817 | M10: =IFERROR(H10/H$49,0) -> 0.030769231 | N10: =IFERROR(I10/I$49,0) -> 0.028828829 | O10: =SUM(E10:I10) -> 122 | P10: =IFERROR(O10/O$49,0) -> 0.029123896 | Q10: =O10*D10 -> 219600
A11: 5 | B11: 4515142545129 | C11: 呪術廻戦 懐玉・玉折 ブラインド缶バッジ（全5種） | D11: 600 | E11: 174 | F11: 16 | G11: 13 | H11: 24 | I11: 20 | J11: =IFERROR(E11/E$49,0) -> 0.097643098 | K11: =IFERROR(F11/F$49,0) -> 0.037825059 | L11: =IFERROR(G11/G$49,0) -> 0.02504817 | M11: =IFERROR(H11/H$49,0) -> 0.026373626 | N11: =IFERROR(I11/I$49,0) -> 0.036036036 | O11: =SUM(E11:I11) -> 247 | P11: =IFERROR(O11/O$49,0) -> 0.058963953 | Q11: =O11*D11 -> 148200
A12: 6 | B12: 4515142545136 | C12: 呪術廻戦 渋谷事変 ブラインド缶バッジ（全9種） | D12: 600 | E12: 407 | F12: 74 | G12: 55 | H12: 53 | I12: 27 | J12: =IFERROR(E12/E$49,0) -> 0.22839506 | K12: =IFERROR(F12/F$49,0) -> 0.1749409 | L12: =IFERROR(G12/G$49,0) -> 0.10597303 | M12: =IFERROR(H12/H$49,0) -> 0.058241758 | N12: =IFERROR(I12/I$49,0) -> 0.048648649 | O12: =SUM(E12:I12) -> 616 | P12: =IFERROR(O12/O$49,0) -> 0.1470518 | Q12: =O12*D12 -> 369600
A13: 7 | B13: 4515142545143 | C13: 呪術廻戦 懐玉・玉折 ブラインドダイカットステッカー（全5種） | D13: 600 | E13: 28 | F13: 4 | G13: 13 | H13: 10 | I13: 24 | J13: =IFERROR(E13/E$49,0) -> 0.015712682 | K13: =IFERROR(F13/F$49,0) -> 0.0094562648 | L13: =IFERROR(G13/G$49,0) -> 0.02504817 | M13: =IFERROR(H13/H$49,0) -> 0.010989011 | N13: =IFERROR(I13/I$49,0) -> 0.043243243 | O13: =SUM(E13:I13) -> 79 | P13: =IFERROR(O13/O$49,0) -> 0.018858916 | Q13: =O13*D13 -> 47400
A14: 8 | B14: 4515142545150 | C14: 呪術廻戦 渋谷事変 ブラインドダイカットステッカー（全9種） | D14: 600 | E14: 39 | F14: 15 | G14: 13 | H14: 40 | I14: 28 | J14: =IFERROR(E14/E$49,0) -> 0.021885522 | K14: =IFERROR(F14/F$49,0) -> 0.035460993 | L14: =IFERROR(G14/G$49,0) -> 0.02504817 | M14: =IFERROR(H14/H$49,0) -> 0.043956044 | N14: =IFERROR(I14/I$49,0) -> 0.05045045 | O14: =SUM(E14:I14) -> 135 | P14: =IFERROR(O14/O$49,0) -> 0.032227262 | Q14: =O14*D14 -> 81000
A15: 9 | B15: 4515142545372 | C15: 呪術廻戦 懐玉・玉折 クリアファイル（五条 悟） | D15: 600 | E15: 28 | F15: 10 | G15: 9 | H15: 14 | I15: 14 | J15: =IFERROR(E15/E$49,0) -> 0.015712682 | K15: =IFERROR(F15/F$49,0) -> 0.023640662 | L15: =IFERROR(G15/G$49,0) -> 0.01734104 | M15: =IFERROR(H15/H$49,0) -> 0.015384615 | N15: =IFERROR(I15/I$49,0) -> 0.025225225 | O15: =SUM(E15:I15) -> 75 | P15: =IFERROR(O15/O$49,0) -> 0.017904034 | Q15: =O15*D15 -> 45000
A16: 10 | B16: 4515142545389 | C16: 呪術廻戦 懐玉・玉折 クリアファイル（夏油 傑） | D16: 600 | E16: 18 | F16: 2 | G16: 4 | H16: 2 | I16: 4 | J16: =IFERROR(E16/E$49,0) -> 0.01010101 | K16: =IFERROR(F16/F$49,0) -> 0.0047281324 | L16: =IFERROR(G16/G$49,0) -> 0.0077071291 | M16: =IFERROR(H16/H$49,0) -> 0.0021978022 | N16: =IFERROR(I16/I$49,0) -> 0.0072072072 | O16: =SUM(E16:I16) -> 30 | P16: =IFERROR(O16/O$49,0) -> 0.0071616138 | Q16: =O16*D16 -> 18000
A17: 11 | B17: 4515142545396 | C17: 呪術廻戦 懐玉・玉折 クリアファイル（家入 硝子） | D17: 600 | E17: 0 | F17: 1 | G17: 2 | H17: 4 | I17: 1 | J17: =IFERROR(E17/E$49,0) -> 0 | K17: =IFERROR(F17/F$49,0) -> 0.0023640662 | L17: =IFERROR(G17/G$49,0) -> 0.0038535645 | M17: =IFERROR(H17/H$49,0) -> 0.0043956044 | N17: =IFERROR(I17/I$49,0) -> 0.0018018018 | O17: =SUM(E17:I17) -> 8 | P17: =IFERROR(O17/O$49,0) -> 0.0019097637 | Q17: =O17*D17 -> 4800
A18: 12 | B18: 4515142545402 | C18: 呪術廻戦 懐玉・玉折 クリアファイル（七海 建人） | D18: 600 | E18: 1 | F18: 3 | G18: 2 | H18: 3 | I18: 3 | J18: =IFERROR(E18/E$49,0) -> 0.00056116723 | K18: =IFERROR(F18/F$49,0) -> 0.0070921986 | L18: =IFERROR(G18/G$49,0) -> 0.0038535645 | M18: =IFERROR(H18/H$49,0) -> 0.0032967033 | N18: =IFERROR(I18/I$49,0) -> 0.0054054054 | O18: =SUM(E18:I18) -> 12 | P18: =IFERROR(O18/O$49,0) -> 0.0028646455 | Q18: =O18*D18 -> 7200
... A48: 42 | B48: 4515142545365 | C48: 伏黒 恵 イメージフラグメントケース | D48: 25000 | E48: 0 | F48: 0 | G48: 0 | H48: 1 | I48: 0 | J48: =IFERROR(E48/E$49,0) -> 0 | K48: =IFERROR(F48/F$49,0) -> 0 | L48: =IFERROR(G48/G$49,0) -> 0 | M48: =IFERROR(H48/H$49,0) -> 0.0010989011 | N48: =IFERROR(I48/I$49,0) -> 0 | O48: =SUM(E48:I48) -> 1 | P48: =IFERROR(O48/O$49,0) -> 0.00023872046 | Q48: =O48*D48 -> 25000
C49: 合計（対象42SKU） | E49: =SUM(E7:E48) -> 1782 | F49: =SUM(F7:F48) -> 423 | G49: =SUM(G7:G48) -> 519 | H49: =SUM(H7:H48) -> 910 | I49: =SUM(I7:I48) -> 555 | J49: 1 | K49: 1 | L49: 1 | M49: 1 | N49: 1 | O49: =SUM(O7:O48) -> 4189 | P49: 1 | Q49: =SUM(Q7:Q48) -> 3319200

Sheet ③追加発注判定
A1: ③ 追加発注 必要有無の判定（札幌会場 会期20日間 需要予測） | S1: 博多 15-20日目補完率 | T1: 0.45321382
A2: 7/26(5日目)実績 × 会期倍率g で 8/10(20日目)までの最終販売数を予測し、販売可能数と突合 | S2: 全体倍率 g（42品計） | T2: 2.689506
A3: 会期倍率 g ＝ 20日累計販売数 ÷ 初5日販売数（名古屋①・博多②の実績から商品別に算出し平均を採用） | S3: ↑ 青字＝入力値／前提。名古屋は14日目までのため15-20日目を博多比率で補完
A6: No. | B6: JAN | C6: 商品名 | D6: 札幌 7/22-26 販売数 | E6: 札幌 販売可能数 | F6: 札幌 現在消化率 | G6: 札幌 残在庫 | H6: 名古屋① 初5日 | I6: 名古屋① 14日累計 | J6: 博多② 初5日 | K6: 博多② 14日累計 | L6: 博多② 20日累計 | M6: 名古屋 倍率g | N6: 博多 倍率g | O6: 採用 倍率g | P6: 予測 会期累計 販売数 | Q6: 予測 消化率 | R6: 過不足数 (予測−可能数) | S6: 追加発注 要否 | T6: 推奨 追加発注数 | U6: 比較会場 売切れ | V6: 備考
A7: 1 | B7: 4515142545082 | C7: 呪術廻戦 メタリックポストカード 展示会キービジュアル | D7: 205 | E7: 1000 | F7: =IFERROR(D7/E7,0) -> 0.205 | G7: =E7-D7 -> 795 | H7: 605 | I7: 1125 | J7: 419 | K7: 781 | L7: 987 | M7: =IF(H7=0,"",I7*(1+$T$1)/H7) -> 2.7022571 | N7: =IF(J7=0,"",L7/J7) -> 2.3556086 | O7: =IF(COUNT(M7:N7)=0,$T$2,AVERAGE(M7:N7)) -> 2.5289328 | P7: =ROUND(D7*O7,0) -> 518 | Q7: =IFERROR(P7/E7,0) -> 0.518 | R7: =P7-E7 -> -482 | S7: =IF(R7>0,"要 追加発注",IF(Q7>=0.9,"要注意(90%超)",IF(Q7>=0.5,"適正","在庫余剰見込"))) -> 適正 | T7: =IF(R7>0,ROUNDUP(R7*1.1,0),0) -> 0 | U7: 博多 | V7: 比較会場(博多)が在庫上限のため倍率gが過小＝予測が控えめ
A8: 2 | B8: 4515142545099 | C8: 呪術廻戦 クリアファイル 展示会キービジュアル | D8: 233 | E8: 1000 | F8: =IFERROR(D8/E8,0) -> 0.233 | G8: =E8-D8 -> 767 | H8: 616 | I8: 1190 | J8: 363 | K8: 738 | L8: 898 | M8: =IF(H8=0,"",I8*(1+$T$1)/H8) -> 2.8073449 | N8: =IF(J8=0,"",L8/J8) -> 2.4738292 | O8: =IF(COUNT(M8:N8)=0,$T$2,AVERAGE(M8:N8)) -> 2.640587 | P8: =ROUND(D8*O8,0) -> 615 | Q8: =IFERROR(P8/E8,0) -> 0.615 | R8: =P8-E8 -> -385 | S8: =IF(R8>0,"要 追加発注",IF(Q8>=0.9,"要注意(90%超)",IF(Q8>=0.5,"適正","在庫余剰見込"))) -> 適正 | T8: =IF(R8>0,ROUNDUP(R8*1.1,0),0) -> 0 | U8: —
A9: 3 | B9: 4515142545105 | C9: 呪術廻戦 懐玉・玉折 ポストカードセット（5枚入） | D9: 84 | E9: 450 | F9: =IFERROR(D9/E9,0) -> 0.18666667 | G9: =E9-D9 -> 366 | H9: 349 | I9: 532 | J9: 166 | K9: 317 | L9: 384 | M9: =IF(H9=0,"",I9*(1+$T$1)/H9) -> 2.2152142 | N9: =IF(J9=0,"",L9/J9) -> 2.313253 | O9: =IF(COUNT(M9:N9)=0,$T$2,AVERAGE(M9:N9)) -> 2.2642336 | P9: =ROUND(D9*O9,0) -> 190 | Q9: =IFERROR(P9/E9,0) -> 0.42222222 | R9: =P9-E9 -> -260 | S9: =IF(R9>0,"要 追加発注",IF(Q9>=0.9,"要注意(90%超)",IF(Q9>=0.5,"適正","在庫余剰見込"))) -> 在庫余剰見込 | T9: =IF(R9>0,ROUNDUP(R9*1.1,0),0) -> 0 | U9: —
A10: 4 | B10: 4515142545112 | C10: 呪術廻戦 渋谷事変 ポストカードセット（9枚入） | D10: 122 | E10: 800 | F10: =IFERROR(D10/E10,0) -> 0.1525 | G10: =E10-D10 -> 678 | H10: 553 | I10: 817 | J10: 212 | K10: 377 | L10: 442 | M10: =IF(H10=0,"",I10*(1+$T$1)/H10) -> 2.1469723 | N10: =IF(J10=0,"",L10/J10) -> 2.0849057 | O10: =IF(COUNT(M10:N10)=0,$T$2,AVERAGE(M10:N10)) -> 2.115939 | P10: =ROUND(D10*O10,0) -> 258 | Q10: =IFERROR(P10/E10,0) -> 0.3225 | R10: =P10-E10 -> -542 | S10: =IF(R10>0,"要 追加発注",IF(Q10>=0.9,"要注意(90%超)",IF(Q10>=0.5,"適正","在庫余剰見込"))) -> 在庫余剰見込 | T10: =IF(R10>0,ROUNDUP(R10*1.1,0),0) -> 0 | U10: —
A11: 5 | B11: 4515142545129 | C11: 呪術廻戦 懐玉・玉折 ブラインド缶バッジ（全5種） | D11: 247 | E11: 9000 | F11: =IFERROR(D11/E11,0) -> 0.027444444 | G11: =E11-D11 -> 8753 | H11: 5070 | I11: 9400 | J11: 2232 | K11: 3939 | L11: 6948 | M11: =IF(H11=0,"",I11*(1+$T$1)/H11) -> 2.6943215 | N11: =IF(J11=0,"",L11/J11) -> 3.1129032 | O11: =IF(COUNT(M11:N11)=0,$T$2,AVERAGE(M11:N11)) -> 2.9036124 | P11: =ROUND(D11*O11,0) -> 717 | Q11: =IFERROR(P11/E11,0) -> 0.079666667 | R11: =P11-E11 -> -8283 | S11: =IF(R11>0,"要 追加発注",IF(Q11>=0.9,"要注意(90%超)",IF(Q11>=0.5,"適正","在庫余剰見込"))) -> 在庫余剰見込 | T11: =IF(R11>0,ROUNDUP(R11*1.1,0),0) -> 0 | U11: 博多 | V11: 比較会場(博多)が在庫上限のため倍率gが過小＝予測が控えめ
A12: 6 | B12: 4515142545136 | C12: 呪術廻戦 渋谷事変 ブラインド缶バッジ（全9種） | D12: 616 | E12: 13991 | F12: =IFERROR(D12/E12,0) -> 0.044028304 | G12: =E12-D12 -> 13375 | H12: 6714 | I12: 13632 | J12: 2836 | K12: 4957 | L12: 8314 | M12: =IF(H12=0,"",I12*(1+$T$1)/H12) -> 2.9505825 | N12: =IF(J12=0,"",L12/J12) -> 2.9315938 | O12: =IF(COUNT(M12:N12)=0,$T$2,AVERAGE(M12:N12)) -> 2.9410881 | P12: =ROUND(D12*O12,0) -> 1812 | Q12: =IFERROR(P12/E12,0) -> 0.12951183 | R12: =P12-E12 -> -12179 | S12: =IF(R12>0,"要 追加発注",IF(Q12>=0.9,"要注意(90%超)",IF(Q12>=0.5,"適正","在庫余剰見込"))) -> 在庫余剰見込 | T12: =IF(R12>0,ROUNDUP(R12*1.1,0),0) -> 0 | U12: 名古屋・博多 | V12: 比較会場(名古屋・博多)が在庫上限のため倍率gが過小＝予測が控えめ
A13: 7 | B13: 4515142545143 | C13: 呪術廻戦 懐玉・玉折 ブラインドダイカットステッカー（全5種） | D13: 79 | E13: 350 | F13: =IFERROR(D13/E13,0) -> 0.22571429 | G13: =E13-D13 -> 271 | H13: 209 | I13: 433 | J13: 148 | K13: 276 | L13: 349 | M13: =IF(H13=0,"",I13*(1+$T$1)/H13) -> 3.0107253 | N13: =IF(J13=0,"",L13/J13) -> 2.3581081 | O13: =IF(COUNT(M13:N13)=0,$T$2,AVERAGE(M13:N13)) -> 2.6844167 | P13: =ROUND(D13*O13,0) -> 212 | Q13: =IFERROR(P13/E13,0) -> 0.60571429 | R13: =P13-E13 -> -138 | S13: =IF(R13>0,"要 追加発注",IF(Q13>=0.9,"要注意(90%超)",IF(Q13>=0.5,"適正","在庫余剰見込"))) -> 適正 | T13: =IF(R13>0,ROUNDUP(R13*1.1,0),0) -> 0 | U13: 博多 | V13: 比較会場(博多)が在庫上限のため倍率gが過小＝予測が控えめ
A14: 8 | B14: 4515142545150 | C14: 呪術廻戦 渋谷事変 ブラインドダイカットステッカー（全9種） | D14: 135 | E14: 900 | F14: =IFERROR(D14/E14,0) -> 0.15 | G14: =E14-D14 -> 765 | H14: 432 | I14: 926 | J14: 235 | K14: 490 | L14: 608 | M14: =IF(H14=0,"",I14*(1+$T$1)/H14) -> 3.1149907 | N14: =IF(J14=0,"",L14/J14) -> 2.587234 | O14: =IF(COUNT(M14:N14)=0,$T$2,AVERAGE(M14:N14)) -> 2.8511124 | P14: =ROUND(D14*O14,0) -> 385 | Q14: =IFERROR(P14/E14,0) -> 0.42777778 | R14: =P14-E14 -> -515 | S14: =IF(R14>0,"要 追加発注",IF(Q14>=0.9,"要注意(90%超)",IF(Q14>=0.5,"適正","在庫余剰見込"))) -> 在庫余剰見込 | T14: =IF(R14>0,ROUNDUP(R14*1.1,0),0) -> 0 | U14: 博多 | V14: 比較会場(博多)が在庫上限のため倍率gが過小＝予測が控えめ
A15: 9 | B15: 4515142545372 | C15: 呪術廻戦 懐玉・玉折 クリアファイル（五条 悟） | D15: 75 | E15: 300 | F15: =IFERROR(D15/E15,0) -> 0.25 | G15: =E15-D15 -> 225 | H15: 197 | I15: 276 | J15: 141 | K15: 238 | L15: 265 | M15: =IF(H15=0,"",I15*(1+$T$1)/H15) -> 2.0359747 | N15: =IF(J15=0,"",L15/J15) -> 1.8794326 | O15: =IF(COUNT(M15:N15)=0,$T$2,AVERAGE(M15:N15)) -> 1.9577037 | P15: =ROUND(D15*O15,0) -> 147 | Q15: =IFERROR(P15/E15,0) -> 0.49 | R15: =P15-E15 -> -153 | S15: =IF(R15>0,"要 追加発注",IF(Q15>=0.9,"要注意(90%超)",IF(Q15>=0.5,"適正","在庫余剰見込"))) -> 在庫余剰見込 | T15: =IF(R15>0,ROUNDUP(R15*1.1,0),0) -> 0 | U15: 博多 | V15: 比較会場(博多)が在庫上限のため倍率gが過小＝予測が控えめ
A16: 10 | B16: 4515142545389 | C16: 呪術廻戦 懐玉・玉折 クリアファイル（夏油 傑） | D16: 30 | E16: 100 | F16: =IFERROR(D16/E16,0) -> 0.3 | G16: =E16-D16 -> 70 | H16: 78 | I16: 118 | J16: 65 | K16: 99 | L16: 108 | M16: =IF(H16=0,"",I16*(1+$T$1)/H16) -> 2.1984517 | N16: =IF(J16=0,"",L16/J16) -> 1.6615385 | O16: =IF(COUNT(M16:N16)=0,$T$2,AVERAGE(M16:N16)) -> 1.9299951 | P16: =ROUND(D16*O16,0) -> 58 | Q16: =IFERROR(P16/E16,0) -> 0.58 | R16: =P16-E16 -> -42 | S16: =IF(R16>0,"要 追加発注",IF(Q16>=0.9,"要注意(90%超)",IF(Q16>=0.5,"適正","在庫余剰見込"))) -> 適正 | T16: =IF(R16>0,ROUNDUP(R16*1.1,0),0) -> 0 | U16: —
A17: 11 | B17: 4515142545396 | C17: 呪術廻戦 懐玉・玉折 クリアファイル（家入 硝子） | D17: 8 | E17: 50 | F17: =IFERROR(D17/E17,0) -> 0.16 | G17: =E17-D17 -> 42 | H17: 8 | I17: 22 | J17: 10 | K17: 28 | L17: 30 | M17: =IF(H17=0,"",I17*(1+$T$1)/H17) -> 3.996338 | N17: =IF(J17=0,"",L17/J17) -> 3 | O17: =IF(COUNT(M17:N17)=0,$T$2,AVERAGE(M17:N17)) -> 3.498169 | P17: =ROUND(D17*O17,0) -> 28 | Q17: =IFERROR(P17/E17,0) -> 0.56 | R17: =P17-E17 -> -22 | S17: =IF(R17>0,"要 追加発注",IF(Q17>=0.9,"要注意(90%超)",IF(Q17>=0.5,"適正","在庫余剰見込"))) -> 適正 | T17: =IF(R17>0,ROUNDUP(R17*1.1,0),0) -> 0 | U17: 博多 | V17: 比較会場(博多)が在庫上限のため倍率gが過小＝予測が控えめ
A18: 12 | B18: 4515142545402 | C18: 呪術廻戦 懐玉・玉折 クリアファイル（七海 建人） | D18: 12 | E18: 50 | F18: =IFERROR(D18/E18,0) -> 0.24 | G18: =E18-D18 -> 38 | H18: 33 | I18: 52 | J18: 13 | K18: 35 | L18: 43 | M18: =IF(H18=0,"",I18*(1+$T$1)/H18) -> 2.2899127 | N18: =IF(J18=0,"",L18/J18) -> 3.3076923 | O18: =IF(COUNT(M18:N18)=0,$T$2,AVERAGE(M18:N18)) -> 2.7988025 | P18: =ROUND(D18*O18,0) -> 34 | Q18: =IFERROR(P18/E18,0) -> 0.68 | R18: =P18-E18 -> -16 | S18: =IF(R18>0,"要 追加発注",IF(Q18>=0.9,"要注意(90%超)",IF(Q18>=0.5,"適正","在庫余剰見込"))) -> 適正 | T18: =IF(R18>0,ROUNDUP(R18*1.1,0),0) -> 0 | U18: —
A19: 13 | B19: 4515142545419 | C19: 呪術廻戦 懐玉・玉折 クリアファイル（灰原 雄） | D19: 3 | E19: 50 | F19: =IFERROR(D19/E19,0) -> 0.06 | G19: =E19-D19 -> 47 | H19: 6 | I19: 14 | J19: 6 | K19: 16 | L19: 18 | M19: =IF(H19=0,"",I19*(1+$T$1)/H19) -> 3.3908322 | N19: =IF(J19=0,"",L19/J19) -> 3 | O19: =IF(COUNT(M19:N19)=0,$T$2,AVERAGE(M19:N19)) -> 3.1954161 | P19: =ROUND(D19*O19,0) -> 10 | Q19: =IFERROR(P19/E19,0) -> 0.2 | R19: =P19-E19 -> -40 | S19: =IF(R19>0,"要 追加発注",IF(Q19>=0.9,"要注意(90%超)",IF(Q19>=0.5,"適正","在庫余剰見込"))) -> 在庫余剰見込 | T19: =IF(R19>0,ROUNDUP(R19*1.1,0),0) -> 0 | U19: —
A20: 14 | B20: 4515142545426 | C20: 呪術廻戦 渋谷事変 クリアファイル（虎杖 悠仁） | D20: 17 | E20: 50 | F20: =IFERROR(D20/E20,0) -> 0.34 | G20: =E20-D20 -> 33 | H20: 36 | I20: 60 | J20: 30 | K20: 54 | L20: 62 | M20: =IF(H20=0,"",I20*(1+$T$1)/H20) -> 2.422023 | N20: =IF(J20=0,"",L20/J20) -> 2.0666667 | O20: =IF(COUNT(M20:N20)=0,$T$2,AVERAGE(M20:N20)) -> 2.2443448 | P20: =ROUND(D20*O20,0) -> 38 | Q20: =IFERROR(P20/E20,0) -> 0.76 | R20: =P20-E20 -> -12 | S20: =IF(R20>0,"要 追加発注",IF(Q20>=0.9,"要注意(90%超)",IF(Q20>=0.5,"適正","在庫余剰見込"))) -> 適正 | T20: =IF(R20>0,ROUNDUP(R20*1.1,0),0) -> 0 | U20: 博多 | V20: 比較会場(博多)が在庫上限のため倍率gが過小＝予測が控えめ
A21: 15 | B21: 4515142545433 | C21: 呪術廻戦 渋谷事変 クリアファイル（伏黒 恵） | D21: 29 | E21: 100 | F21: =IFERROR(D21/E21,0) -> 0.29 | G21: =E21-D21 -> 71 | H21: 49 | I21: 85 | J21: 33 | K21: 71 | L21: 91 | M21: =IF(H21=0,"",I21*(1+$T$1)/H21) -> 2.5208811 | N21: =IF(J21=0,"",L21/J21) -> 2.7575758 | O21: =IF(COUNT(M21:N21)=0,$T$2,AVERAGE(M21:N21)) -> 2.6392284 | P21: =ROUND(D21*O21,0) -> 77 | Q21: =IFERROR(P21/E21,0) -> 0.77 | R21: =P21-E21 -> -23 | S21: =IF(R21>0,"要 追加発注",IF(Q21>=0.9,"要注意(90%超)",IF(Q21>=0.5,"適正","在庫余剰見込"))) -> 適正 | T21: =IF(R21>0,ROUNDUP(R21*1.1,0),0) -> 0 | U21: 博多 | V21: 比較会場(博多)が在庫上限のため倍率gが過小＝予測が控えめ
A22: 16 | B22: 4515142545440 | C22: 呪術廻戦 渋谷事変 クリアファイル（釘崎 野薔薇） | D22: 3 | E22: 50 | F22: =IFERROR(D22/E22,0) -> 0.06 | G22: =E22-D22 -> 47 | H22: 13 | I22: 24 | J22: 9 | K22: 21 | L22: 26 | M22: =IF(H22=0,"",I22*(1+$T$1)/H22) -> 2.6828563 | N22: =IF(J22=0,"",L22/J22) -> 2.8888889 | O22: =IF(COUNT(M22:N22)=0,$T$2,AVERAGE(M22:N22)) -> 2.7858726 | P22: =ROUND(D22*O22,0) -> 8 | Q22: =IFERROR(P22/E22,0) -> 0.16 | R22: =P22-E22 -> -42 | S22: =IF(R22>0,"要 追加発注",IF(Q22>=0.9,"要注意(90%超)",IF(Q22>=0.5,"適正","在庫余剰見込"))) -> 在庫余剰見込 | T22: =IF(R22>0,ROUNDUP(R22*1.1,0),0) -> 0 | U22: 博多 | V22: 比較会場(博多)が在庫上限のため倍率gが過小＝予測が控えめ
A23: 17 | B23: 4515142545457 | C23: 呪術廻戦 渋谷事変 クリアファイル（七海 建人） | D23: 39 | E23: 100 | F23: =IFERROR(D23/E23,0) -> 0.39 | G23: =E23-D23 -> 61 | H23: 62 | I23: 100 | J23: 41 | K23: 70 | L23: 94 | M23: =IF(H23=0,"",I23*(1+$T$1)/H23) -> 2.3438933 | N23: =IF(J23=0,"",L23/J23) -> 2.2926829 | O23: =IF(COUNT(M23:N23)=0,$T$2,AVERAGE(M23:N23)) -> 2.3182881 | P23: =ROUND(D23*O23,0) -> 90 | Q23: =IFERROR(P23/E23,0) -> 0.9 | R23: =P23-E23 -> -10 | S23: =IF(R23>0,"要 追加発注",IF(Q23>=0.9,"要注意(90%超)",IF(Q23>=0.5,"適正","在庫余剰見込"))) -> 要注意(90%超) | T23: =IF(R23>0,ROUNDUP(R23*1.1,0),0) -> 0 | U23: 博多 | V23: 比較会場(博多)が在庫上限のため倍率gが過小＝予測が控えめ
A24: 18 | B24: 4515142545464 | C24: 呪術廻戦 渋谷事変 クリアファイル（五条 悟） | D24: 224 | E24: 1500 | F24: =IFERROR(D24/E24,0) -> 0.14933333 | G24: =E24-D24 -> 1276 | H24: 638 | I24: 1029 | J24: 386 | K24: 644 | L24: 743 | M24: =IF(H24=0,"",I24*(1+$T$1)/H24) -> 2.3438198 | N24: =IF(J24=0,"",L24/J24) -> 1.9248705 | O24: =IF(COUNT(M24:N24)=0,$T$2,AVERAGE(M24:N24)) -> 2.1343451 | P24: =ROUND(D24*O24,0) -> 478 | Q24: =IFERROR(P24/E24,0) -> 0.31866667 | R24: =P24-E24 -> -1022 | S24: =IF(R24>0,"要 追加発注",IF(Q24>=0.9,"要注意(90%超)",IF(Q24>=0.5,"適正","在庫余剰見込"))) -> 在庫余剰見込 | T24: =IF(R24>0,ROUNDUP(R24*1.1,0),0) -> 0 | U24: 博多 | V24: 比較会場(博多)が在庫上限のため倍率gが過小＝予測が控えめ
A25: 19 | B25: 4515142545471 | C25: 呪術廻戦 渋谷事変 クリアファイル（夏油 傑） | D25: 8 | E25: 50 | F25: =IFERROR(D25/E25,0) -> 0.16 | G25: =E25-D25 -> 42 | H25: 19 | I25: 23 | J25: 8 | K25: 19 | L25: 19 | M25: =IF(H25=0,"",I25*(1+$T$1)/H25) -> 1.7591536 | N25: =IF(J25=0,"",L25/J25) -> 2.375 | O25: =IF(COUNT(M25:N25)=0,$T$2,AVERAGE(M25:N25)) -> 2.0670768 | P25: =ROUND(D25*O25,0) -> 17 | Q25: =IFERROR(P25/E25,0) -> 0.34 | R25: =P25-E25 -> -33 | S25: =IF(R25>0,"要 追加発注",IF(Q25>=0.9,"要注意(90%超)",IF(Q25>=0.5,"適正","在庫余剰見込"))) -> 在庫余剰見込 | T25: =IF(R25>0,ROUNDUP(R25*1.1,0),0) -> 0 | U25: 博多 | V25: 比較会場(博多)が在庫上限のため倍率gが過小＝予測が控えめ
A26: 20 | B26: 4515142545488 | C26: 呪術廻戦 渋谷事変 クリアファイル（真人） | D26: 5 | E26: 30 | F26: =IFERROR(D26/E26,0) -> 0.16666667 | G26: =E26-D26 -> 25 | H26: 10 | I26: 18 | J26: 7 | K26: 15 | L26: 15 | M26: =IF(H26=0,"",I26*(1+$T$1)/H26) -> 2.6157849 | N26: =IF(J26=0,"",L26/J26) -> 2.1428571 | O26: =IF(COUNT(M26:N26)=0,$T$2,AVERAGE(M26:N26)) -> 2.379321 | P26: =ROUND(D26*O26,0) -> 12 | Q26: =IFERROR(P26/E26,0) -> 0.4 | R26: =P26-E26 -> -18 | S26: =IF(R26>0,"要 追加発注",IF(Q26>=0.9,"要注意(90%超)",IF(Q26>=0.5,"適正","在庫余剰見込"))) -> 在庫余剰見込 | T26: =IF(R26>0,ROUNDUP(R26*1.1,0),0) -> 0 | U26: 博多 | V26: 比較会場(博多)が在庫上限のため倍率gが過小＝予測が控えめ
A27: 21 | B27: 4515142545495 | C27: 呪術廻戦 渋谷事変 クリアファイル（脹相） | D27: 40 | E27: 50 | F27: =IFERROR(D27/E27,0) -> 0.8 | G27: =E27-D27 -> 10 | H27: 73 | I27: 139 | J27: 63 | K27: 116 | L27: 139 | M27: =IF(H27=0,"",I27*(1+$T$1)/H27) -> 2.7670784 | N27: =IF(J27=0,"",L27/J27) -> 2.2063492 | O27: =IF(COUNT(M27:N27)=0,$T$2,AVERAGE(M27:N27)) -> 2.4867138 | P27: =ROUND(D27*O27,0) -> 99 | Q27: =IFERROR(P27/E27,0) -> 1.98 | R27: =P27-E27 -> 49 | S27: =IF(R27>0,"要 追加発注",IF(Q27>=0.9,"要注意(90%超)",IF(Q27>=0.5,"適正","在庫余剰見込"))) -> 要 追加発注 | T27: =IF(R27>0,ROUNDUP(R27*1.1,0),0) -> 54 | U27: 名古屋・博多 | V27: 比較会場(名古屋・博多)が在庫上限のため倍率gが過小＝予測が控えめ
A28: 22 | B28: 4515142545501 | C28: 呪術廻戦 渋谷事変 クリアファイル（宿儺） | D28: 14 | E28: 50 | F28: =IFERROR(D28/E28,0) -> 0.28 | G28: =E28-D28 -> 36 | H28: 35 | I28: 80 | J28: 20 | K28: 59 | L28: 77 | M28: =IF(H28=0,"",I28*(1+$T$1)/H28) -> 3.3216316 | N28: =IF(J28=0,"",L28/J28) -> 3.85 | O28: =IF(COUNT(M28:N28)=0,$T$2,AVERAGE(M28:N28)) -> 3.5858158 | P28: =ROUND(D28*O28,0) -> 50 | Q28: =IFERROR(P28/E28,0) -> 1 | R28: =P28-E28 -> 0 | S28: =IF(R28>0,"要 追加発注",IF(Q28>=0.9,"要注意(90%超)",IF(Q28>=0.5,"適正","在庫余剰見込"))) -> 要注意(90%超) | T28: =IF(R28>0,ROUNDUP(R28*1.1,0),0) -> 0 | U28: 博多 | V28: 比較会場(博多)が在庫上限のため倍率gが過小＝予測が控えめ
A29: 23 | B29: 4515142545174 | C29: 呪術廻戦 懐玉・玉折 ブラインドミニ色紙（全5種） | D29: 1027 | E29: 11000 | F29: =IFERROR(D29/E29,0) -> 0.093363636 | G29: =E29-D29 -> 9973 | H29: 6233 | I29: 11918 | J29: 2701 | K29: 5144 | L29: 6933 | M29: =IF(H29=0,"",I29*(1+$T$1)/H29) -> 2.7786623 | N29: =IF(J29=0,"",L29/J29) -> 2.5668271 | O29: =IF(COUNT(M29:N29)=0,$T$2,AVERAGE(M29:N29)) -> 2.6727447 | P29: =ROUND(D29*O29,0) -> 2745 | Q29: =IFERROR(P29/E29,0) -> 0.24954545 | R29: =P29-E29 -> -8255 | S29: =IF(R29>0,"要 追加発注",IF(Q29>=0.9,"要注意(90%超)",IF(Q29>=0.5,"適正","在庫余剰見込"))) -> 在庫余剰見込 | T29: =IF(R29>0,ROUNDUP(R29*1.1,0),0) -> 0 | U29: —
A30: 24 | B30: 4515142545181 | C30: 呪術廻戦 渋谷事変 ブラインドミニ色紙（全5種） | D30: 543 | E30: 8000 | F30: =IFERROR(D30/E30,0) -> 0.067875 | G30: =E30-D30 -> 7457 | H30: 4369 | I30: 7253 | J30: 1535 | K30: 3074 | L30: 4202 | M30: =IF(H30=0,"",I30*(1+$T$1)/H30) -> 2.4124879 | N30: =IF(J30=0,"",L30/J30) -> 2.7374593 | O30: =IF(COUNT(M30:N30)=0,$T$2,AVERAGE(M30:N30)) -> 2.5749736 | P30: =ROUND(D30*O30,0) -> 1398 | Q30: =IFERROR(P30/E30,0) -> 0.17475 | R30: =P30-E30 -> -6602 | S30: =IF(R30>0,"要 追加発注",IF(Q30>=0.9,"要注意(90%超)",IF(Q30>=0.5,"適正","在庫余剰見込"))) -> 在庫余剰見込 | T30: =IF(R30>0,ROUNDUP(R30*1.1,0),0) -> 0 | U30: —
A31: 25 | B31: 4515142545198 | C31: 虚式『茈』バスボール | D31: 18 | E31: 200 | F31: =IFERROR(D31/E31,0) -> 0.09 | G31: =E31-D31 -> 182 | H31: 98 | I31: 181 | J31: 57 | K31: 110 | L31: 140 | M31: =IF(H31=0,"",I31*(1+$T$1)/H31) -> 2.6839969 | N31: =IF(J31=0,"",L31/J31) -> 2.4561404 | O31: =IF(COUNT(M31:N31)=0,$T$2,AVERAGE(M31:N31)) -> 2.5700686 | P31: =ROUND(D31*O31,0) -> 46 | Q31: =IFERROR(P31/E31,0) -> 0.23 | R31: =P31-E31 -> -154 | S31: =IF(R31>0,"要 追加発注",IF(Q31>=0.9,"要注意(90%超)",IF(Q31>=0.5,"適正","在庫余剰見込"))) -> 在庫余剰見込 | T31: =IF(R31>0,ROUNDUP(R31*1.1,0),0) -> 0 | U31: 博多 | V31: 比較会場(博多)が在庫上限のため倍率gが過小＝予測が控えめ
A32: 26 | B32: 4515142545204 | C32: 前髪ヘアバンド | D32: 85 | E32: 100 | F32: =IFERROR(D32/E32,0) -> 0.85 | G32: =E32-D32 -> 15 | H32: 373 | I32: 513 | J32: 162 | K32: 292 | L32: 353 | M32: =IF(H32=0,"",I32*(1+$T$1)/H32) -> 1.998656 | N32: =IF(J32=0,"",L32/J32) -> 2.1790123 | O32: =IF(COUNT(M32:N32)=0,$T$2,AVERAGE(M32:N32)) -> 2.0888342 | P32: =ROUND(D32*O32,0) -> 178 | Q32: =IFERROR(P32/E32,0) -> 1.78 | R32: =P32-E32 -> 78 | S32: =IF(R32>0,"要 追加発注",IF(Q32>=0.9,"要注意(90%超)",IF(Q32>=0.5,"適正","在庫余剰見込"))) -> 要 追加発注 | T32: =IF(R32>0,ROUNDUP(R32*1.1,0),0) -> 86 | U32: 名古屋 | V32: 比較会場(名古屋)が在庫上限のため倍率gが過小＝予測が控えめ
A33: 27 | B33: 4515142545211 | C33: 反転術式絆創膏 | D33: 15 | E33: 70 | F33: =IFERROR(D33/E33,0) -> 0.21428571 | G33: =E33-D33 -> 55 | H33: 33 | I33: 80 | J33: 26 | K33: 57 | L33: 69 | M33: =IF(H33=0,"",I33*(1+$T$1)/H33) -> 3.5229426 | N33: =IF(J33=0,"",L33/J33) -> 2.6538462 | O33: =IF(COUNT(M33:N33)=0,$T$2,AVERAGE(M33:N33)) -> 3.0883944 | P33: =ROUND(D33*O33,0) -> 46 | Q33: =IFERROR(P33/E33,0) -> 0.65714286 | R33: =P33-E33 -> -24 | S33: =IF(R33>0,"要 追加発注",IF(Q33>=0.9,"要注意(90%超)",IF(Q33>=0.5,"適正","在庫余剰見込"))) -> 適正 | T33: =IF(R33>0,ROUNDUP(R33*1.1,0),0) -> 0 | U33: 博多 | V33: 比較会場(博多)が在庫上限のため倍率gが過小＝予測が控えめ
A34: 28 | B34: 4515142545228 | C34: 宿儺の指風お菓子 | D34: 130 | E34: 200 | F34: =IFERROR(D34/E34,0) -> 0.65 | G34: =E34-D34 -> 70 | H34: 299 | I34: 436 | J34: 167 | K34: 333 | L34: 333 | M34: =IF(H34=0,"",I34*(1+$T$1)/H34) -> 2.1190676 | N34: =IF(J34=0,"",L34/J34) -> 1.994012 | O34: =IF(COUNT(M34:N34)=0,$T$2,AVERAGE(M34:N34)) -> 2.0565398 | P34: =ROUND(D34*O34,0) -> 267 | Q34: =IFERROR(P34/E34,0) -> 1.335 | R34: =P34-E34 -> 67 | S34: =IF(R34>0,"要 追加発注",IF(Q34>=0.9,"要注意(90%超)",IF(Q34>=0.5,"適正","在庫余剰見込"))) -> 要 追加発注 | T34: =IF(R34>0,ROUNDUP(R34*1.1,0),0) -> 74 | U34: 名古屋・博多 | V34: 比較会場(名古屋・博多)が在庫上限のため倍率gが過小＝予測が控えめ
A35: 29 | B35: 4515142545235 | C35: 脱兎！ポーチ入りクリップセット | D35: 66 | E35: 100 | F35: =IFERROR(D35/E35,0) -> 0.66 | G35: =E35-D35 -> 34 | H35: 236 | I35: 318 | J35: 102 | K35: 239 | L35: 249 | M35: =IF(H35=0,"",I35*(1+$T$1)/H35) -> 1.958144 | N35: =IF(J35=0,"",L35/J35) -> 2.4411765 | O35: =IF(COUNT(M35:N35)=0,$T$2,AVERAGE(M35:N35)) -> 2.1996603 | P35: =ROUND(D35*O35,0) -> 145 | Q35: =IFERROR(P35/E35,0) -> 1.45 | R35: =P35-E35 -> 45 | S35: =IF(R35>0,"要 追加発注",IF(Q35>=0.9,"要注意(90%超)",IF(Q35>=0.5,"適正","在庫余剰見込"))) -> 要 追加発注 | T35: =IF(R35>0,ROUNDUP(R35*1.1,0),0) -> 50 | U35: 名古屋・博多 | V35: 比較会場(名古屋・博多)が在庫上限のため倍率gが過小＝予測が控えめ
A36: 30 | B36: 4515142545242 | C36: 釘崎のポーチ風エコバッグ | D36: 20 | E36: 250 | F36: =IFERROR(D36/E36,0) -> 0.08 | G36: =E36-D36 -> 230 | H36: 68 | I36: 142 | J36: 20 | K36: 51 | L36: 63 | M36: =IF(H36=0,"",I36*(1+$T$1)/H36) -> 3.0346524 | N36: =IF(J36=0,"",L36/J36) -> 3.15 | O36: =IF(COUNT(M36:N36)=0,$T$2,AVERAGE(M36:N36)) -> 3.0923262 | P36: =ROUND(D36*O36,0) -> 62 | Q36: =IFERROR(P36/E36,0) -> 0.248 | R36: =P36-E36 -> -188 | S36: =IF(R36>0,"要 追加発注",IF(Q36>=0.9,"要注意(90%超)",IF(Q36>=0.5,"適正","在庫余剰見込"))) -> 在庫余剰見込 | T36: =IF(R36>0,ROUNDUP(R36*1.1,0),0) -> 0 | U36: 博多 | V36: 比較会場(博多)が在庫上限のため倍率gが過小＝予測が控えめ
A37: 31 | B37: 4515142545259 | C37: 半年分の情報が書き込める手帳 | D37: 43 | E37: 200 | F37: =IFERROR(D37/E37,0) -> 0.215 | G37: =E37-D37 -> 157 | H37: 116 | I37: 198 | J37: 73 | K37: 138 | L37: 160 | M37: =IF(H37=0,"",I37*(1+$T$1)/H37) -> 2.4804857 | N37: =IF(J37=0,"",L37/J37) -> 2.1917808 | O37: =IF(COUNT(M37:N37)=0,$T$2,AVERAGE(M37:N37)) -> 2.3361332 | P37: =ROUND(D37*O37,0) -> 100 | Q37: =IFERROR(P37/E37,0) -> 0.5 | R37: =P37-E37 -> -100 | S37: =IF(R37>0,"要 追加発注",IF(Q37>=0.9,"要注意(90%超)",IF(Q37>=0.5,"適正","在庫余剰見込"))) -> 適正 | T37: =IF(R37>0,ROUNDUP(R37*1.1,0),0) -> 0 | U37: 博多 | V37: 比較会場(博多)が在庫上限のため倍率gが過小＝予測が控えめ
A38: 32 | B38: 4515142545266 | C38: 気分リフレッシュオルゴール | D38: 10 | E38: 10 | F38: =IFERROR(D38/E38,0) -> 1 | G38: =E38-D38 -> 0 | H38: 36 | I38: 36 | J38: 28 | K38: 30 | L38: 30 | M38: =IF(H38=0,"",I38*(1+$T$1)/H38) -> 1.4532138 | N38: =IF(J38=0,"",L38/J38) -> 1.0714286 | O38: =IF(COUNT(M38:N38)=0,$T$2,AVERAGE(M38:N38)) -> 1.2623212 | P38: =ROUND(D38*O38,0) -> 13 | Q38: =IFERROR(P38/E38,0) -> 1.3 | R38: =P38-E38 -> 3 | S38: =IF(R38>0,"要 追加発注",IF(Q38>=0.9,"要注意(90%超)",IF(Q38>=0.5,"適正","在庫余剰見込"))) -> 要 追加発注 | T38: =IF(R38>0,ROUNDUP(R38*1.1,0),0) -> 4 | U38: 博多 | V38: 比較会場(博多)が在庫上限のため倍率gが過小＝予測が控えめ ／ 販売可能数が極小(10個)・在庫追加の実現性を要確認
A39: 33 | B39: 4515142545273 | C39: 五条 悟 イメージリング（#11） | D39: 0 | E39: 15 | F39: =IFERROR(D39/E39,0) -> 0 | G39: =E39-D39 -> 15 | H39: 28 | I39: 35 | J39: 4 | K39: 12 | L39: 13 | M39: =IF(H39=0,"",I39*(1+$T$1)/H39) -> 1.8165173 | N39: =IF(J39=0,"",L39/J39) -> 3.25 | O39: =IF(COUNT(M39:N39)=0,$T$2,AVERAGE(M39:N39)) -> 2.5332586 | P39: =ROUND(D39*O39,0) -> 0 | Q39: =IFERROR(P39/E39,0) -> 0 | R39: =P39-E39 -> -15 | S39: =IF(R39>0,"要 追加発注",IF(Q39>=0.9,"要注意(90%超)",IF(Q39>=0.5,"適正","在庫余剰見込"))) -> 在庫余剰見込 | T39: =IF(R39>0,ROUNDUP(R39*1.1,0),0) -> 0 | U39: — | V39: 札幌5日間の販売実績ゼロ
A40: 34 | B40: 4515142545280 | C40: 五条 悟 イメージリング（#13） | D40: 1 | E40: 2 | F40: =IFERROR(D40/E40,0) -> 0.5 | G40: =E40-D40 -> 1 | H40: 3 | I40: 3 | J40: 3 | K40: 3 | L40: 3 | M40: =IF(H40=0,"",I40*(1+$T$1)/H40) -> 1.4532138 | N40: =IF(J40=0,"",L40/J40) -> 1 | O40: =IF(COUNT(M40:N40)=0,$T$2,AVERAGE(M40:N40)) -> 1.2266069 | P40: =ROUND(D40*O40,0) -> 1 | Q40: =IFERROR(P40/E40,0) -> 0.5 | R40: =P40-E40 -> -1 | S40: =IF(R40>0,"要 追加発注",IF(Q40>=0.9,"要注意(90%超)",IF(Q40>=0.5,"適正","在庫余剰見込"))) -> 適正 | T40: =IF(R40>0,ROUNDUP(R40*1.1,0),0) -> 0 | U40: 名古屋・博多 | V40: 比較会場(名古屋・博多)が在庫上限のため倍率gが過小＝予測が控えめ ／ 販売可能数が極小(2個)・在庫追加の実現性を要確認
A41: 35 | B41: 4515142545297 | C41: 五条 悟 イメージリング（#15） | D41: 0 | E41: 2 | F41: =IFERROR(D41/E41,0) -> 0 | G41: =E41-D41 -> 2 | H41: 3 | I41: 3 | J41: 3 | K41: 3 | L41: 3 | M41: =IF(H41=0,"",I41*(1+$T$1)/H41) -> 1.4532138 | N41: =IF(J41=0,"",L41/J41) -> 1 | O41: =IF(COUNT(M41:N41)=0,$T$2,AVERAGE(M41:N41)) -> 1.2266069 | P41: =ROUND(D41*O41,0) -> 0 | Q41: =IFERROR(P41/E41,0) -> 0 | R41: =P41-E41 -> -2 | S41: =IF(R41>0,"要 追加発注",IF(Q41>=0.9,"要注意(90%超)",IF(Q41>=0.5,"適正","在庫余剰見込"))) -> 在庫余剰見込 | T41: =IF(R41>0,ROUNDUP(R41*1.1,0),0) -> 0 | U41: 名古屋・博多 | V41: 比較会場(名古屋・博多)が在庫上限のため倍率gが過小＝予測が控えめ ／ 販売可能数が極小(2個)・在庫追加の実現性を要確認 ／ 札幌5日間の販売実績ゼロ
A42: 36 | B42: 4515142545303 | C42: 五条 悟 イメージリング（#17） | D42: 0 | E42: 2 | F42: =IFERROR(D42/E42,0) -> 0 | G42: =E42-D42 -> 2 | H42: 3 | I42: 3 | J42: 3 | K42: 3 | L42: 3 | M42: =IF(H42=0,"",I42*(1+$T$1)/H42) -> 1.4532138 | N42: =IF(J42=0,"",L42/J42) -> 1 | O42: =IF(COUNT(M42:N42)=0,$T$2,AVERAGE(M42:N42)) -> 1.2266069 | P42: =ROUND(D42*O42,0) -> 0 | Q42: =IFERROR(P42/E42,0) -> 0 | R42: =P42-E42 -> -2 | S42: =IF(R42>0,"要 追加発注",IF(Q42>=0.9,"要注意(90%超)",IF(Q42>=0.5,"適正","在庫余剰見込"))) -> 在庫余剰見込 | T42: =IF(R42>0,ROUNDUP(R42*1.1,0),0) -> 0 | U42: 名古屋・博多 | V42: 比較会場(名古屋・博多)が在庫上限のため倍率gが過小＝予測が控えめ ／ 販売可能数が極小(2個)・在庫追加の実現性を要確認 ／ 札幌5日間の販売実績ゼロ
...

Sheet ④全データ統合リスト
A1: ④ 商品別 全データ統合リスト（対象42SKU）
A2: 札幌③（7/26時点）・名古屋①・博多② の販売実績／構成比率／在庫／追加発注判定を商品別に集約
A5: 基本情報 | E5: 札幌③ 販売実績（7/22-7/26） | M5: 札幌③ 構成比率 | R5: 札幌③ 在庫 | X5: 名古屋① 実績・構成比 | AD5: 博多② 実績・構成比 | AK5: 追加発注判定
A6: No. | B6: JAN | C6: 商品名 | D6: 税込単価 | E6: 7/22 (水) | F6: 7/23 (木) | G6: 7/24 (金) | H6: 7/25 (土) | I6: 7/26 (日) | J6: 初日 販売数 | K6: 5日 累計 | L6: 5日累計 販売金額 | M6: 初日 構成比 | N6: 5日累計 構成比 | O6: 金額 構成比 | P6: 初日 順位 | Q6: 5日累計 順位 | R6: 納品数 合計 | S6: 販売 可能数 | T6: 残在庫 | U6: 消化率 | V6: 日販 平均 | W6: 在庫 消尽日数 | X6: 初日 販売数 | Y6: 初週5日 累計 | Z6: 14日 累計 | AA6: 初日 構成比 | AB6: 初週 構成比 | AC6: 消化率 | AD6: 初日 販売数 | AE6: 初週4日 累計 | AF6: 20日 累計 | AG6: 26日 累計 | AH6: 初日 構成比 | AI6: 初週 構成比 | AJ6: 消化率 | AK6: 採用 倍率g | AL6: 予測会期 累計販売数 | AM6: 予測 消化率 | AN6: 過不足数 | AO6: 追加発注 要否 | AP6: 推奨追加 発注数
A7: 1 | B7: 4515142545082 | C7: 呪術廻戦 メタリックポストカード 展示会キービジュアル | D7: 500 | E7: 72 | F7: 23 | G7: 26 | H7: 49 | I7: 35 | J7: =E7 -> 72 | K7: =SUM(E7:I7) -> 205 | L7: =K7*D7 -> 102500 | M7: =IFERROR(J7/J$49,0) -> 0.04040404 | N7: =IFERROR(K7/K$49,0) -> 0.048937694 | O7: =IFERROR(L7/L$49,0) -> 0.030880935 | P7: =IF(J7=0,"-",RANK(J7,J$7:J$48)) -> 6 | Q7: =IF(K7=0,"-",RANK(K7,K$7:K$48)) -> 7 | R7: 1000 | S7: 1000 | T7: =S7-K7 -> 795 | U7: =IFERROR(K7/S7,0) -> 0.205 | V7: =K7/5 -> 41 | W7: =IF(V7=0,"—",IF(T7/V7>=15,"15日超",ROUND(T7/V7,0))) -> 15日超 | X7: 159 | Y7: 605 | Z7: 1125 | AA7: =IFERROR(X7/X$49,0) -> 0.025579151 | AB7: =IFERROR(Y7/Y$49,0) -> 0.021817526 | AC7: =IFERROR(Z7/2000,0) -> 0.5625 | AD7: 107 | AE7: 361 | AF7: 987 | AG7: 1092 | AH7: =IFERROR(AD7/AD$49,0) -> 0.027893639 | AI7: =IFERROR(AE7/AE$49,0) -> 0.033043478 | AJ7: =IFERROR(AG7/1099,0) -> 0.99363057 | AK7: =③追加発注判定!O7 -> 2.5289328 | AL7: =③追加発注判定!P7 -> 518 | AM7: =③追加発注判定!Q7 -> 0.518 | AN7: =③追加発注判定!R7 -> -482 | AO7: =③追加発注判定!S7 -> 適正 | AP7: =③追加発注判定!T7 -> 0
A8: 2 | B8: 4515142545099 | C8: 呪術廻戦 クリアファイル 展示会キービジュアル | D8: 600 | E8: 66 | F8: 23 | G8: 31 | H8: 61 | I8: 52 | J8: =E8 -> 66 | K8: =SUM(E8:I8) -> 233 | L8: =K8*D8 -> 139800 | M8: =IFERROR(J8/J$49,0) -> 0.037037037 | N8: =IFERROR(K8/K$49,0) -> 0.055621867 | O8: =IFERROR(L8/L$49,0) -> 0.042118583 | P8: =IF(J8=0,"-",RANK(J8,J$7:J$48)) -> 7 | Q8: =IF(K8=0,"-",RANK(K8,K$7:K$48)) -> 5 | R8: 1000 | S8: 1000 | T8: =S8-K8 -> 767 | U8: =IFERROR(K8/S8,0) -> 0.233 | V8: =K8/5 -> 46.6 | W8: =IF(V8=0,"—",IF(T8/V8>=15,"15日超",ROUND(T8/V8,0))) -> 15日超 | X8: 154 | Y8: 616 | Z8: 1190 | AA8: =IFERROR(X8/X$49,0) -> 0.024774775 | AB8: =IFERROR(Y8/Y$49,0) -> 0.022214208 | AC8: =IFERROR(Z8/2000,0) -> 0.595 | AD8: 88 | AE8: 307 | AF8: 898 | AG8: 1132 | AH8: =IFERROR(AD8/AD$49,0) -> 0.022940563 | AI8: =IFERROR(AE8/AE$49,0) -> 0.028100686 | AJ8: =IFERROR(AG8/1200,0) -> 0.94333333 | AK8: =③追加発注判定!O8 -> 2.640587 | AL8: =③追加発注判定!P8 -> 615 | AM8: =③追加発注判定!Q8 -> 0.615 | AN8: =③追加発注判定!R8 -> -385 | AO8: =③追加発注判定!S8 -> 適正 | AP8: =③追加発注判定!T8 -> 0
A9: 3 | B9: 4515142545105 | C9: 呪術廻戦 懐玉・玉折 ポストカードセット（5枚入） | D9: 1000 | E9: 39 | F9: 12 | G9: 7 | H9: 16 | I9: 10 | J9: =E9 -> 39 | K9: =SUM(E9:I9) -> 84 | L9: =K9*D9 -> 84000 | M9: =IFERROR(J9/J$49,0) -> 0.021885522 | N9: =IFERROR(K9/K$49,0) -> 0.020052519 | O9: =IFERROR(L9/L$49,0) -> 0.025307303 | P9: =IF(J9=0,"-",RANK(J9,J$7:J$48)) -> 9 | Q9: =IF(K9=0,"-",RANK(K9,K$7:K$48)) -> 12 | R9: 450 | S9: 450 | T9: =S9-K9 -> 366 | U9: =IFERROR(K9/S9,0) -> 0.18666667 | V9: =K9/5 -> 16.8 | W9: =IF(V9=0,"—",IF(T9/V9>=15,"15日超",ROUND(T9/V9,0))) -> 15日超 | X9: 103 | Y9: 349 | Z9: 532 | AA9: =IFERROR(X9/X$49,0) -> 0.016570142 | AB9: =IFERROR(Y9/Y$49,0) -> 0.012585647 | AC9: =IFERROR(Z9/1200,0) -> 0.44333333 | AD9: 42 | AE9: 141 | AF9: 384 | AG9: 454 | AH9: =IFERROR(AD9/AD$49,0) -> 0.010948905 | AI9: =IFERROR(AE9/AE$49,0) -> 0.012906178 | AJ9: =IFERROR(AG9/500,0) -> 0.908 | AK9: =③追加発注判定!O9 -> 2.2642336 | AL9: =③追加発注判定!P9 -> 190 | AM9: =③追加発注判定!Q9 -> 0.42222222 | AN9: =③追加発注判定!R9 -> -260 | AO9: =③追加発注判定!S9 -> 在庫余剰見込 | AP9: =③追加発注判定!T9 -> 0
A10: 4 | B10: 4515142545112 | C10: 呪術廻戦 渋谷事変 ポストカードセット（9枚入） | D10: 1800 | E10: 52 | F10: 13 | G10: 13 | H10: 28 | I10: 16 | J10: =E10 -> 52 | K10: =SUM(E10:I10) -> 122 | L10: =K10*D10 -> 219600 | M10: =IFERROR(J10/J$49,0) -> 0.029180696 | N10: =IFERROR(K10/K$49,0) -> 0.029123896 | O10: =IFERROR(L10/L$49,0) -> 0.066160521 | P10: =IF(J10=0,"-",RANK(J10,J$7:J$48)) -> 8 | Q10: =IF(K10=0,"-",RANK(K10,K$7:K$48)) -> 10 | R10: 800 | S10: 800 | T10: =S10-K10 -> 678 | U10: =IFERROR(K10/S10,0) -> 0.1525 | V10: =K10/5 -> 24.4 | W10: =IF(V10=0,"—",IF(T10/V10>=15,"15日超",ROUND(T10/V10,0))) -> 15日超 | X10: 196 | Y10: 553 | Z10: 817 | AA10: =IFERROR(X10/X$49,0) -> 0.031531532 | AB10: =IFERROR(Y10/Y$49,0) -> 0.019942301 | AC10: =IFERROR(Z10/1330,0) -> 0.61428571 | AD10: 66 | AE10: 188 | AF10: 442 | AG10: 539 | AH10: =IFERROR(AD10/AD$49,0) -> 0.017205422 | AI10: =IFERROR(AE10/AE$49,0) -> 0.017208238 | AJ10: =IFERROR(AG10/800,0) -> 0.67375 | AK10: =③追加発注判定!O10 -> 2.115939 | AL10: =③追加発注判定!P10 -> 258 | AM10: =③追加発注判定!Q10 -> 0.3225 | AN10: =③追加発注判定!R10 -> -542 | AO10: =③追加発注判定!S10 -> 在庫余剰見込 | AP10: =③追加発注判定!T10 -> 0
A11: 5 | B11: 4515142545129 | C11: 呪術廻戦 懐玉・玉折 ブラインド缶バッジ（全5種） | D11: 600 | E11: 174 | F11: 16 | G11: 13 | H11: 24 | I11: 20 | J11: =E11 -> 174 | K11: =SUM(E11:I11) -> 247 | L11: =K11*D11 -> 148200 | M11: =IFERROR(J11/J$49,0) -> 0.097643098 | N11: =IFERROR(K11/K$49,0) -> 0.058963953 | O11: =IFERROR(L11/L$49,0) -> 0.044649313 | P11: =IF(J11=0,"-",RANK(J11,J$7:J$48)) -> 4 | Q11: =IF(K11=0,"-",RANK(K11,K$7:K$48)) -> 4 | R11: 9000 | S11: 9000 | T11: =S11-K11 -> 8753 | U11: =IFERROR(K11/S11,0) -> 0.027444444 | V11: =K11/5 -> 49.4 | W11: =IF(V11=0,"—",IF(T11/V11>=15,"15日超",ROUND(T11/V11,0))) -> 15日超 | X11: 1089 | Y11: 5070 | Z11: 9400 | AA11: =IFERROR(X11/X$49,0) -> 0.17519305 | AB11: =IFERROR(Y11/Y$49,0) -> 0.18283448 | AC11: =IFERROR(Z11/14505,0) -> 0.6480524 | AD11: 618 | AE11: 1927 | AF11: 6948 | AG11: 8991 | AH11: =IFERROR(AD11/AD$49,0) -> 0.16110532 | AI11: =IFERROR(AE11/AE$49,0) -> 0.17638444 | AJ11: =IFERROR(AG11/9000,0) -> 0.999 | AK11: =③追加発注判定!O11 -> 2.9036124 | AL11: =③追加発注判定!P11 -> 717 | AM11: =③追加発注判定!Q11 -> 0.079666667 | AN11: =③追加発注判定!R11 -> -8283 | AO11: =③追加発注判定!S11 -> 在庫余剰見込 | AP11: =③追加発注判定!T11 -> 0
A12: 6 | B12: 4515142545136 | C12: 呪術廻戦 渋谷事変 ブラインド缶バッジ（全9種） | D12: 600 | E12: 407 | F12: 74 | G12: 55 | H12: 53 | I12: 27 | J12: =E12 -> 407 | K12: =SUM(E12:I12) -> 616 | L12: =K12*D12 -> 369600 | M12: =IFERROR(J12/J$49,0) -> 0.22839506 | N12: =IFERROR(K12/K$49,0) -> 0.1470518 | O12: =IFERROR(L12/L$49,0) -> 0.11135213 | P12: =IF(J12=0,"-",RANK(J12,J$7:J$48)) -> 1 | Q12: =IF(K12=0,"-",RANK(K12,K$7:K$48)) -> 2 | R12: 13995 | S12: 13991 | T12: =S12-K12 -> 13375 | U12: =IFERROR(K12/S12,0) -> 0.044028304 | V12: =K12/5 -> 123.2 | W12: =IF(V12=0,"—",IF(T12/V12>=15,"15日超",ROUND(T12/V12,0))) -> 15日超 | X12: 1543 | Y12: 6714 | Z12: 13632 | AA12: =IFERROR(X12/X$49,0) -> 0.24823037 | AB12: =IFERROR(Y12/Y$49,0) -> 0.24212045 | AC12: =IFERROR(Z12/12439,0) -> 1.095908 | AD12: 942 | AE12: 2531 | AF12: 8314 | AG12: 13877 | AH12: =IFERROR(AD12/AD$49,0) -> 0.2455683 | AI12: =IFERROR(AE12/AE$49,0) -> 0.23167048 | AJ12: =IFERROR(AG12/13986,0) -> 0.99220649 | AK12: =③追加発注判定!O12 -> 2.9410881 | AL12: =③追加発注判定!P12 -> 1812 | AM12: =③追加発注判定!Q12 -> 0.12951183 | AN12: =③追加発注判定!R12 -> -12179 | AO12: =③追加発注判定!S12 -> 在庫余剰見込 | AP12: =③追加発注判定!T12 -> 0
A13: 7 | B13: 4515142545143 | C13: 呪術廻戦 懐玉・玉折 ブラインドダイカットステッカー（全5種） | D13: 600 | E13: 28 | F13: 4 | G13: 13 | H13: 10 | I13: 24 | J13: =E13 -> 28 | K13: =SUM(E13:I13) -> 79 | L13: =K13*D13 -> 47400 | M13: =IFERROR(J13/J$49,0) -> 0.015712682 | N13: =IFERROR(K13/K$49,0) -> 0.018858916 | O13: =IFERROR(L13/L$49,0) -> 0.01428055 | P13: =IF(J13=0,"-",RANK(J13,J$7:J$48)) -> 12 | Q13: =IF(K13=0,"-",RANK(K13,K$7:K$48)) -> 13 | R13: 350 | S13: 350 | T13: =S13-K13 -> 271 | U13: =IFERROR(K13/S13,0) -> 0.22571429 | V13: =K13/5 -> 15.8 | W13: =IF(V13=0,"—",IF(T13/V13>=15,"15日超",ROUND(T13/V13,0))) -> 15日超 | X13: 70 | Y13: 209 | Z13: 433 | AA13: =IFERROR(X13/X$49,0) -> 0.011261261 | AB13: =IFERROR(Y13/Y$49,0) -> 0.0075369636 | AC13: =IFERROR(Z13/1389,0) -> 0.31173506 | AD13: 72 | AE13: 133 | AF13: 349 | AG13: 384 | AH13: =IFERROR(AD13/AD$49,0) -> 0.018769552 | AI13: =IFERROR(AE13/AE$49,0) -> 0.012173913 | AJ13: =IFERROR(AG13/400,0) -> 0.96 | AK13: =③追加発注判定!O13 -> 2.6844167 | AL13: =③追加発注判定!P13 -> 212 | AM13: =③追加発注判定!Q13 -> 0.60571429 | AN13: =③追加発注判定!R13 -> -138 | AO13: =③追加発注判定!S13 -> 適正 | AP13: =③追加発注判定!T13 -> 0
A14: 8 | B14: 4515142545150 | C14: 呪術廻戦 渋谷事変 ブラインドダイカットステッカー（全9種） | D14: 600 | E14: 39 | F14: 15 | G14: 13 | H14: 40 | I14: 28 | J14: =E14 -> 39 | K14: =SUM(E14:I14) -> 135 | L14: =K14*D14 -> 81000 | M14: =IFERROR(J14/J$49,0) -> 0.021885522 | N14: =IFERROR(K14/K$49,0) -> 0.032227262 | O14: =IFERROR(L14/L$49,0) -> 0.024403471 | P14: =IF(J14=0,"-",RANK(J14,J$7:J$48)) -> 9 | Q14: =IF(K14=0,"-",RANK(K14,K$7:K$48)) -> 8 | R14: 900 | S14: 900 | T14: =S14-K14 -> 765 | U14: =IFERROR(K14/S14,0) -> 0.15 | V14: =K14/5 -> 27 | W14: =IF(V14=0,"—",IF(T14/V14>=15,"15日超",ROUND(T14/V14,0))) -> 15日超 | X14: 106 | Y14: 432 | Z14: 926 | AA14: =IFERROR(X14/X$49,0) -> 0.017052767 | AB14: =IFERROR(Y14/Y$49,0) -> 0.015578796 | AC14: =IFERROR(Z14/2240,0) -> 0.41339286 | AD14: 82 | AE14: 201 | AF14: 608 | AG14: 799 | AH14: =IFERROR(AD14/AD$49,0) -> 0.021376434 | AI14: =IFERROR(AE14/AE$49,0) -> 0.018398169 | AJ14: =IFERROR(AG14/840,0) -> 0.95119048 | AK14: =③追加発注判定!O14 -> 2.8511124 | AL14: =③追加発注判定!P14 -> 385 | AM14: =③追加発注判定!Q14 -> 0.42777778 | AN14: =③追加発注判定!R14 -> -515 | AO14: =③追加発注判定!S14 -> 在庫余剰見込 | AP14: =③追加発注判定!T14 -> 0
